Workbook

Sheet Kalender Mentoring
A1: KALENDER MENTORING SMAVO 2026-2027
A3: Tanggal | C3: Pertemuan | D3: Agenda Mentee | E3: Materi | F3: Agenda Mentor | G3: Keterangan
A4: Semester Ganjil
A5: 46235 | B5: 1 | C5: P1 | D5: Grand Launching Mentoring | E5: Circle time perdana - perkenalan singkat, penentuan struktur dan nama circle
B6: 8 | C6: P2 | D6: Circle Time | E6: Perkenalan lanjutan, kreasi bersama pembuatan Pprofil grup dengan Canva sharing
B7: 15 | C7: - | D7: Libur long weekend 17 Agustus | F7: 17an SCC x Mentor SMAVO (outing)
B8: 22 | C8: P3 | D8: Circle Time | E8: Materi Maulid
B9: 29 | C9: P4 | D9: Sport Time
A10: 46266 | B10: 5 | C10: P5 | D10: Circle Time
B11: 12 | C11: P6 | D11: Circle Time
B12: 19 | C12: P7 | D12: Circle Time
B13: 26 | C13: P8 | D13: Circle Time
A14: 46296 | B14: 3 | C14: P9 | D14: Circle Time
B15: 10 | C15: P10 | D15: Circle Time
B16: 17 | C16: P11 | D16: Circle Time
B17: 24 | C17: P12 | D17: Circle Time
B18: 31 | C18: P13 | D18: Circle Time | G18: TKA 26 Oktober - 8 November -> Antisipasi backup mentor murid
A19: 46327 | B19: 7 | C19: P14 | D19: Circle Time | G19: TKA 26 Oktober - 8 November -> Antisipasi backup mentor murid
B20: 14 | C20: P15 | D20: Circle Time
B21: 21 | C21: P16 | D21: Circle Time
B22: 28 | C22: - | D22: Libur persiapan PAS

Sheet Dashboard Circle
B1: Mentor SMAVO 2026-2027
B3: Angkatan 34 (Kelas X)
B4: Ikhwan | C4: Jml Mentee | D4: Mentor | E4: Asal Kelas/Alumni | H4: Akhwat | I4: Jml Mentee | J4: Mentor | K4: Asal Kelas/Alumni
B5: X-1 | C5: ='Kelas X Angk.34'!F41 -> 15 | D5: Fariz Duta | E5: {=XLOOKUP(TRIM(D5),TRIM('Database CirclePro +Mentor Muri'!B:B),'Database CirclePro +Mentor Muri'!C:C,"")} -> XII A2 | H5: X-1 | I5: ='Kelas X Angk.34'!F40 -> 17 | J5: Naila | K5: {=XLOOKUP(TRIM(J5),TRIM('Database CirclePro +Mentor Muri'!B:B),'Database CirclePro +Mentor Muri'!C:C,"")} -> XI C3
B6: X-2 | C6: ='Kelas X Angk.34'!F82 -> 15 | D6: Muhammad Daffa Sugianto | E6: {=XLOOKUP(TRIM(D6),TRIM('Database CirclePro +Mentor Muri'!B:B),'Database CirclePro +Mentor Muri'!C:C,"")} -> XII B2 | H6: X-2 | I6: ='Kelas X Angk.34'!F81 -> 17 | J6: Bilqis Anwar Thebe | K6: {=XLOOKUP(TRIM(J6),TRIM('Database CirclePro +Mentor Muri'!B:B),'Database CirclePro +Mentor Muri'!C:C,"")} -> XI E1
B7: X-3 | C7: ='Kelas X Angk.34'!F123 -> 14 | D7: Rifky Akbar | E7: {=XLOOKUP(TRIM(D7),TRIM('Database CirclePro +Mentor Muri'!B:B),'Database CirclePro +Mentor Muri'!C:C,"")} -> XII D1 | H7: X-3 | I7: ='Kelas X Angk.34'!F122 -> 17 | J7: Rayhana Rizkya Al-Multazam | K7: {=XLOOKUP(TRIM(J7),TRIM('Database CirclePro +Mentor Muri'!B:B),'Database CirclePro +Mentor Muri'!C:C,"")} -> XI C4
B8: X-4 | C8: ='Kelas X Angk.34'!F164 -> 14 | D8: Rifqi Putra | E8: {=XLOOKUP(TRIM(D8),TRIM('Database CirclePro +Mentor Muri'!B:B),'Database CirclePro +Mentor Muri'!C:C,"")} -> XII E1 | H8: X-4 | I8: ='Kelas X Angk.34'!F163 -> 17 | J8: Rifqah Ramadhani | K8: {=XLOOKUP(TRIM(J8),TRIM('Database CirclePro +Mentor Muri'!B:B),'Database CirclePro +Mentor Muri'!C:C,"")} -> XI C2
B9: X-5 | C9: ='Kelas X Angk.34'!F205 -> 14 | D9: Samy Abdurrahman Romdhony | E9: {=XLOOKUP(TRIM(D9),TRIM('Database CirclePro +Mentor Muri'!B:B),'Database CirclePro +Mentor Muri'!C:C,"")} -> XII B1 | H9: X-5 | I9: ='Kelas X Angk.34'!F204 -> 17 | J9: Isnaini Fauziyah Utomo | K9: {=XLOOKUP(TRIM(J9),TRIM('Database CirclePro +Mentor Muri'!B:B),'Database CirclePro +Mentor Muri'!C:C,"")} -> XI E1
B10: X-6 | C10: ='Kelas X Angk.34'!F246 -> 14 | D10: Zhafran Ramadhan Drajat Sukma | E10: {=XLOOKUP(TRIM(D10),TRIM('Database CirclePro +Mentor Muri'!B:B),'Database CirclePro +Mentor Muri'!C:C,"")} -> XII E1 | H10: X-6 | I10: ='Kelas X Angk.34'!F245 -> 17 | J10: Queensha Anindya Azka | K10: {=XLOOKUP(TRIM(J10),TRIM('Database CirclePro +Mentor Muri'!B:B),'Database CirclePro +Mentor Muri'!C:C,"")} -> XI C2
B11: X-7 | C11: ='Kelas X Angk.34'!F287 -> 14 | D11: Kaysan Umar Azka Setiawan | E11: {=XLOOKUP(TRIM(D11),TRIM('Database CirclePro +Mentor Muri'!B:B),'Database CirclePro +Mentor Muri'!C:C,"")} -> XI B1 | H11: X-7 | I11: ='Kelas X Angk.34'!F286 -> 17 | J11: Shabira Ayatul Husna | K11: {=XLOOKUP(TRIM(J11),TRIM('Database CirclePro +Mentor Muri'!B:B),'Database CirclePro +Mentor Muri'!C:C,"")} -> XI E1
B12: X-8 | C12: ='Kelas X Angk.34'!F328 -> 14 | D12: Luqman Aziz Saputro | E12: {=XLOOKUP(TRIM(D12),TRIM('Database CirclePro +Mentor Muri'!B:B),'Database CirclePro +Mentor Muri'!C:C,"")} -> XI A | H12: X-8A | I12: ='Kelas X Angk.34'!F327 -> 17 | J12: Jazirah Rahmah | K12: {=XLOOKUP(TRIM(J12),TRIM('Database CirclePro +Mentor Muri'!B:B),'Database CirclePro +Mentor Muri'!C:C,"")} -> XI C1
B13: X-9 | C13: ='Kelas X Angk.34'!F368 -> 15 | D13: Mirza Maulana Altamis | E13: {=XLOOKUP(TRIM(D13),TRIM('Database CirclePro +Mentor Muri'!B:B),'Database CirclePro +Mentor Muri'!C:C,"")} -> XI B1 | H13: X-8B | J13: Fakhi Zulfia Bilqis | K13: {=XLOOKUP(TRIM(J13),TRIM('Database CirclePro +Mentor Muri'!B:B),'Database CirclePro +Mentor Muri'!C:C,"")} -> XI D2
B14: X-10 | C14: ='Kelas X Angk.34'!F408 -> 14 | D14: Keyno Nazmi Afham | E14: {=XLOOKUP(TRIM(D14),TRIM('Database CirclePro +Mentor Muri'!B:B),'Database CirclePro +Mentor Muri'!C:C,"")} -> XI D2 | H14: X-9 | I14: ='Kelas X Angk.34'!F367 -> 15 | J14: Dinda Aulia | K14: {=XLOOKUP(TRIM(J14),TRIM('Database CirclePro +Mentor Muri'!B:B),'Database CirclePro +Mentor Muri'!C:C,"")} -> XI B1
B15: X-11A | C15: ='Kelas X Angk.34'!F448 -> 16 | D15: Daffa Khoirul Fajri | E15: {=XLOOKUP(TRIM(D15),TRIM('Database CirclePro +Mentor Muri'!B:B),'Database CirclePro +Mentor Muri'!C:C,"")} -> XI C4 | H15: X-10 | I15: ='Kelas X Angk.34'!F407 -> 16 | J15: Dwi Irmawati | K15: {=XLOOKUP(TRIM(J15),TRIM('Database CirclePro +Mentor Muri'!B:B),'Database CirclePro +Mentor Muri'!C:C,"")} -> XI C4
B16: X-11B | D16: Mohammad Irshad Faizanshah | E16: {=XLOOKUP(TRIM(D16),TRIM('Database CirclePro +Mentor Muri'!B:B),'Database CirclePro +Mentor Muri'!C:C,"")} -> XI C4 | H16: X-11 | I16: ='Kelas X Angk.34'!F447 -> 15 | J16: Masayu Ganisha Pambayun Putri | K16: {=XLOOKUP(TRIM(J16),TRIM('Database CirclePro +Mentor Muri'!B:B),'Database CirclePro +Mentor Muri'!C:C,"")} -> XI C4
B17: X-12 | C17: ='Kelas X Angk.34'!F488 -> 14 | D17: Muhammad Tsafiq Ihsan | E17: {=XLOOKUP(TRIM(D17),TRIM('Database CirclePro +Mentor Muri'!B:B),'Database CirclePro +Mentor Muri'!C:C,"")} -> XI B3 | H17: X-12 | I17: ='Kelas X Angk.34'!F487 -> 16 | J17: Syakira Alma Annisa | K17: {=XLOOKUP(TRIM(J17),TRIM('Database CirclePro +Mentor Muri'!B:B),'Database CirclePro +Mentor Muri'!C:C,"")} -> XI D1
B18: Circel Plus-1 | D18: Rahman | E18: Alumni 15 | H18: Circel Plus-1 | J18: Ramania | K18: Alumni 23
B19: Jumlah | C19: =sum(C5:C17) -> 173 | H19: Jumlah | I19: =sum(I5:I17) -> 198
B21: Angkatan 33 (Kelas XI)
B22: Ikhwan | C22: Jml Mentee | D22: Mentor | E22: Asal Kelas/Alumni | F22: Di CirclePro | H22: Akhwat | I22: Jml Mentee | J22: Mentor | K22: Asal Kelas/Alumni | L22: Di CirclePro
B23: XI B1 | C23: ='Kelas XI Angk.33'!D113 -> 11 | D23: Muhammad Shafa | E23: {=XLOOKUP(TRIM(D25),TRIM('Database CirclePro +Mentor Muri'!B:B),'Database CirclePro +Mentor Muri'!C:C,"")} -> XII F2 | F23: 2 | H23: XI A | I23: ='Kelas XI Angk.33'!D57 -> 24 | J23: Farisa | K23: Alumni 31 | L23: 0
B24: XI B2 | C24: ='Kelas XI Angk.33'!D170 -> 12 | D24: Rifqi Hadzami | E24: {=XLOOKUP(TRIM(D24),TRIM('Database CirclePro +Mentor Muri'!B:B),'Database CirclePro +Mentor Muri'!C:C,"")} -> XII D3 | F24: 3 | H24: XI B1 | I24: ='Kelas XI Angk.33'!D114 -> 36 | J24: Nadira | K24: Alumni 31 | L24: 4
B25: XI B3 | C25: ='Kelas XI Angk.33'!D227 -> 12 | D25: M. Royyan | E25: {=XLOOKUP(TRIM(D23),TRIM('Database CirclePro +Mentor Muri'!B:B),'Database CirclePro +Mentor Muri'!C:C,"")} -> XII B1 | F25: 1 | H25: XI B2-A | I25: ='Kelas XI Angk.33'!D171 -> 35 | J25: Faliqa Haq Hasanah | K25: {=XLOOKUP(TRIM(D5),TRIM('Database CirclePro +Mentor Muri'!B:B),'Database CirclePro +Mentor Muri'!C:C,"")} -> XII A2 | L25: 0
B26: XI A | C26: ='Kelas XI Angk.33'!D56 -> 23 | D26: Dimas | E26: Alumni 23 | F26: 2 | H26: XI B2-B | J26: Annisa Nur Fajriya | K26: XII A2
B27: XI C1 | C27: ='Kelas XI Angk.33'!D283 -> 20 | F27: 2 | H27: XI B3-A | I27: ='Kelas XI Angk.33'!D228 -> 35 | J27: Arsyila Kayyisah B | K27: XII D1 | L27: 0
B28: XI C2 | C28: ='Kelas XI Angk.33'!D339 -> 19 | D28: Taufik | E28: Alumni 10 | F28: 5 | H28: XI B3-B | J28: Zhafira Fathin Ilmira | K28: XII D1
B29: XI C3 | C29: ='Kelas XI Angk.33'!D394 -> 18 | F29: 0 | H29: XI C1 | I29: ='Kelas XI Angk.33'!D284 -> 26 | J29: Lexa El Sohbia | K29: XII D2 | L29: 7
B30: XI C4 | C30: ='Kelas XI Angk.33'!D449 -> 17 | F30: 4 | H30: XI C2 | I30: ='Kelas XI Angk.33'!D340 -> 27 | J30: Kusniawati | K30: Alumni 8 | L30: 5
B31: XI D1 | C31: ='Kelas XI Angk.33'!D507 -> 30 | D31: Hamzah | E31: Alumni 16 | F31: 0 | H31: XI C3 | I31: ='Kelas XI Angk.33'!D395 -> 27 | L31: 3
B32: XI E1 | C32: ='Kelas XI Angk.33'!D621 -> 14 | F32: 1 | H32: XI C4 | I32: ='Kelas XI Angk.33'!D450 -> 28 | J32: Zalika | K32: Alumni 30 | L32: 6
B33: XI D2 | C33: ='Kelas XI Angk.33'!D564 -> 28 | D33: Rizza | E33: Alumni 24 | F33: 0 | H33: XI D1 | I33: ='Kelas XI Angk.33'!D508 -> 18 | J33: Syaikhah Anbar | K33: XII F2 | L33: 1
B34: XI E2 | C34: ='Kelas XI Angk.33'!D677 -> 14 | F34: 6 | H34: XI D2 | I34: ='Kelas XI Angk.33'!D565 -> 19 | J34: Zaina Husniyati Hamdani | K34: {=XLOOKUP(TRIM(D7),TRIM('Database CirclePro +Mentor Muri'!B:B),'Database CirclePro +Mentor Muri'!C:C,"")} -> XII D1 | L34: 0
B35: Circle Pro-1 | C35: ='Database CirclePro +Mentor Muri'!E18 -> 15 | D35: Rekhsa | E35: Alumni 20 | H35: XI E1 | I35: ='Kelas XI Angk.33'!D622 -> 33 | J35: Annisa Alya | K35: Alumni 31 | L35: 5
B36: Circle Pro-2 | C36: ='Database CirclePro +Mentor Muri'!E32 -> 11 | D36: Teguh | E36: Alumni 18 | H36: XI E2-A | I36: ='Kelas XI Angk.33'!D678 -> 32 | J36: Sabika Zaura Khumairo | K36: XII E1 | L36: 2
B37: Jumlah | C37: =sum(C23:C33) -> 204 | H37: XI E2-B | J37: Desya Maulida | K37: XII E1
H38: Circle Pro-1 | I38: ='Database CirclePro +Mentor Muri'!K17 -> 14 | J38: Ayun | K38: Alumni 18
H39: Circle Pro-2 | I39: ='Database CirclePro +Mentor Muri'!K33 -> 13 | J39: Ulfi | K39: Alumni 16
H40: Circle Pro-3 | I40: ='Database CirclePro +Mentor Muri'!K49 -> 13 | J40: Iga | K40: Alumni 19
H41: Jumlah | I41: =sum(I26:I37) -> 245
B43: Angkatan 32 (Kelas XII)
...

Sheet Database CirclePro +Mentor Muri
E1: CIRCLE PRO 2026/2027
E2: 33 - Kak Rekhsa | K2: 33 - Kak Ayun
A3: IKHWAN | E3: NO | F3: NAMA | G3: KELAS | H3: NO. HP | K3: NO | L3: NAMA | M3: KELAS | N3: NO. HP | O3: Asal Kelas
A4: 33 | E4: 1 | F4: Muhammad Ariza Rizkya Irvan | G4: {=XLOOKUP(TRIM(F4),TRIM('Kelas XI Angk.33'!C:C),'Kelas XI Angk.33'!E:E,"")} -> XI C2 | K4: 1 | L4: Aira Alessia Adha | M4: {=XLOOKUP(TRIM(L4),TRIM('Kelas XI Angk.33'!C:C),'Kelas XI Angk.33'!E:E,"")} -> XI A | O4: X-5
A5: Mentor: Rekhsa | E5: 2 | F5: Mohammad Irshad Faizanshah | G5: {=XLOOKUP(TRIM(F5),TRIM('Kelas XI Angk.33'!C:C),'Kelas XI Angk.33'!E:E,"")} -> XI C4 | K5: 2 | L5: Alyya Zahra Kusumadewi | M5: {=XLOOKUP(TRIM(L5),TRIM('Kelas XI Angk.33'!C:C),'Kelas XI Angk.33'!E:E,"")} -> XI C1 | O5: X-2
A6: 1. | B6: Keyno Nazmi Afham | C6: XI D2 | E6: 3 | F6: Keyno Nazmi Afham | G6: {=XLOOKUP(TRIM(F6),TRIM('Kelas XI Angk.33'!C:C),'Kelas XI Angk.33'!E:E,"")} -> XI D2 | K6: 3 | L6: Aulia Intan Rhamadhani | M6: {=XLOOKUP(TRIM(L6),TRIM('Kelas XI Angk.33'!C:C),'Kelas XI Angk.33'!E:E,"")} -> XI C4 | O6: X-11
A7: 2. | B7: Muhammad Tsafiq Ihsan | C7: XI B3 | E7: 4 | F7: Muhammad Zaidan Aqil | G7: {=XLOOKUP(TRIM(F7),TRIM('Kelas XI Angk.33'!C:C),'Kelas XI Angk.33'!E:E,"")} -> XI A | K7: 4 | L7: Bilqis Anwar Thebe | M7: {=XLOOKUP(TRIM(L7),TRIM('Kelas XI Angk.33'!C:C),'Kelas XI Angk.33'!E:E,"")} -> XI E1 | O7: X-1
A8: 3. | B8: Daffa Khoirul Fajri | C8: XI C4 | E8: 5 | F8: Achmad Ardiansyah | G8: {=XLOOKUP(TRIM(F8),TRIM('Kelas XI Angk.33'!C:C),'Kelas XI Angk.33'!E:E,"")} -> XI C1 | K8: 5 | L8: Isnaini Fauziyah Utomo | M8: {=XLOOKUP(TRIM(L8),TRIM('Kelas XI Angk.33'!C:C),'Kelas XI Angk.33'!E:E,"")} -> XI E1 | O8: X-10
A9: 4. | B9: Mohammad Irshad Faizanshah | C9: XI C4 | E9: 6 | F9: Muhammad Naufal Rhesa Fernando | G9: {=XLOOKUP(TRIM(F9),TRIM('Kelas XI Angk.33'!C:C),'Kelas XI Angk.33'!E:E,"")} -> XI C2 | K9: 6 | L9: Naila | M9: {=XLOOKUP(TRIM(L9),TRIM('Kelas XI Angk.33'!C:C),'Kelas XI Angk.33'!E:E,"")} -> XI C3 | O9: X-12
A10: Mentor: Teguh | E10: 7 | F10: Daffa Khoirul Fajri | G10: {=XLOOKUP(TRIM(F10),TRIM('Kelas XI Angk.33'!C:C),'Kelas XI Angk.33'!E:E,"")} -> XI C4 | K10: 7 | L10: Naya | M10: {=XLOOKUP(TRIM(L10),TRIM('Kelas XI Angk.33'!C:C),'Kelas XI Angk.33'!E:E,"")} | O10: X. 11
A11: 1. | B11: Kaysan Umar Azka Setiawan | C11: XI B1 | E11: 8 | F11: Muhamad Ilham Akbar | G11: {=XLOOKUP(TRIM(F11),TRIM('Kelas XI Angk.33'!C:C),'Kelas XI Angk.33'!E:E,"")} -> XI B1 | K11: 8 | L11: Queensha Anindya Azka | M11: {=XLOOKUP(TRIM(L11),TRIM('Kelas XI Angk.33'!C:C),'Kelas XI Angk.33'!E:E,"")} -> XI C3 | O11: X10
A12: 2. | B12: Luqman Aziz Saputro | C12: XI A | E12: 9 | F12: Muhammad Fawaz Ali | G12: {=XLOOKUP(TRIM(F12),TRIM('Kelas XI Angk.33'!C:C),'Kelas XI Angk.33'!E:E,"")} -> XI D2 | K12: 9 | L12: Rayhana Rizkya Al-Multazam | M12: {=XLOOKUP(TRIM(L12),TRIM('Kelas XI Angk.33'!C:C),'Kelas XI Angk.33'!E:E,"")} -> XI C4 | O12: X-1
A13: 3. | B13: Mirza Maulana Altamis | C13: XI B1 | E13: 10 | F13: Raka Syabany Amsyah | G13: {=XLOOKUP(TRIM(F13),TRIM('Kelas XI Angk.33'!C:C),'Kelas XI Angk.33'!E:E,"")} -> XI B2 | K13: 10 | L13: Rifqah Ramadhani | M13: {=XLOOKUP(TRIM(L13),TRIM('Kelas XI Angk.33'!C:C),'Kelas XI Angk.33'!E:E,"")} -> XI C2 | O13: X-12
A14: 32 | E14: 11 | F14: Abdul Ghofar | G14: {=XLOOKUP(TRIM(F14),TRIM('Kelas XI Angk.33'!C:C),'Kelas XI Angk.33'!E:E,"")} -> XI C2 | K14: 11 | L14: Syaakhira Fauziah | M14: {=XLOOKUP(TRIM(L14),TRIM('Kelas XI Angk.33'!C:C),'Kelas XI Angk.33'!E:E,"")} -> XI B1 | O14: X10
A15: Mentor: Randy | E15: 12 | F15: Muhammad Tsafiq Ihsan | G15: {=XLOOKUP(TRIM(F15),TRIM('Kelas XI Angk.33'!C:C),'Kelas XI Angk.33'!E:E,"")} -> XI B3 | K15: 12 | M15: {=XLOOKUP(TRIM(L15),TRIM('Kelas XI Angk.33'!C:C),'Kelas XI Angk.33'!E:E,"")}
A16: 1. | B16: Rifqi Hadzami | C16: XII D3 | E16: 13 | F16: Muhammad Ieddzar Haradiya | G16: {=XLOOKUP(TRIM(F16),TRIM('Kelas XI Angk.33'!C:C),'Kelas XI Angk.33'!E:E,"")} -> XI B2 | K16: 13 | M16: {=XLOOKUP(TRIM(L16),TRIM('Kelas XI Angk.33'!C:C),'Kelas XI Angk.33'!E:E,"")}
A17: 2. | B17: Fariz Duta | C17: XII A2 | E17: 14 | F17: Natiq Tawqir Muniruzzaman Anandamaya | G17: {=XLOOKUP(TRIM(F17),TRIM('Kelas XI Angk.33'!C:C),'Kelas XI Angk.33'!E:E,"")} -> XI D1 | K17: 14 | M17: {=XLOOKUP(TRIM(L17),TRIM('Kelas XI Angk.33'!C:C),'Kelas XI Angk.33'!E:E,"")}
A18: 3. | B18: Rifqi Putra | C18: XII E1 | E18: 15 | F18: Muhammad Adrian Gianni Adam | G18: {=XLOOKUP(TRIM(F18),TRIM('Kelas XI Angk.33'!C:C),'Kelas XI Angk.33'!E:E,"")} -> XI D2
A19: 4. | B19: Rifky Akbar | C19: XII D1 | K19: 33 - Kak Ulfi
A20: 5. | B20: Samy Abdurrahman Romdhony | C20: XII B1 | E20: 33 - Kak Teguh | K20: NO | L20: NAMA | M20: KELAS | N20: NO. HP | O20: Asal kelas
A21: 6. | B21: Zhafran Ramadhan Drajat Sukma | C21: XII E1 | E21: NO | F21: NAMA | G21: KELAS | H21: NO. HP | I21: Asal kelas | K21: 1 | L21: Aurelia Septiani Putri | M21: {=XLOOKUP(TRIM(L21),TRIM('Kelas XI Angk.33'!C:C),'Kelas XI Angk.33'!E:E,"")} -> XI C1 | N21: 8997074777 | O21: X-1
A22: 7. | B22: Muhammad Daffa Sugianto | C22: XII B2 | E22: 1 | F22: Raivan Elang Pramono | G22: {=XLOOKUP(TRIM(F5),TRIM('Kelas XI Angk.33'!C:C),'Kelas XI Angk.33'!E:E,"")} -> XI C4 | H22: 85817652799 | I22: X-10 | K22: 2 | L22: Aurelia Langit Callysta | M22: {=XLOOKUP(TRIM(L22),TRIM('Kelas XI Angk.33'!C:C),'Kelas XI Angk.33'!E:E,"")} -> XI C4 | N22: 81323955089 | O22: X-1
A23: 8. | B23: Muhammad Shafa | C23: XII B1 | E23: 2 | F23: Bintang jati Pratama | G23: {=XLOOKUP(TRIM(F6),TRIM('Kelas XI Angk.33'!C:C),'Kelas XI Angk.33'!E:E,"")} -> XI D2 | H23: 0857-1963-1782 | I23: X-12 | K23: 3 | L23: Shabira Ayatul Husna | M23: {=XLOOKUP(TRIM(L23),TRIM('Kelas XI Angk.33'!C:C),'Kelas XI Angk.33'!E:E,"")} -> XI E1 | N23: 0821-1428-2069 | O23: X-1
A24: 9. | B24: M. Royyan | C24: XII F2 | E24: 3 | F24: Farid Pradana | G24: {=XLOOKUP(TRIM(F7),TRIM('Kelas XI Angk.33'!C:C),'Kelas XI Angk.33'!E:E,"")} -> XI A | H24: 62 813-8514-7615 | I24: X-8 | K24: 4 | L24: Alifa Safa Salsabila | M24: {=XLOOKUP(TRIM(L24),TRIM('Kelas XI Angk.33'!C:C),'Kelas XI Angk.33'!E:E,"")} -> XI E1 | N24: 0881-2752-675 | O24: X-2
A25: AKHWAT | E25: 4 | F25: Kaysan Umar Azka Setiawan | G25: {=XLOOKUP(TRIM(F8),TRIM('Kelas XI Angk.33'!C:C),'Kelas XI Angk.33'!E:E,"")} -> XI C1 | H25: 62 881-5379-026 | I25: X-8 | K25: 5 | L25: Denisa Azka Putri | M25: {=XLOOKUP(TRIM(L25),TRIM('Kelas XI Angk.33'!C:C),'Kelas XI Angk.33'!E:E,"")} -> XI E2 | N25: 87874292010 | O25: X-2
A26: 33 | E26: 5 | F26: Luqman Aziz Saputro | G26: {=XLOOKUP(TRIM(F9),TRIM('Kelas XI Angk.33'!C:C),'Kelas XI Angk.33'!E:E,"")} -> XI C2 | H26: 62 882-9224-2109 | I26: X-8 | K26: 6 | L26: Andini Qoriyati Khaerani | M26: {=XLOOKUP(TRIM(L26),TRIM('Kelas XI Angk.33'!C:C),'Kelas XI Angk.33'!E:E,"")} -> XI C2 | O26: X-2
A27: Mentor: Ayun | E27: 6 | F27: Mirza Maulana Altamis | G27: {=XLOOKUP(TRIM(F10),TRIM('Kelas XI Angk.33'!C:C),'Kelas XI Angk.33'!E:E,"")} -> XI C4 | H27: 62 857-9258-8050 | I27: X-8 | K27: 7 | L27: Qaniah Mardiyah Salsabila | M27: {=XLOOKUP(TRIM(L27),TRIM('Kelas XI Angk.33'!C:C),'Kelas XI Angk.33'!E:E,"")} -> XI C4 | N27: 0812‑1391‑7720‬ | O27: X-2
A28: 1. | B28: Naila | C28: XI C3 | E28: 7 | F28: Muhammad Yafiargi Simbangando | G28: {=XLOOKUP(TRIM(F11),TRIM('Kelas XI Angk.33'!C:C),'Kelas XI Angk.33'!E:E,"")} -> XI B1 | H28: 62 813-8171-2152 | I28: X-8 | K28: 8 | L28: Niesha Anindya Firstsaly | M28: {=XLOOKUP(TRIM(L28),TRIM('Kelas XI Angk.33'!C:C),'Kelas XI Angk.33'!E:E,"")} -> XI E1 | N28: 0812‑1026‑0707 | O28: X-2
A29: 2. | B29: Bilqis Anwar Thebe | C29: XI E1 | E29: 8 | F29: Bima Anggareksa Yusiansyah | G29: {=XLOOKUP(TRIM(F12),TRIM('Kelas XI Angk.33'!C:C),'Kelas XI Angk.33'!E:E,"")} -> XI D2 | H29: 0858-8016-3225 | I29: X-8 | K29: 9 | L29: Yasmine Almira Queen | M29: {=XLOOKUP(TRIM(L29),TRIM('Kelas XI Angk.33'!C:C),'Kelas XI Angk.33'!E:E,"")} -> XI C2 | N29: 0813-8042-9524 | O29: X-3
A30: 3. | B30: Rayhana Rizkya Al-Multazam | C30: XI C4 | E30: 9 | F30: Manda Rizza | G30: {=XLOOKUP(TRIM(F12),TRIM('Kelas XI Angk.33'!C:C),'Kelas XI Angk.33'!E:E,"")} -> XI D2 | H30: 81284517061 | I30: X-3 | K30: 10 | L30: Balqis Jauza Sabreenijka | M30: {=XLOOKUP(TRIM(L30),TRIM('Kelas XI Angk.33'!C:C),'Kelas XI Angk.33'!E:E,"")} -> XI B1
A31: 4. | B31: Rifqah Ramadhani | C31: XI C2 | E31: 10 | F31: Arman | G31: {=XLOOKUP(TRIM(F13),TRIM('Kelas XI Angk.33'!C:C),'Kelas XI Angk.33'!E:E,"")} -> XI B2 | H31: 895330590233 | I31: X-3 | K31: 11 | L31: Jazirah Rahmah | M31: {=XLOOKUP(TRIM(L31),TRIM('Kelas XI Angk.33'!C:C),'Kelas XI Angk.33'!E:E,"")} -> XI C1
A32: 5. | B32: Isnaini Fauziyah Utomo | C32: XI E1 | E32: 11 | F32: Bimo | G32: {=XLOOKUP(TRIM(F14),TRIM('Kelas XI Angk.33'!C:C),'Kelas XI Angk.33'!E:E,"")} -> XI C2 | H32: 895320471747 | I32: X-3 | K32: 12 | L32: Askana Nailazahran Hermansyah | M32: {=XLOOKUP(TRIM(L32),TRIM('Kelas XI Angk.33'!C:C),'Kelas XI Angk.33'!E:E,"")} -> XI C3
A33: 6. | B33: Queensha Anindya Azka | C33: XI C2 | K33: 13 | L33: Syaakhira Fauziah | M33: {=XLOOKUP(TRIM(L33),TRIM('Kelas XI Angk.33'!C:C),'Kelas XI Angk.33'!E:E,"")} -> XI B1
A34: Mentor: Ulfi | E34: 32 - Kak Randy
A35: 1. | B35: Jazirah Rahmah | C35: XI C1 | E35: NO | F35: NAMA | G35: KELAS | H35: NO. HP | I35: Asal Kelas | K35: 33 - Kak Iga
A36: 2. | B36: Shabira Ayatul Husna | C36: XI E1 | E36: 1 | F36: Muhammad Rifqi Hadzami | G36: {=XLOOKUP(TRIM(F36),TRIM('Kelas XII Angk.32'!C:C),'Kelas XII Angk.32'!E:E,"")} -> XII D3 | H36: 85697065033 | I36: X-4 | K36: NO | L36: NAMA | M36: KELAS | N36: NO. HP | O36: Asal kelas
A37: No. | B37: Mentor Iga: | E37: 2 | F37: Muhammad Fariz Duta Eshan | G37: {=XLOOKUP(TRIM(F37),TRIM('Kelas XII Angk.32'!C:C),'Kelas XII Angk.32'!E:E,"")} -> XII A2 | H37: 89526336510 | I37: X-4 | K37: 1 | L37: Masayu Ganisha Pembayun Putri | M37: {=XLOOKUP(TRIM(L37),TRIM('Kelas XI Angk.33'!C:C),'Kelas XI Angk.33'!E:E,"")} -> XI C4 | N37: 8977432121 | O37: X-4
A38: 1. | B38: Dinda Aulia | C38: XI B1 | E38: 3 | F38: Rifqi Anindya Putra | G38: {=XLOOKUP(TRIM(F38),TRIM('Kelas XII Angk.32'!C:C),'Kelas XII Angk.32'!E:E,"")} -> XII E1 | H38: 8118126863 | I38: X-1 | K38: 2 | L38: Khansa Vanya Laudya Putri | M38: {=XLOOKUP(TRIM(L38),TRIM('Kelas XI Angk.33'!C:C),'Kelas XI Angk.33'!E:E,"")} -> XI D2 | N38: 81318560921 | O38: X-4
A39: 2. | B39: Fakhi Zulfia Bilqis | C39: XI D2 | E39: 4 | F39: Rifky Akbar Maulana | G39: {=XLOOKUP(TRIM(F39),TRIM('Kelas XII Angk.32'!C:C),'Kelas XII Angk.32'!E:E,"")} -> XII D1 | H39: 81386755883 | I39: X-4 | K39: 3 | L39: Syakira Alma Annisa | M39: {=XLOOKUP(TRIM(L39),TRIM('Kelas XI Angk.33'!C:C),'Kelas XI Angk.33'!E:E,"")} -> XI D1 | N39: 82322189618 | O39: X-4
A40: 3. | B40: Dwi Irmawati | C40: XI C4 | E40: 5 | F40: Hibban Abdurrahman | G40: {=XLOOKUP(TRIM(F40),TRIM('Kelas XII Angk.32'!C:C),'Kelas XII Angk.32'!E:E,"")} -> XII E2 | K40: 4 | L40: Fakhi Zulfia Bilqis Nasyifa | M40: {=XLOOKUP(TRIM(L40),TRIM('Kelas XI Angk.33'!C:C),'Kelas XI Angk.33'!E:E,"")} -> XI D2 | N40: 81257384837 | O40: X-4
...

Sheet Kelas X Angk.34
A1: PEMERINTAH DAERAH PROVINSI JAWA BARAT DINAS PENDIDIKAN SMA NEGERI 2 CIBINONG Jln. Karadenan No. 5 Cibinong Telp/Fax. ( 0251 ) 8654347 Bogor 16913 http://www.sman2cibinong.sch.id email: info@sman2cibinong.sch.id
A3: DAFTAR MURID
A4: KELAS X 1
A5: TAHUN PELAJARAN 2026-2027
A6: Wali Kelas : Deden Nur Hasanah, S.E
A7: NO | B7: SUB JALUR | C7: NISN | D7: NIS | E7: NAMA | F7: P/L
A8: 1 | B8: Kompetensi Nonakademik | C8: 0114443942 | D8: 262710018 | E8: Airo Nisya Mandira Boru Angkat | F8: P
A9: 2 | B9: Kompetensi Akademik Kejuaraan | C9: 0118175898 | D9: 262710036 | E9: Allesya Ananto | F9: P
A10: 3 | B10: Kompetensi Akademik Rapor | C10: 0115929061 | D10: 262710051 | E10: Anida Zakia | F10: P
A11: 4 | B11: Kompetensi Akademik Rapor | C11: 0102583300 | D11: 262710056 | E11: Aqeela Karima Fitri | F11: P
A12: 5 | B12: Kompetensi Nonakademik | C12: 3104861688 | D12: 262710068 | E12: Asma Zulfa Diyanah | F12: P
A13: 6 | B13: Kompetensi Akademik Rapor | C13: 0114691128 | D13: 262710078 | E13: Belqhis Insa Salsabilla | F13: P
A14: 7 | B14: Kompetensi Akademik Rapor | C14: 0102787072 | D14: 262710092 | E14: Daffa Rizky Ramadhan | F14: L
A15: 8 | B15: Kompetensi Akademik Rapor | C15: 0104086813 | D15: 262710093 | E15: Damar Volka Khalendra | F15: L
A16: 9 | B16: Kompetensi Nonakademik | C16: 3108124049 | D16: 262710112 | E16: Dzalfan Adzikra Martha | F16: L
A17: 10 | B17: Kompetensi Akademik Rapor | C17: 0111302202 | D17: 262710136 | E17: Fathan Jiwantana | F17: L
A18: 11 | B18: Kompetensi Akademik Rapor | C18: 0119048908 | D18: 262710138 | E18: Fathir Athaillah Pratama | F18: L
A19: 12 | B19: Kompetensi Akademik Rapor | C19: 0118600996 | D19: 262710150 | E19: Gideon Herlambang Ritonga | F19: L
A20: 13 | B20: Kompetensi Nonakademik | C20: 0107448918 | D20: 262710155 | E20: Hafiz Muhamad Arfa | F20: L
A21: 14 | B21: Kompetensi Akademik Kejuaraan | C21: 0116527821 | D21: 262710164 | E21: Hanna Fathiya Difani | F21: P
A22: 15 | B22: Kompetensi Akademik Rapor | C22: 0102028622 | D22: 262710171 | E22: Hisyam Ahmad Zulkarnain | F22: L
A23: 16 | B23: Kompetensi Akademik Rapor | C23: 0108974570 | D23: 262710181 | E23: Jihan Thahirah Khalilah Ajna | F23: P
A24: 17 | B24: Kompetensi Nonakademik | C24: 0111893063 | D24: 262710194 | E24: Kenzie Ataya Narda | F24: L
A25: 18 | B25: Kompetensi Akademik Rapor | C25: 0115332644 | D25: 262710205 | E25: Kinanthi Paramitha Nareswari | F25: P
A26: 19 | B26: Kompetensi Akademik Rapor | C26: 0108373038 | D26: 262710210 | E26: Levina Nayaka | F26: P
A27: 20 | B27: Kompetensi Akademik Rapor | C27: 0116728450 | D27: 262710259 | E27: Mutyara Putri Shaqina | F27: P
A28: 21 | B28: Kompetensi Nonakademik | C28: 0099285471 | D28: 262710260 | E28: Muzhaffir Naillur Raja | F28: L
... A32: 25 | B32: Potensi Akademik | C32: 0112110754 | D32: 262710316 | E32: Rayhan Daniswara | F32: L
A33: 26 | B33: Kompetensi Akademik Rapor | C33: 3117777065 | D33: 262710342 | E33: Shakila Alma Falisha | F33: P
A34: 27 | B34: Kompetensi Akademik Rapor | C34: 0115579184 | D34: 262710351 | E34: Syakila Nahda Dhania | F34: P
A35: 28 | B35: Kompetensi Akademik Rapor | C35: 0119448889 | D35: 262710362 | E35: Tubagus Akmal Rizky | F35: L
A36: 29 | B36: Kompetensi Akademik Rapor | C36: 0102618611 | D36: 262710365 | E36: Vanessa Ellianova Zivanna Pangaribuan | F36: P
A37: 30 | B37: Kompetensi Akademik Rapor | C37: 0118298885 | D37: 262710367 | E37: Verra Nayla Karnaen | F37: P
A38: 31 | B38: Kompetensi Akademik Kejuaraan | C38: 0104256246 | D38: 262710372 | E38: Yusuf Rabani | F38: L
A39: 32 | B39: Kompetensi Akademik Rapor | C39: 0103251939 | D39: 262710375 | E39: Zahran Ariza Saputra | F39: L
E40: Perempuan | F40: =COUNTIF(F8:F39,"P") -> 17
E41: Laki - Laki | F41: =COUNTIF(F10:F40,"L") -> 15
A44: DAFTAR MURID
A45: KELAS X 2
A46: TAHUN PELAJARAN 2026-2027
...

Sheet Kelas XI Angk.33
A1: PEMERINTAH DAERAH PROVINSI JAWA BARAT DINAS PENDIDIKAN SMA NEGERI 2 CIBINONG Jln. Karadenan No. 5 Cibinong Telp/Fax. ( 0251 ) 8654347 Bogor 16913 http://www.sman2cibinong.sch.id email: info@sman2cibinong.sch.id
A3: DAFTAR MURID
A4: KELAS XI A
A5: TAHUN PELAJARAN 2026-2027
A6: Wali Kelas : Teguh Satya Pratama, S.Pd.
A7: NO | B7: NISN / NIS | C7: NAMA | D7: L / P | E7: KELAS
A8: 1 | B8: 0091825991 / 252610009 | C8: Adi Pati Jaya Prana | D8: L | E8: XI A
A9: 2 | B9: 0105770130 / 252610021 | C9: Aik Novitasari | D9: P | E9: XI A
A10: 3 | B10: 0099540724 / 252610022 | C10: Aira Alessia Adha | D10: P | E10: XI A
A11: 4 | B11: 0084218795 / 242510016 | C11: Aisyah Nara Purusa Ningsa | D11: P | E11: XI A
A12: 5 | B12: 0107055406 / 252610032 | C12: Akram Mubarak | D12: L | E12: XI A
A13: 6 | B13: 0102387971 / 252610059 | C13: Ananda Bari Al Kausar | D13: L | E13: XI A
A14: 7 | B14: 0099339799 / 252610060 | C14: Anas Legawa Riyadi | D14: L | E14: XI A
A15: 8 | B15: 0098221239 / 252610079 | C15: Arman Firmansyah | D15: L | E15: XI A
A16: 9 | B16: 0101396555 / 252610080 | C16: Arsyad Khaerul Izzan | D16: L | E16: XI A
A17: 10 | B17: 0102307654 / 252610097 | C17: Aulia Cinta Divia | D17: P | E17: XI A
A18: 11 | B18: 0095522157 / 252610155 | C18: Dhefa Raditya Putra | D18: P | E18: XI A
A19: 12 | B19: 0105616025 / 252610169 | C19: Dindin Andini Suryaman | D19: L | E19: XI A
... A54: 47 | B54: 0108505453 / 252610566 | C54: Zhafirah Dwi Fauziah | D54: P | E54: XI A
C56: Laki - laki | D56: =COUNTIF(D8:D54, "L") -> 23
C57: Perempuan | D57: =COUNTIF(D8:D54, "P") -> 24
A60: DAFTAR MURID
A61: KELAS XI B1
A62: TAHUN PELAJARAN 2026-2027
A63: Wali Kelas : Hj. Srie Endang Wigati, M.Pd
A64: NO | B64: NISN / NIS | C64: NAMA | D64: L / P | E64: KELAS
A65: 1 | B65: 0096128036 / 252610020 | C65: Ahmad Husein Al Latief | D65: L | E65: XI B1
A66: 2 | B66: 3096764634 / 252610025 | C66: Aira Kirana | D66: P | E66: XI B1
A67: 3 | B67: 0087811342 / 252610038 | C67: Alfian Chaniago | D67: L | E67: XI B1
A68: 4 | B68: 3093210071 / 252610042 | C68: Alisa Putri | D68: P | E68: XI B1
A69: 5 | B69: 0094347087 / 252610044 | C69: Aliya Trianzani Putri | D69: P | E69: XI B1
A70: 6 | B70: 0104825356 / 252610057 | C70: Amirah Khalishah Somoal | D70: P | E70: XI B1
A71: 7 | B71: 0104668456 / 252610061 | C71: Andagita Vilnaira Atha | D71: P | E71: XI B1
A72: 8 | B72: 3108667209 / 252610070 | C72: Aqeela Az Zahra | D72: P | E72: XI B1
A73: 9 | B73: 0106376916 / 252610090 | C73: Atharrayhan Abimanyu Pratama | D73: P | E73: XI B1
A74: 10 | B74: 0093343311 / 252610092 | C74: Attar Palestine Taha | D74: L | E74: XI B1
A75: 11 | B75: 0104895570 / 252610099 | C75: Aura Nabilah Zahirah | D75: P | E75: XI B1
A76: 12 | B76: 2099366441 / 252610106 | C76: Ayi Artadinata | D76: P | E76: XI B1
... A111: 47 | B111: 0109499801 / 252610559 | C111: Zafira Salsa Haniah | D111: P | E111: XI B1
C113: LAKI - LAKI | D113: =COUNTIF(D65:D111, "L") -> 11
...

Sheet Kelas XII Angk.32
A1: PEMERINTAH DAERAH PROVINSI JAWA BARAT DINAS PENDIDIKAN SMA NEGERI 2 CIBINONG Jln. Karadenan No. 5 Cibinong Telp/Fax. ( 0251 ) 8654347 Bogor 16913 http://www.sman2cibinong.sch.id email: info@sman2cibinong.sch.id
A3: DAFTAR MURID
A4: KELAS XII A1
A5: TAHUN PELAJARAN 2026-2027
A6: Wali Kelas : Wawan Kurniawan, S.Sos
A7: NO | B7: NISN / NIS | C7: NAMA | D7: L / P | E7: KELAS
A8: 1 | B8: 0082590495 / 242510008 | C8: Agil Umar | D8: L | E8: XII A1
A9: 2 | B9: 0097313548 / 242510011 | C9: Ahmad Riyad Sugiarto | D9: L | E9: XII A1
A10: 3 | B10: 0094510551 / 242510025 | C10: Alifah Khairani Sawaludin | D10: P | E10: XII A1
A11: 4 | B11: 0087298416 / 242510031 | C11: Almira Tungga Dewi | D11: P | E11: XII A1
A12: 5 | B12: 0095546511 / 242510069 | C12: Aulya Mawal Juniar | D12: P | E12: XII A1
A13: 6 | B13: 3086190678 / 242510079 | C13: Bagaskara Arya Perkasa | D13: L | E13: XII A1
A14: 7 | B14: 0107163370 / 242510095 | C14: Chiara Nanda Setiyo Fazria | D14: P | E14: XII A1
A15: 8 | B15: 3092678408 / 242510108 | C15: Devin Anandya Syuja | D15: L | E15: XII A1
A16: 9 | B16: 0095504110 / 242510111 | C16: Diaz Pradana Putra | D16: L | E16: XII A1
A17: 10 | B17: 3081717964 / 242510114 | C17: Disha Ramanda Putra | D17: L | E17: XII A1
A18: 11 | B18: 0083076557 / 242510116 | C18: Donita Aulia Ramadhani | D18: P | E18: XII A1
A19: 12 | B19: 0093137843 / 242510126 | C19: Evania Sarah Ilmira | D19: P | E19: XII A1
... A43: 36 | B43: 0085011294 / 242510432 | C43: Zulfa Laila Mashurah | D43: P | E43: XII A1
C45: Perempuan | D45: =COUNTIF(R[-37]C[0]:R[-2]C[0],"P") -> #ERROR!
C46: Laki-Laki | D46: =COUNTIF(R[-38]C[0]:R[-3]C[0],"L") -> #ERROR!
A50: DAFTAR MURID
A51: KELAS XII A2
A52: TAHUN PELAJARAN 2026-2027
A53: Wali Kelas : Rahmalia Dewi, S.Si
A54: NO | B54: NISN / NIS | C54: NAMA | D54: L / P | E54: KELAS
A55: 1 | B55: 0092385645 / 242510005 | C55: Adinda Khayla | D55: P | E55: XII A2
A56: 2 | B56: 0083638898 / 242510007 | C56: Aditya Narayan | D56: L | E56: XII A2
A57: 3 | B57: 0083581318 / 242510018 | C57: Aisyah Syuja Larasati Sigit | D57: P | E57: XII A2
A58: 4 | B58: 0086733881 / 242510028 | C58: Alma Destianti | D58: P | E58: XII A2
A59: 5 | B59: 0098621054 / 242510037 | C59: Alya Mukhbita Hendriana | D59: P | E59: XII A2
A60: 6 | B60: 0092707821 / 242510046 | C60: Anindita Naranisa Jati | D60: P | E60: XII A2
A61: 7 | B61: 0083016159 / 242510052 | C61: Annisa Nur Fajriya | D61: P | E61: XII A2
A62: 8 | B62: 0083641645 / 242510064 | C62: Atma Pertiwi | D62: P | E62: XII A2
A63: 9 | B63: 0093262366 / 242510104 | C63: Deivar Brimantara | D63: L | E63: XII A2
A64: 10 | B64: 0096851574 / 242510117 | C64: Dzakia Fitri | D64: P | E64: XII A2
A65: 11 | B65: 0092622229 / 242510129 | C65: Fadhilah Dwi Sabrina Nugrahaning Putri | D65: P | E65: XII A2
A66: 12 | B66: 0081916428 / 242510141 | C66: Fellysia Oktafia Fernanda | D66: P | E66: XII A2
... A90: 36 | B90: 0094935892 / 242510412 | C90: Wanda Zhafirah | D90: P | E90: XII A2
C92: Perempuan | D92: =COUNTIF(R[-37]C[0]:R[-2]C[0],"P") -> #ERROR!
...
