Workbook

Sheet Dashboard Presensi SCC
A1: Tahun Ajaran | B1: 2025/2026
A2: Semester I
A5: Persentase Kehadiran
A6: Kelas X
A7: Kelas XI
A8: Kelas XII
A10: Cari Siswa

Sheet Form Presensi SCC
A1: Timestamp | B1: NISN | C1: Status | D1: Email Address | E1: Nama Lengkap | F1: L/P | G1: Angkatan | H1: Kelas | I1: Grup | J1: Mentor | K1: Tanggal Mentoring | L1: Tahun Ajaran | M1: Pertemuan Grup
A2: 45969.318 | B2: 0093629282 | C2: Hadir | D2: m.rizza.alfarisi67@gmail.com
A3: 45969.32 | B3: 3103220251 | C3: Hadir | D3: m.rizza.alfarisi67@gmail.com
A4: 45969.321 | B4: 0107936085 | C4: Hadir | D4: m.rizza.alfarisi67@gmail.com
A5: 45969.321 | B5: 0104328116 | C5: Hadir | D5: m.rizza.alfarisi67@gmail.com
A6: 45969.321 | B6: 0093828028 | C6: Hadir | D6: m.rizza.alfarisi67@gmail.com
A7: 45969.351 | B7: 0094782869 | C7: Hadir | D7: m.rizza.alfarisi67@gmail.com
A8: 45983.335 | B8: 0093629282 | C8: Hadir | D8: m.rizza.alfarisi67@gmail.com
A9: 45983.335 | B9: 0107936085 | C9: Hadir | D9: m.rizza.alfarisi67@gmail.com
A10: 45983.336 | B10: 0105614197 | C10: Hadir | D10: m.rizza.alfarisi67@gmail.com
A11: 45983.336 | B11: 3103220251 | C11: Hadir | D11: m.rizza.alfarisi67@gmail.com
A12: 45983.337 | B12: 0104328116 | C12: Hadir | D12: m.rizza.alfarisi67@gmail.com
A13: 45983.338 | B13: 0094782869 | C13: Hadir | D13: m.rizza.alfarisi67@gmail.com
A14: 45983.338 | B14: 0107487290 | C14: Hadir | D14: m.rizza.alfarisi67@gmail.com
A15: 45983.339 | B15: 0093678218 | C15: Hadir | D15: m.rizza.alfarisi67@gmail.com
A16: 45983.34 | B16: 0093078917 | C16: Hadir | D16: m.rizza.alfarisi67@gmail.com
A17: 45983.341 | B17: 0097446281 | C17: Hadir | D17: m.rizza.alfarisi67@gmail.com
A18: 45983.341 | B18: 0095243962 | C18: Hadir | D18: m.rizza.alfarisi67@gmail.com
A19: 45983.355 | B19: 3092618789 | C19: Hadir | D19: ekadimw35@gmail.com
A20: 45983.38 | B20: 0106995291 | C20: Hadir | D20: ronydurra@gmail.com
A21: 45983.38 | B21: 0108107461 | C21: Hadir | D21: ronydurra@gmail.com
A22: 45983.381 | B22: 0103151970 | C22: Hadir | D22: ronydurra@gmail.com
A23: 45983.381 | B23: 0092626116 | C23: Hadir | D23: ronydurra@gmail.com
A24: 45983.381 | B24: 0095992391 | C24: Hadir | D24: ronydurra@gmail.com
A25: 45983.382 | B25: 0093126257 | C25: Hadir | D25: ronydurra@gmail.com
A26: 45983.382 | B26: 0105914504 | C26: Hadir | D26: ronydurra@gmail.com
A27: 45983.383 | B27: 0092135851 | C27: Hadir | D27: ronydurra@gmail.com
A28: 45983.405 | B28: 0094465097 | C28: Hadir | D28: ekadimw35@gmail.com
A29: 46053.31 | B29: 0093828028 | C29: Hadir | D29: m.rizza.alfarisi67@gmail.com
A30: 46053.312 | B30: 0107487290 | C30: Hadir | D30: m.rizza.alfarisi67@gmail.com
A31: 46053.334 | B31: 0093078917 | C31: Hadir | D31: m.rizza.alfarisi67@gmail.com
... A38: 46053.337 | B38: 0093629282 | C38: Hadir | D38: m.rizza.alfarisi67@gmail.com
A39: 46053.337 | B39: 3103220251 | C39: Hadir | D39: m.rizza.alfarisi67@gmail.com
A40: 46056.263 | B40: 0082590495 / 242510008 | C40: Hadir | D40: skycircle.id@gmail.com
A41: 46067.699 | B41: 0094782869 | C41: Hadir | D41: m.rizza.alfarisi67@gmail.com
A42: 46067.699 | B42: 0093678218 | C42: Hadir | D42: m.rizza.alfarisi67@gmail.com
A43: 46067.699 | B43: 0093078917 | C43: Hadir | D43: m.rizza.alfarisi67@gmail.com
A44: 46067.699 | B44: 0105614197 | C44: Hadir | D44: m.rizza.alfarisi67@gmail.com
A45: 46067.7 | B45: 0095243962 | C45: Hadir | D45: m.rizza.alfarisi67@gmail.com
A46: 46067.704 | B46: 0093629282 | C46: Hadir | D46: m.rizza.alfarisi67@gmail.com
...

Sheet Database Presensi SCC
A1: NO URUT | B1: NO ABSEN | C1: NISN / NIS | D1: NAMA | E1: L/P | F1: ANGKATAN | G1: KELAS TA | H1: Grup TA | I1: Mentor TA | J1: Kelas X | K1: Kelas XI | L1: Kelas XII | M1: Grup X | N1: Grup XI | O1: Grup XII | P1: Link Presensi | Q1: QR Code | R1: Merged Doc ID - Kartu QR Code | S1: Merged Doc URL - Kartu QR Code | T1: Link to merged Doc - Kartu QR Code | U1: Document Merge Status - Kartu QR Code | W1: Total Kehadiran | X1: Total Mentoring | Y1: Persentase
A2: 1 | B2: 1 | C2: 0092626116 / 252610008 | D2: Adhie Bramantyo Faqih - L | E2: L | F2: 33 | G2: X1 | J2: X1 | P2: ="https://docs.google.com/forms/d/e/1FAIpQLSeZ-R1GrWlAPkfaThGqxeTj0QTtrARw4rroxIIepf2kipn1nw/formResponse?usp=pp_url&entry.1313582257="&C2&"&entry.1578404635=Hadir" -> https://docs.google.com/forms/d/e/1FAIpQLSeZ-R1GrWlAPkfaThGqxeTj0QTtrARw4rroxIIepf2kipn1nw/formResponse?usp=pp_url&entry.1313582257=0092626116 / 252610008&entry.1578404635=Hadir | Q2: {=IF(P2:P1382="","", "https://quickchart.io/qr?size=250&text=" & ENCODEURL(P2:P1382))} -> https://quickchart.io/qr?size=250&text=https%3A%2F%2Fdocs.google.com%2Fforms%2Fd%2Fe%2F1FAIpQLSeZ-R1GrWlAPkfaThGqxeTj0QTtrARw4rroxIIepf2kipn1nw%2FformResponse%3Fusp%3Dpp_url%26entry.1313582257%3D0092626116%20%2F%20252610008%26entry.1578404635%3DHadir | R2: 1vT3CS4iZFqZLg_tEljBkkpZG9JMocT_A | S2: https://drive.google.com/file/d/1vT3CS4iZFqZLg_tEljBkkpZG9JMocT_A/view?usp=drivesdk | T2: =HYPERLINK("https://drive.google.com/file/d/1vT3CS4iZFqZLg_tEljBkkpZG9JMocT_A/view?usp=drivesdk","33 - X1 - Adhie Bramantyo Faqih - L") -> 33 - X1 - Adhie Bramantyo Faqih - L | U2: Document successfully created; Document successfully merged; PDF created; Manually run by skycircle.id@gmail.com; Timestamp: Nov 7 2025 2:43 AM | W2: =COUNTIFS('Form Presensi SCC'!$B:$B, IF($C2<>0, TEXT($C2, "0000000000"), $D2), 'Form Presensi SCC'!$C:$C, "Hadir") -> 0 | X2: =MAXIFS($W:$W, $H:$H, $H2) -> 0 | Y2: =(W2/X2)*100% -> #DIV/0!
A3: 2 | B3: 2 | C3: 3103201253 / 252610048 | D3: Almira Dwi Safira - P | E3: P | F3: 33 | G3: X1 | J3: X1 | P3: ="https://docs.google.com/forms/d/e/1FAIpQLSeZ-R1GrWlAPkfaThGqxeTj0QTtrARw4rroxIIepf2kipn1nw/formResponse?usp=pp_url&entry.1313582257="&C3&"&entry.1578404635=Hadir" -> https://docs.google.com/forms/d/e/1FAIpQLSeZ-R1GrWlAPkfaThGqxeTj0QTtrARw4rroxIIepf2kipn1nw/formResponse?usp=pp_url&entry.1313582257=3103201253 / 252610048&entry.1578404635=Hadir | Q3: https://quickchart.io/qr?size=250&text=https%3A%2F%2Fdocs.google.com%2Fforms%2Fd%2Fe%2F1FAIpQLSeZ-R1GrWlAPkfaThGqxeTj0QTtrARw4rroxIIepf2kipn1nw%2FformResponse%3Fusp%3Dpp_url%26entry.1313582257%3D3103201253%20%2F%20252610048%26entry.1578404635%3DHadir | R3: 1mKmnVoLnZHVkK0DIF_UMnaayEkobf0l1 | S3: https://drive.google.com/file/d/1mKmnVoLnZHVkK0DIF_UMnaayEkobf0l1/view?usp=drivesdk | T3: =HYPERLINK("https://drive.google.com/file/d/1mKmnVoLnZHVkK0DIF_UMnaayEkobf0l1/view?usp=drivesdk","33 - X1 - Almira Dwi Safira - P") -> 33 - X1 - Almira Dwi Safira - P | U3: Document successfully created; Document successfully merged; PDF created; Manually run by skycircle.id@gmail.com; Timestamp: Nov 7 2025 2:50 AM | W3: =COUNTIFS('Form Presensi SCC'!$B:$B, IF($C3<>0, TEXT($C3, "0000000000"), $D3), 'Form Presensi SCC'!$C:$C, "Hadir") -> 0 | X3: =MAXIFS($W:$W, $H:$H, $H3) -> 0 | Y3: =(W3/X3)*100% -> #DIV/0!
A4: 3 | B4: 3 | C4: 0102149444 / 252610053 | D4: Alzena Juneeta Talisha Theo - P | E4: P | F4: 33 | G4: X1 | J4: X1 | P4: ="https://docs.google.com/forms/d/e/1FAIpQLSeZ-R1GrWlAPkfaThGqxeTj0QTtrARw4rroxIIepf2kipn1nw/formResponse?usp=pp_url&entry.1313582257="&C4&"&entry.1578404635=Hadir" -> https://docs.google.com/forms/d/e/1FAIpQLSeZ-R1GrWlAPkfaThGqxeTj0QTtrARw4rroxIIepf2kipn1nw/formResponse?usp=pp_url&entry.1313582257=0102149444 / 252610053&entry.1578404635=Hadir | Q4: https://quickchart.io/qr?size=250&text=https%3A%2F%2Fdocs.google.com%2Fforms%2Fd%2Fe%2F1FAIpQLSeZ-R1GrWlAPkfaThGqxeTj0QTtrARw4rroxIIepf2kipn1nw%2FformResponse%3Fusp%3Dpp_url%26entry.1313582257%3D0102149444%20%2F%20252610053%26entry.1578404635%3DHadir | R4: 1d7U49CQ9RJNH2-hBQjzC_hHvscAAXvsr | S4: https://drive.google.com/file/d/1d7U49CQ9RJNH2-hBQjzC_hHvscAAXvsr/view?usp=drivesdk | T4: =HYPERLINK("https://drive.google.com/file/d/1d7U49CQ9RJNH2-hBQjzC_hHvscAAXvsr/view?usp=drivesdk","33 - X1 - Alzena Juneeta Talisha Theo - P") -> 33 - X1 - Alzena Juneeta Talisha Theo - P | U4: Document successfully created; Document successfully merged; PDF created; Manually run by skycircle.id@gmail.com; Timestamp: Nov 7 2025 2:50 AM | W4: =COUNTIFS('Form Presensi SCC'!$B:$B, IF($C4<>0, TEXT($C4, "0000000000"), $D4), 'Form Presensi SCC'!$C:$C, "Hadir") -> 0 | X4: =MAXIFS($W:$W, $H:$H, $H4) -> 0 | Y4: =(W4/X4)*100% -> #DIV/0!
A5: 4 | B5: 4 | C5: 0095992391 / 252610082 | D5: Arya Aditya Gunawan - L | E5: L | F5: 33 | G5: X1 | J5: X1 | P5: ="https://docs.google.com/forms/d/e/1FAIpQLSeZ-R1GrWlAPkfaThGqxeTj0QTtrARw4rroxIIepf2kipn1nw/formResponse?usp=pp_url&entry.1313582257="&C5&"&entry.1578404635=Hadir" -> https://docs.google.com/forms/d/e/1FAIpQLSeZ-R1GrWlAPkfaThGqxeTj0QTtrARw4rroxIIepf2kipn1nw/formResponse?usp=pp_url&entry.1313582257=0095992391 / 252610082&entry.1578404635=Hadir | Q5: https://quickchart.io/qr?size=250&text=https%3A%2F%2Fdocs.google.com%2Fforms%2Fd%2Fe%2F1FAIpQLSeZ-R1GrWlAPkfaThGqxeTj0QTtrARw4rroxIIepf2kipn1nw%2FformResponse%3Fusp%3Dpp_url%26entry.1313582257%3D0095992391%20%2F%20252610082%26entry.1578404635%3DHadir | R5: 1LNiRTYHv6w9YVnhAR2HLyIcVFJQpcjze | S5: https://drive.google.com/file/d/1LNiRTYHv6w9YVnhAR2HLyIcVFJQpcjze/view?usp=drivesdk | T5: =HYPERLINK("https://drive.google.com/file/d/1LNiRTYHv6w9YVnhAR2HLyIcVFJQpcjze/view?usp=drivesdk","33 - X1 - Arya Aditya Gunawan - L") -> 33 - X1 - Arya Aditya Gunawan - L | U5: Document successfully created; Document successfully merged; PDF created; Manually run by skycircle.id@gmail.com; Timestamp: Nov 7 2025 2:51 AM | W5: =COUNTIFS('Form Presensi SCC'!$B:$B, IF($C5<>0, TEXT($C5, "0000000000"), $D5), 'Form Presensi SCC'!$C:$C, "Hadir") -> 0 | X5: =MAXIFS($W:$W, $H:$H, $H5) -> 0 | Y5: =(W5/X5)*100% -> #DIV/0!
A6: 5 | B6: 5 | C6: 0106142601 / 252610083 | D6: Aryasatia Pradipta - P | E6: P | F6: 33 | G6: X1 | J6: X1 | P6: ="https://docs.google.com/forms/d/e/1FAIpQLSeZ-R1GrWlAPkfaThGqxeTj0QTtrARw4rroxIIepf2kipn1nw/formResponse?usp=pp_url&entry.1313582257="&C6&"&entry.1578404635=Hadir" -> https://docs.google.com/forms/d/e/1FAIpQLSeZ-R1GrWlAPkfaThGqxeTj0QTtrARw4rroxIIepf2kipn1nw/formResponse?usp=pp_url&entry.1313582257=0106142601 / 252610083&entry.1578404635=Hadir | Q6: https://quickchart.io/qr?size=250&text=https%3A%2F%2Fdocs.google.com%2Fforms%2Fd%2Fe%2F1FAIpQLSeZ-R1GrWlAPkfaThGqxeTj0QTtrARw4rroxIIepf2kipn1nw%2FformResponse%3Fusp%3Dpp_url%26entry.1313582257%3D0106142601%20%2F%20252610083%26entry.1578404635%3DHadir | R6: 1IvfC4ixA8_XmXd4iM5ff5AmblC3pElr0 | S6: https://drive.google.com/file/d/1IvfC4ixA8_XmXd4iM5ff5AmblC3pElr0/view?usp=drivesdk | T6: =HYPERLINK("https://drive.google.com/file/d/1IvfC4ixA8_XmXd4iM5ff5AmblC3pElr0/view?usp=drivesdk","33 - X1 - Aryasatia Pradipta - P") -> 33 - X1 - Aryasatia Pradipta - P | U6: Document successfully created; Document successfully merged; PDF created; Manually run by skycircle.id@gmail.com; Timestamp: Nov 7 2025 2:51 AM | W6: =COUNTIFS('Form Presensi SCC'!$B:$B, IF($C6<>0, TEXT($C6, "0000000000"), $D6), 'Form Presensi SCC'!$C:$C, "Hadir") -> 0 | X6: =MAXIFS($W:$W, $H:$H, $H6) -> 0 | Y6: =(W6/X6)*100% -> #DIV/0!
A7: 6 | B7: 6 | C7: 0108104548 / 252610087 | D7: Asyifa Diandra Bayu - P | E7: P | F7: 33 | G7: X1 | J7: X1 | P7: ="https://docs.google.com/forms/d/e/1FAIpQLSeZ-R1GrWlAPkfaThGqxeTj0QTtrARw4rroxIIepf2kipn1nw/formResponse?usp=pp_url&entry.1313582257="&C7&"&entry.1578404635=Hadir" -> https://docs.google.com/forms/d/e/1FAIpQLSeZ-R1GrWlAPkfaThGqxeTj0QTtrARw4rroxIIepf2kipn1nw/formResponse?usp=pp_url&entry.1313582257=0108104548 / 252610087&entry.1578404635=Hadir | Q7: https://quickchart.io/qr?size=250&text=https%3A%2F%2Fdocs.google.com%2Fforms%2Fd%2Fe%2F1FAIpQLSeZ-R1GrWlAPkfaThGqxeTj0QTtrARw4rroxIIepf2kipn1nw%2FformResponse%3Fusp%3Dpp_url%26entry.1313582257%3D0108104548%20%2F%20252610087%26entry.1578404635%3DHadir | R7: 10upqMCystGLOOuj8IXeBYoCPDfZ9BeId | S7: https://drive.google.com/file/d/10upqMCystGLOOuj8IXeBYoCPDfZ9BeId/view?usp=drivesdk | T7: =HYPERLINK("https://drive.google.com/file/d/10upqMCystGLOOuj8IXeBYoCPDfZ9BeId/view?usp=drivesdk","33 - X1 - Asyifa Diandra Bayu - P") -> 33 - X1 - Asyifa Diandra Bayu - P | U7: Document successfully created; Document successfully merged; PDF created; Manually run by skycircle.id@gmail.com; Timestamp: Nov 7 2025 2:51 AM | W7: =COUNTIFS('Form Presensi SCC'!$B:$B, IF($C7<>0, TEXT($C7, "0000000000"), $D7), 'Form Presensi SCC'!$C:$C, "Hadir") -> 0 | X7: =MAXIFS($W:$W, $H:$H, $H7) -> 0 | Y7: =(W7/X7)*100% -> #DIV/0!
A8: 7 | B8: 7 | C8: 0103045473 / 252610088 | D8: Asyifa Maulidia Salsabila - P | E8: P | F8: 33 | G8: X1 | J8: X1 | P8: ="https://docs.google.com/forms/d/e/1FAIpQLSeZ-R1GrWlAPkfaThGqxeTj0QTtrARw4rroxIIepf2kipn1nw/formResponse?usp=pp_url&entry.1313582257="&C8&"&entry.1578404635=Hadir" -> https://docs.google.com/forms/d/e/1FAIpQLSeZ-R1GrWlAPkfaThGqxeTj0QTtrARw4rroxIIepf2kipn1nw/formResponse?usp=pp_url&entry.1313582257=0103045473 / 252610088&entry.1578404635=Hadir | Q8: https://quickchart.io/qr?size=250&text=https%3A%2F%2Fdocs.google.com%2Fforms%2Fd%2Fe%2F1FAIpQLSeZ-R1GrWlAPkfaThGqxeTj0QTtrARw4rroxIIepf2kipn1nw%2FformResponse%3Fusp%3Dpp_url%26entry.1313582257%3D0103045473%20%2F%20252610088%26entry.1578404635%3DHadir | R8: 1ZImG2x2uc38nnR6zZWUTE7w5Gq5qaqVc | S8: https://drive.google.com/file/d/1ZImG2x2uc38nnR6zZWUTE7w5Gq5qaqVc/view?usp=drivesdk | T8: =HYPERLINK("https://drive.google.com/file/d/1ZImG2x2uc38nnR6zZWUTE7w5Gq5qaqVc/view?usp=drivesdk","33 - X1 - Asyifa Maulidia Salsabila - P") -> 33 - X1 - Asyifa Maulidia Salsabila - P | U8: Document successfully created; Document successfully merged; PDF created; Manually run by skycircle.id@gmail.com; Timestamp: Nov 7 2025 2:51 AM | W8: =COUNTIFS('Form Presensi SCC'!$B:$B, IF($C8<>0, TEXT($C8, "0000000000"), $D8), 'Form Presensi SCC'!$C:$C, "Hadir") -> 0 | X8: =MAXIFS($W:$W, $H:$H, $H8) -> 0 | Y8: =(W8/X8)*100% -> #DIV/0!
A9: 8 | B9: 8 | C9: 0109105725 / 252610100 | D9: Aurelia Langit Callysta - P | E9: P | F9: 33 | G9: X1 | J9: X1 | P9: ="https://docs.google.com/forms/d/e/1FAIpQLSeZ-R1GrWlAPkfaThGqxeTj0QTtrARw4rroxIIepf2kipn1nw/formResponse?usp=pp_url&entry.1313582257="&C9&"&entry.1578404635=Hadir" -> https://docs.google.com/forms/d/e/1FAIpQLSeZ-R1GrWlAPkfaThGqxeTj0QTtrARw4rroxIIepf2kipn1nw/formResponse?usp=pp_url&entry.1313582257=0109105725 / 252610100&entry.1578404635=Hadir | Q9: https://quickchart.io/qr?size=250&text=https%3A%2F%2Fdocs.google.com%2Fforms%2Fd%2Fe%2F1FAIpQLSeZ-R1GrWlAPkfaThGqxeTj0QTtrARw4rroxIIepf2kipn1nw%2FformResponse%3Fusp%3Dpp_url%26entry.1313582257%3D0109105725%20%2F%20252610100%26entry.1578404635%3DHadir | R9: 1rvQo4Ey68VFrcETscC7InUaTRI1kIUWw | S9: https://drive.google.com/file/d/1rvQo4Ey68VFrcETscC7InUaTRI1kIUWw/view?usp=drivesdk | T9: =HYPERLINK("https://drive.google.com/file/d/1rvQo4Ey68VFrcETscC7InUaTRI1kIUWw/view?usp=drivesdk","33 - X1 - Aurelia Langit Callysta - P") -> 33 - X1 - Aurelia Langit Callysta - P | U9: Document successfully created; Document successfully merged; PDF created; Manually run by skycircle.id@gmail.com; Timestamp: Nov 7 2025 2:51 AM | W9: =COUNTIFS('Form Presensi SCC'!$B:$B, IF($C9<>0, TEXT($C9, "0000000000"), $D9), 'Form Presensi SCC'!$C:$C, "Hadir") -> 0 | X9: =MAXIFS($W:$W, $H:$H, $H9) -> 0 | Y9: =(W9/X9)*100% -> #DIV/0!
A10: 9 | B10: 9 | C10: 0096394871 / 252610101 | D10: Aurelia Septiani Putri - P | E10: P | F10: 33 | G10: X1 | J10: X1 | P10: ="https://docs.google.com/forms/d/e/1FAIpQLSeZ-R1GrWlAPkfaThGqxeTj0QTtrARw4rroxIIepf2kipn1nw/formResponse?usp=pp_url&entry.1313582257="&C10&"&entry.1578404635=Hadir" -> https://docs.google.com/forms/d/e/1FAIpQLSeZ-R1GrWlAPkfaThGqxeTj0QTtrARw4rroxIIepf2kipn1nw/formResponse?usp=pp_url&entry.1313582257=0096394871 / 252610101&entry.1578404635=Hadir | Q10: https://quickchart.io/qr?size=250&text=https%3A%2F%2Fdocs.google.com%2Fforms%2Fd%2Fe%2F1FAIpQLSeZ-R1GrWlAPkfaThGqxeTj0QTtrARw4rroxIIepf2kipn1nw%2FformResponse%3Fusp%3Dpp_url%26entry.1313582257%3D0096394871%20%2F%20252610101%26entry.1578404635%3DHadir | R10: 1b-GDSmMzqildFBtX8OSafkbnN90HrSEe | S10: https://drive.google.com/file/d/1b-GDSmMzqildFBtX8OSafkbnN90HrSEe/view?usp=drivesdk | T10: =HYPERLINK("https://drive.google.com/file/d/1b-GDSmMzqildFBtX8OSafkbnN90HrSEe/view?usp=drivesdk","33 - X1 - Aurelia Septiani Putri - P") -> 33 - X1 - Aurelia Septiani Putri - P | U10: Document successfully created; Document successfully merged; PDF created; Manually run by skycircle.id@gmail.com; Timestamp: Nov 7 2025 2:51 AM | W10: =COUNTIFS('Form Presensi SCC'!$B:$B, IF($C10<>0, TEXT($C10, "0000000000"), $D10), 'Form Presensi SCC'!$C:$C, "Hadir") -> 0 | X10: =MAXIFS($W:$W, $H:$H, $H10) -> 0 | Y10: =(W10/X10)*100% -> #DIV/0!
A11: 10 | B11: 10 | C11: 0099038184 / 252610109 | D11: Azalia Maheswari Christabel - P | E11: P | F11: 33 | G11: X1 | J11: X1 | P11: ="https://docs.google.com/forms/d/e/1FAIpQLSeZ-R1GrWlAPkfaThGqxeTj0QTtrARw4rroxIIepf2kipn1nw/formResponse?usp=pp_url&entry.1313582257="&C11&"&entry.1578404635=Hadir" -> https://docs.google.com/forms/d/e/1FAIpQLSeZ-R1GrWlAPkfaThGqxeTj0QTtrARw4rroxIIepf2kipn1nw/formResponse?usp=pp_url&entry.1313582257=0099038184 / 252610109&entry.1578404635=Hadir | Q11: https://quickchart.io/qr?size=250&text=https%3A%2F%2Fdocs.google.com%2Fforms%2Fd%2Fe%2F1FAIpQLSeZ-R1GrWlAPkfaThGqxeTj0QTtrARw4rroxIIepf2kipn1nw%2FformResponse%3Fusp%3Dpp_url%26entry.1313582257%3D0099038184%20%2F%20252610109%26entry.1578404635%3DHadir | R11: 1yx3LelcXw_e83FhlIETtKt3gLFBbBxee | S11: https://drive.google.com/file/d/1yx3LelcXw_e83FhlIETtKt3gLFBbBxee/view?usp=drivesdk | T11: =HYPERLINK("https://drive.google.com/file/d/1yx3LelcXw_e83FhlIETtKt3gLFBbBxee/view?usp=drivesdk","33 - X1 - Azalia Maheswari Christabel - P") -> 33 - X1 - Azalia Maheswari Christabel - P | U11: Document successfully created; Document successfully merged; PDF created; Manually run by skycircle.id@gmail.com; Timestamp: Nov 7 2025 2:51 AM | W11: =COUNTIFS('Form Presensi SCC'!$B:$B, IF($C11<>0, TEXT($C11, "0000000000"), $D11), 'Form Presensi SCC'!$C:$C, "Hadir") -> 0 | X11: =MAXIFS($W:$W, $H:$H, $H11) -> 0 | Y11: =(W11/X11)*100% -> #DIV/0!
A12: 11 | B12: 11 | C12: 0096477713 / 252610122 | D12: Bilqis Anwar Thebe - P | E12: P | F12: 33 | G12: X1 | J12: X1 | P12: ="https://docs.google.com/forms/d/e/1FAIpQLSeZ-R1GrWlAPkfaThGqxeTj0QTtrARw4rroxIIepf2kipn1nw/formResponse?usp=pp_url&entry.1313582257="&C12&"&entry.1578404635=Hadir" -> https://docs.google.com/forms/d/e/1FAIpQLSeZ-R1GrWlAPkfaThGqxeTj0QTtrARw4rroxIIepf2kipn1nw/formResponse?usp=pp_url&entry.1313582257=0096477713 / 252610122&entry.1578404635=Hadir | Q12: https://quickchart.io/qr?size=250&text=https%3A%2F%2Fdocs.google.com%2Fforms%2Fd%2Fe%2F1FAIpQLSeZ-R1GrWlAPkfaThGqxeTj0QTtrARw4rroxIIepf2kipn1nw%2FformResponse%3Fusp%3Dpp_url%26entry.1313582257%3D0096477713%20%2F%20252610122%26entry.1578404635%3DHadir | R12: 1tS8oCGyjXE_iUjrmtYwoF0c6IxPj5bwe | S12: https://drive.google.com/file/d/1tS8oCGyjXE_iUjrmtYwoF0c6IxPj5bwe/view?usp=drivesdk | T12: =HYPERLINK("https://drive.google.com/file/d/1tS8oCGyjXE_iUjrmtYwoF0c6IxPj5bwe/view?usp=drivesdk","33 - X1 - Bilqis Anwar Thebe - P") -> 33 - X1 - Bilqis Anwar Thebe - P | U12: Document successfully created; Document successfully merged; PDF created; Manually run by skycircle.id@gmail.com; Timestamp: Nov 7 2025 2:52 AM | W12: =COUNTIFS('Form Presensi SCC'!$B:$B, IF($C12<>0, TEXT($C12, "0000000000"), $D12), 'Form Presensi SCC'!$C:$C, "Hadir") -> 1 | X12: =MAXIFS($W:$W, $H:$H, $H12) -> 0 | Y12: =(W12/X12)*100% -> #DIV/0!
A13: 12 | B13: 12 | C13: 0106995291 / 252610126 | D13: Bimo Armani Aulia Putra - L | E13: L | F13: 33 | G13: X1 | J13: X1 | P13: ="https://docs.google.com/forms/d/e/1FAIpQLSeZ-R1GrWlAPkfaThGqxeTj0QTtrARw4rroxIIepf2kipn1nw/formResponse?usp=pp_url&entry.1313582257="&C13&"&entry.1578404635=Hadir" -> https://docs.google.com/forms/d/e/1FAIpQLSeZ-R1GrWlAPkfaThGqxeTj0QTtrARw4rroxIIepf2kipn1nw/formResponse?usp=pp_url&entry.1313582257=0106995291 / 252610126&entry.1578404635=Hadir | Q13: https://quickchart.io/qr?size=250&text=https%3A%2F%2Fdocs.google.com%2Fforms%2Fd%2Fe%2F1FAIpQLSeZ-R1GrWlAPkfaThGqxeTj0QTtrARw4rroxIIepf2kipn1nw%2FformResponse%3Fusp%3Dpp_url%26entry.1313582257%3D0106995291%20%2F%20252610126%26entry.1578404635%3DHadir | R13: 1EmJkPoxdTJ-gQWZdii-D138hhWBcspG4 | S13: https://drive.google.com/file/d/1EmJkPoxdTJ-gQWZdii-D138hhWBcspG4/view?usp=drivesdk | T13: =HYPERLINK("https://drive.google.com/file/d/1EmJkPoxdTJ-gQWZdii-D138hhWBcspG4/view?usp=drivesdk","33 - X1 - Bimo Armani Aulia Putra - L") -> 33 - X1 - Bimo Armani Aulia Putra - L | U13: Document successfully created; Document successfully merged; PDF created; Manually run by skycircle.id@gmail.com; Timestamp: Nov 7 2025 2:52 AM | W13: =COUNTIFS('Form Presensi SCC'!$B:$B, IF($C13<>0, TEXT($C13, "0000000000"), $D13), 'Form Presensi SCC'!$C:$C, "Hadir") -> 0 | X13: =MAXIFS($W:$W, $H:$H, $H13) -> 0 | Y13: =(W13/X13)*100% -> #DIV/0!
A14: 13 | B14: 13 | C14: 0094126705 / 252610130 | D14: Callysta Tuchi Solin - P | E14: P | F14: 33 | G14: X1 | J14: X1 | P14: ="https://docs.google.com/forms/d/e/1FAIpQLSeZ-R1GrWlAPkfaThGqxeTj0QTtrARw4rroxIIepf2kipn1nw/formResponse?usp=pp_url&entry.1313582257="&C14&"&entry.1578404635=Hadir" -> https://docs.google.com/forms/d/e/1FAIpQLSeZ-R1GrWlAPkfaThGqxeTj0QTtrARw4rroxIIepf2kipn1nw/formResponse?usp=pp_url&entry.1313582257=0094126705 / 252610130&entry.1578404635=Hadir | Q14: https://quickchart.io/qr?size=250&text=https%3A%2F%2Fdocs.google.com%2Fforms%2Fd%2Fe%2F1FAIpQLSeZ-R1GrWlAPkfaThGqxeTj0QTtrARw4rroxIIepf2kipn1nw%2FformResponse%3Fusp%3Dpp_url%26entry.1313582257%3D0094126705%20%2F%20252610130%26entry.1578404635%3DHadir | R14: 1V36ZPnUswM9ug8uwlwbe7s6iXPAB3HIh | S14: https://drive.google.com/file/d/1V36ZPnUswM9ug8uwlwbe7s6iXPAB3HIh/view?usp=drivesdk | T14: =HYPERLINK("https://drive.google.com/file/d/1V36ZPnUswM9ug8uwlwbe7s6iXPAB3HIh/view?usp=drivesdk","33 - X1 - Callysta Tuchi Solin - P") -> 33 - X1 - Callysta Tuchi Solin - P | U14: Document successfully created; Document successfully merged; PDF created; Manually run by skycircle.id@gmail.com; Timestamp: Nov 7 2025 2:52 AM | W14: =COUNTIFS('Form Presensi SCC'!$B:$B, IF($C14<>0, TEXT($C14, "0000000000"), $D14), 'Form Presensi SCC'!$C:$C, "Hadir") -> 0 | X14: =MAXIFS($W:$W, $H:$H, $H14) -> 0 | Y14: =(W14/X14)*100% -> #DIV/0!
A15: 14 | B15: 14 | C15: 0105914504 / 252610171 | D15: Diwangkara Rizki Rabbani - L | E15: L | F15: 33 | G15: X1 | J15: X1 | P15: ="https://docs.google.com/forms/d/e/1FAIpQLSeZ-R1GrWlAPkfaThGqxeTj0QTtrARw4rroxIIepf2kipn1nw/formResponse?usp=pp_url&entry.1313582257="&C15&"&entry.1578404635=Hadir" -> https://docs.google.com/forms/d/e/1FAIpQLSeZ-R1GrWlAPkfaThGqxeTj0QTtrARw4rroxIIepf2kipn1nw/formResponse?usp=pp_url&entry.1313582257=0105914504 / 252610171&entry.1578404635=Hadir | Q15: https://quickchart.io/qr?size=250&text=https%3A%2F%2Fdocs.google.com%2Fforms%2Fd%2Fe%2F1FAIpQLSeZ-R1GrWlAPkfaThGqxeTj0QTtrARw4rroxIIepf2kipn1nw%2FformResponse%3Fusp%3Dpp_url%26entry.1313582257%3D0105914504%20%2F%20252610171%26entry.1578404635%3DHadir | R15: 1Y17P9BaSObYaTN9WA1Z9-poUfGpD2LLP | S15: https://drive.google.com/file/d/1Y17P9BaSObYaTN9WA1Z9-poUfGpD2LLP/view?usp=drivesdk | T15: =HYPERLINK("https://drive.google.com/file/d/1Y17P9BaSObYaTN9WA1Z9-poUfGpD2LLP/view?usp=drivesdk","33 - X1 - Diwangkara Rizki Rabbani - L") -> 33 - X1 - Diwangkara Rizki Rabbani - L | U15: Document successfully created; Document successfully merged; PDF created; Manually run by skycircle.id@gmail.com; Timestamp: Nov 7 2025 2:52 AM | W15: =COUNTIFS('Form Presensi SCC'!$B:$B, IF($C15<>0, TEXT($C15, "0000000000"), $D15), 'Form Presensi SCC'!$C:$C, "Hadir") -> 0 | X15: =MAXIFS($W:$W, $H:$H, $H15) -> 0 | Y15: =(W15/X15)*100% -> #DIV/0!
A16: 15 | B16: 15 | C16: 0092097491 / 252610175 | D16: Dzahra Miftahuljanah - P | E16: P | F16: 33 | G16: X1 | J16: X1 | P16: ="https://docs.google.com/forms/d/e/1FAIpQLSeZ-R1GrWlAPkfaThGqxeTj0QTtrARw4rroxIIepf2kipn1nw/formResponse?usp=pp_url&entry.1313582257="&C16&"&entry.1578404635=Hadir" -> https://docs.google.com/forms/d/e/1FAIpQLSeZ-R1GrWlAPkfaThGqxeTj0QTtrARw4rroxIIepf2kipn1nw/formResponse?usp=pp_url&entry.1313582257=0092097491 / 252610175&entry.1578404635=Hadir | Q16: https://quickchart.io/qr?size=250&text=https%3A%2F%2Fdocs.google.com%2Fforms%2Fd%2Fe%2F1FAIpQLSeZ-R1GrWlAPkfaThGqxeTj0QTtrARw4rroxIIepf2kipn1nw%2FformResponse%3Fusp%3Dpp_url%26entry.1313582257%3D0092097491%20%2F%20252610175%26entry.1578404635%3DHadir | R16: 1gdHQkc3oC094D12II38YKtMKEBJWo6Sv | S16: https://drive.google.com/file/d/1gdHQkc3oC094D12II38YKtMKEBJWo6Sv/view?usp=drivesdk | T16: =HYPERLINK("https://drive.google.com/file/d/1gdHQkc3oC094D12II38YKtMKEBJWo6Sv/view?usp=drivesdk","33 - X1 - Dzahra Miftahuljanah - P") -> 33 - X1 - Dzahra Miftahuljanah - P | U16: Document successfully created; Document successfully merged; PDF created; Manually run by skycircle.id@gmail.com; Timestamp: Nov 7 2025 2:52 AM | W16: =COUNTIFS('Form Presensi SCC'!$B:$B, IF($C16<>0, TEXT($C16, "0000000000"), $D16), 'Form Presensi SCC'!$C:$C, "Hadir") -> 0 | X16: =MAXIFS($W:$W, $H:$H, $H16) -> 0 | Y16: =(W16/X16)*100% -> #DIV/0!
A17: 16 | B17: 16 | C17: 0102644442 / 252610193 | D17: Fakhri Haikal Alvito Rachmat - L | E17: L | F17: 33 | G17: X1 | J17: X1 | P17: ="https://docs.google.com/forms/d/e/1FAIpQLSeZ-R1GrWlAPkfaThGqxeTj0QTtrARw4rroxIIepf2kipn1nw/formResponse?usp=pp_url&entry.1313582257="&C17&"&entry.1578404635=Hadir" -> https://docs.google.com/forms/d/e/1FAIpQLSeZ-R1GrWlAPkfaThGqxeTj0QTtrARw4rroxIIepf2kipn1nw/formResponse?usp=pp_url&entry.1313582257=0102644442 / 252610193&entry.1578404635=Hadir | Q17: https://quickchart.io/qr?size=250&text=https%3A%2F%2Fdocs.google.com%2Fforms%2Fd%2Fe%2F1FAIpQLSeZ-R1GrWlAPkfaThGqxeTj0QTtrARw4rroxIIepf2kipn1nw%2FformResponse%3Fusp%3Dpp_url%26entry.1313582257%3D0102644442%20%2F%20252610193%26entry.1578404635%3DHadir | R17: 1DkiMBRJidCu4rpARd_sGeCMxkHoE_dEf | S17: https://drive.google.com/file/d/1DkiMBRJidCu4rpARd_sGeCMxkHoE_dEf/view?usp=drivesdk | T17: =HYPERLINK("https://drive.google.com/file/d/1DkiMBRJidCu4rpARd_sGeCMxkHoE_dEf/view?usp=drivesdk","33 - X1 - Fakhri Haikal Alvito Rachmat - L") -> 33 - X1 - Fakhri Haikal Alvito Rachmat - L | U17: Document successfully created; Document successfully merged; PDF created; Manually run by skycircle.id@gmail.com; Timestamp: Nov 7 2025 2:52 AM | W17: =COUNTIFS('Form Presensi SCC'!$B:$B, IF($C17<>0, TEXT($C17, "0000000000"), $D17), 'Form Presensi SCC'!$C:$C, "Hadir") -> 0 | X17: =MAXIFS($W:$W, $H:$H, $H17) -> 0 | Y17: =(W17/X17)*100% -> #DIV/0!
A18: 17 | B18: 17 | C18: 0107657965 / 252610202 | D18: Fathi Azzam Hawwari - L | E18: L | F18: 33 | G18: X1 | J18: X1 | P18: ="https://docs.google.com/forms/d/e/1FAIpQLSeZ-R1GrWlAPkfaThGqxeTj0QTtrARw4rroxIIepf2kipn1nw/formResponse?usp=pp_url&entry.1313582257="&C18&"&entry.1578404635=Hadir" -> https://docs.google.com/forms/d/e/1FAIpQLSeZ-R1GrWlAPkfaThGqxeTj0QTtrARw4rroxIIepf2kipn1nw/formResponse?usp=pp_url&entry.1313582257=0107657965 / 252610202&entry.1578404635=Hadir | Q18: https://quickchart.io/qr?size=250&text=https%3A%2F%2Fdocs.google.com%2Fforms%2Fd%2Fe%2F1FAIpQLSeZ-R1GrWlAPkfaThGqxeTj0QTtrARw4rroxIIepf2kipn1nw%2FformResponse%3Fusp%3Dpp_url%26entry.1313582257%3D0107657965%20%2F%20252610202%26entry.1578404635%3DHadir | R18: 1Qoz2BWw-WzedC8leFgPiQ4Ljuz6FTB4b | S18: https://drive.google.com/file/d/1Qoz2BWw-WzedC8leFgPiQ4Ljuz6FTB4b/view?usp=drivesdk | T18: =HYPERLINK("https://drive.google.com/file/d/1Qoz2BWw-WzedC8leFgPiQ4Ljuz6FTB4b/view?usp=drivesdk","33 - X1 - Fathi Azzam Hawwari - L") -> 33 - X1 - Fathi Azzam Hawwari - L | U18: Document successfully created; Document successfully merged; PDF created; Manually run by skycircle.id@gmail.com; Timestamp: Nov 7 2025 2:53 AM | W18: =COUNTIFS('Form Presensi SCC'!$B:$B, IF($C18<>0, TEXT($C18, "0000000000"), $D18), 'Form Presensi SCC'!$C:$C, "Hadir") -> 0 | X18: =MAXIFS($W:$W, $H:$H, $H18) -> 0 | Y18: =(W18/X18)*100% -> #DIV/0!
A19: 18 | B19: 18 | C19: 0095023834 / 252610206 | D19: Fatimah Aszahra - P | E19: P | F19: 33 | G19: X1 | J19: X1 | P19: ="https://docs.google.com/forms/d/e/1FAIpQLSeZ-R1GrWlAPkfaThGqxeTj0QTtrARw4rroxIIepf2kipn1nw/formResponse?usp=pp_url&entry.1313582257="&C19&"&entry.1578404635=Hadir" -> https://docs.google.com/forms/d/e/1FAIpQLSeZ-R1GrWlAPkfaThGqxeTj0QTtrARw4rroxIIepf2kipn1nw/formResponse?usp=pp_url&entry.1313582257=0095023834 / 252610206&entry.1578404635=Hadir | Q19: https://quickchart.io/qr?size=250&text=https%3A%2F%2Fdocs.google.com%2Fforms%2Fd%2Fe%2F1FAIpQLSeZ-R1GrWlAPkfaThGqxeTj0QTtrARw4rroxIIepf2kipn1nw%2FformResponse%3Fusp%3Dpp_url%26entry.1313582257%3D0095023834%20%2F%20252610206%26entry.1578404635%3DHadir | R19: 1SXGJ8Fa5qpDhxnKbC01wKIyMtkQ0FLnG | S19: https://drive.google.com/file/d/1SXGJ8Fa5qpDhxnKbC01wKIyMtkQ0FLnG/view?usp=drivesdk | T19: =HYPERLINK("https://drive.google.com/file/d/1SXGJ8Fa5qpDhxnKbC01wKIyMtkQ0FLnG/view?usp=drivesdk","33 - X1 - Fatimah Aszahra - P") -> 33 - X1 - Fatimah Aszahra - P | U19: Document successfully created; Document successfully merged; PDF created; Manually run by skycircle.id@gmail.com; Timestamp: Nov 7 2025 2:53 AM | W19: =COUNTIFS('Form Presensi SCC'!$B:$B, IF($C19<>0, TEXT($C19, "0000000000"), $D19), 'Form Presensi SCC'!$C:$C, "Hadir") -> 0 | X19: =MAXIFS($W:$W, $H:$H, $H19) -> 0 | Y19: =(W19/X19)*100% -> #DIV/0!
A20: 19 | B20: 19 | C20: 0094631117 / 252610224 | D20: Gwenna Irene Winata - P | E20: P | F20: 33 | G20: X1 | J20: X1 | P20: ="https://docs.google.com/forms/d/e/1FAIpQLSeZ-R1GrWlAPkfaThGqxeTj0QTtrARw4rroxIIepf2kipn1nw/formResponse?usp=pp_url&entry.1313582257="&C20&"&entry.1578404635=Hadir" -> https://docs.google.com/forms/d/e/1FAIpQLSeZ-R1GrWlAPkfaThGqxeTj0QTtrARw4rroxIIepf2kipn1nw/formResponse?usp=pp_url&entry.1313582257=0094631117 / 252610224&entry.1578404635=Hadir | Q20: https://quickchart.io/qr?size=250&text=https%3A%2F%2Fdocs.google.com%2Fforms%2Fd%2Fe%2F1FAIpQLSeZ-R1GrWlAPkfaThGqxeTj0QTtrARw4rroxIIepf2kipn1nw%2FformResponse%3Fusp%3Dpp_url%26entry.1313582257%3D0094631117%20%2F%20252610224%26entry.1578404635%3DHadir | R20: 15IXPQVUuOt8H540EqjLVe6zzkm15WpLl | S20: https://drive.google.com/file/d/15IXPQVUuOt8H540EqjLVe6zzkm15WpLl/view?usp=drivesdk | T20: =HYPERLINK("https://drive.google.com/file/d/15IXPQVUuOt8H540EqjLVe6zzkm15WpLl/view?usp=drivesdk","33 - X1 - Gwenna Irene Winata - P") -> 33 - X1 - Gwenna Irene Winata - P | U20: Document successfully created; Document successfully merged; PDF created; Manually run by skycircle.id@gmail.com; Timestamp: Nov 7 2025 2:53 AM | W20: =COUNTIFS('Form Presensi SCC'!$B:$B, IF($C20<>0, TEXT($C20, "0000000000"), $D20), 'Form Presensi SCC'!$C:$C, "Hadir") -> 0 | X20: =MAXIFS($W:$W, $H:$H, $H20) -> 0 | Y20: =(W20/X20)*100% -> #DIV/0!
A21: 20 | B21: 20 | C21: 0092679798 / 252610239 | D21: Jasmine Zahira Ramadhani - P | E21: P | F21: 33 | G21: X1 | J21: X1 | P21: ="https://docs.google.com/forms/d/e/1FAIpQLSeZ-R1GrWlAPkfaThGqxeTj0QTtrARw4rroxIIepf2kipn1nw/formResponse?usp=pp_url&entry.1313582257="&C21&"&entry.1578404635=Hadir" -> https://docs.google.com/forms/d/e/1FAIpQLSeZ-R1GrWlAPkfaThGqxeTj0QTtrARw4rroxIIepf2kipn1nw/formResponse?usp=pp_url&entry.1313582257=0092679798 / 252610239&entry.1578404635=Hadir | Q21: https://quickchart.io/qr?size=250&text=https%3A%2F%2Fdocs.google.com%2Fforms%2Fd%2Fe%2F1FAIpQLSeZ-R1GrWlAPkfaThGqxeTj0QTtrARw4rroxIIepf2kipn1nw%2FformResponse%3Fusp%3Dpp_url%26entry.1313582257%3D0092679798%20%2F%20252610239%26entry.1578404635%3DHadir | R21: 1EGzdBFstUsXDWTMpSUXHrpW133xlD9yz | S21: https://drive.google.com/file/d/1EGzdBFstUsXDWTMpSUXHrpW133xlD9yz/view?usp=drivesdk | T21: =HYPERLINK("https://drive.google.com/file/d/1EGzdBFstUsXDWTMpSUXHrpW133xlD9yz/view?usp=drivesdk","33 - X1 - Jasmine Zahira Ramadhani - P") -> 33 - X1 - Jasmine Zahira Ramadhani - P | U21: Document successfully created; Document successfully merged; PDF created; Manually run by skycircle.id@gmail.com; Timestamp: Nov 7 2025 2:53 AM | W21: =COUNTIFS('Form Presensi SCC'!$B:$B, IF($C21<>0, TEXT($C21, "0000000000"), $D21), 'Form Presensi SCC'!$C:$C, "Hadir") -> 2 | X21: =MAXIFS($W:$W, $H:$H, $H21) -> 0 | Y21: =(W21/X21)*100% -> #DIV/0!
A22: 21 | B22: 21 | C22: 0109256207 / 252610244 | D22: Jesslyn Quinn Gabrielle Sitorus - P | E22: P | F22: 33 | G22: X1 | J22: X1 | P22: ="https://docs.google.com/forms/d/e/1FAIpQLSeZ-R1GrWlAPkfaThGqxeTj0QTtrARw4rroxIIepf2kipn1nw/formResponse?usp=pp_url&entry.1313582257="&C22&"&entry.1578404635=Hadir" -> https://docs.google.com/forms/d/e/1FAIpQLSeZ-R1GrWlAPkfaThGqxeTj0QTtrARw4rroxIIepf2kipn1nw/formResponse?usp=pp_url&entry.1313582257=0109256207 / 252610244&entry.1578404635=Hadir | Q22: https://quickchart.io/qr?size=250&text=https%3A%2F%2Fdocs.google.com%2Fforms%2Fd%2Fe%2F1FAIpQLSeZ-R1GrWlAPkfaThGqxeTj0QTtrARw4rroxIIepf2kipn1nw%2FformResponse%3Fusp%3Dpp_url%26entry.1313582257%3D0109256207%20%2F%20252610244%26entry.1578404635%3DHadir | R22: 12uQAsBzgjDVCNB2aXCt2Qqlq8_hb85oB | S22: https://drive.google.com/file/d/12uQAsBzgjDVCNB2aXCt2Qqlq8_hb85oB/view?usp=drivesdk | T22: =HYPERLINK("https://drive.google.com/file/d/12uQAsBzgjDVCNB2aXCt2Qqlq8_hb85oB/view?usp=drivesdk","33 - X1 - Jesslyn Quinn Gabrielle Sitorus - P") -> 33 - X1 - Jesslyn Quinn Gabrielle Sitorus - P | U22: Document successfully created; Document successfully merged; PDF created; Manually run by skycircle.id@gmail.com; Timestamp: Nov 7 2025 2:53 AM | W22: =COUNTIFS('Form Presensi SCC'!$B:$B, IF($C22<>0, TEXT($C22, "0000000000"), $D22), 'Form Presensi SCC'!$C:$C, "Hadir") -> 0 | X22: =MAXIFS($W:$W, $H:$H, $H22) -> 0 | Y22: =(W22/X22)*100% -> #DIV/0!
A23: 22 | B23: 22 | C23: 0103648473 / 252610246 | D23: Jihan Al Hasya - P | E23: P | F23: 33 | G23: X1 | J23: X1 | P23: ="https://docs.google.com/forms/d/e/1FAIpQLSeZ-R1GrWlAPkfaThGqxeTj0QTtrARw4rroxIIepf2kipn1nw/formResponse?usp=pp_url&entry.1313582257="&C23&"&entry.1578404635=Hadir" -> https://docs.google.com/forms/d/e/1FAIpQLSeZ-R1GrWlAPkfaThGqxeTj0QTtrARw4rroxIIepf2kipn1nw/formResponse?usp=pp_url&entry.1313582257=0103648473 / 252610246&entry.1578404635=Hadir | Q23: https://quickchart.io/qr?size=250&text=https%3A%2F%2Fdocs.google.com%2Fforms%2Fd%2Fe%2F1FAIpQLSeZ-R1GrWlAPkfaThGqxeTj0QTtrARw4rroxIIepf2kipn1nw%2FformResponse%3Fusp%3Dpp_url%26entry.1313582257%3D0103648473%20%2F%20252610246%26entry.1578404635%3DHadir | R23: 1HOHvM3vFSGTw7CrqlBE9JjKk3PveT9N4 | S23: https://drive.google.com/file/d/1HOHvM3vFSGTw7CrqlBE9JjKk3PveT9N4/view?usp=drivesdk | T23: =HYPERLINK("https://drive.google.com/file/d/1HOHvM3vFSGTw7CrqlBE9JjKk3PveT9N4/view?usp=drivesdk","33 - X1 - Jihan Al Hasya - P") -> 33 - X1 - Jihan Al Hasya - P | U23: Document successfully created; Document successfully merged; PDF created; Manually run by skycircle.id@gmail.com; Timestamp: Nov 7 2025 2:53 AM | W23: =COUNTIFS('Form Presensi SCC'!$B:$B, IF($C23<>0, TEXT($C23, "0000000000"), $D23), 'Form Presensi SCC'!$C:$C, "Hadir") -> 0 | X23: =MAXIFS($W:$W, $H:$H, $H23) -> 0 | Y23: =(W23/X23)*100% -> #DIV/0!
A24: 23 | B24: 23 | C24: 0108537666 / 252610250 | D24: Johanes Satria Yudha - L | E24: L | F24: 33 | G24: X1 | J24: X1 | P24: ="https://docs.google.com/forms/d/e/1FAIpQLSeZ-R1GrWlAPkfaThGqxeTj0QTtrARw4rroxIIepf2kipn1nw/formResponse?usp=pp_url&entry.1313582257="&C24&"&entry.1578404635=Hadir" -> https://docs.google.com/forms/d/e/1FAIpQLSeZ-R1GrWlAPkfaThGqxeTj0QTtrARw4rroxIIepf2kipn1nw/formResponse?usp=pp_url&entry.1313582257=0108537666 / 252610250&entry.1578404635=Hadir | Q24: https://quickchart.io/qr?size=250&text=https%3A%2F%2Fdocs.google.com%2Fforms%2Fd%2Fe%2F1FAIpQLSeZ-R1GrWlAPkfaThGqxeTj0QTtrARw4rroxIIepf2kipn1nw%2FformResponse%3Fusp%3Dpp_url%26entry.1313582257%3D0108537666%20%2F%20252610250%26entry.1578404635%3DHadir | R24: 12UktbM36EnKr45A3BRaTHCnYcQKipFoh | S24: https://drive.google.com/file/d/12UktbM36EnKr45A3BRaTHCnYcQKipFoh/view?usp=drivesdk | T24: =HYPERLINK("https://drive.google.com/file/d/12UktbM36EnKr45A3BRaTHCnYcQKipFoh/view?usp=drivesdk","33 - X1 - Johanes Satria Yudha - L") -> 33 - X1 - Johanes Satria Yudha - L | U24: Document successfully created; Document successfully merged; PDF created; Manually run by skycircle.id@gmail.com; Timestamp: Nov 7 2025 2:54 AM | W24: =COUNTIFS('Form Presensi SCC'!$B:$B, IF($C24<>0, TEXT($C24, "0000000000"), $D24), 'Form Presensi SCC'!$C:$C, "Hadir") -> 0 | X24: =MAXIFS($W:$W, $H:$H, $H24) -> 0 | Y24: =(W24/X24)*100% -> #DIV/0!
A25: 24 | B25: 24 | C25: 0098409943 / 252610304 | D25: Kariswan Wahyudi - L | E25: L | F25: 33 | G25: X1 | J25: X1 | P25: ="https://docs.google.com/forms/d/e/1FAIpQLSeZ-R1GrWlAPkfaThGqxeTj0QTtrARw4rroxIIepf2kipn1nw/formResponse?usp=pp_url&entry.1313582257="&C25&"&entry.1578404635=Hadir" -> https://docs.google.com/forms/d/e/1FAIpQLSeZ-R1GrWlAPkfaThGqxeTj0QTtrARw4rroxIIepf2kipn1nw/formResponse?usp=pp_url&entry.1313582257=0098409943 / 252610304&entry.1578404635=Hadir | Q25: https://quickchart.io/qr?size=250&text=https%3A%2F%2Fdocs.google.com%2Fforms%2Fd%2Fe%2F1FAIpQLSeZ-R1GrWlAPkfaThGqxeTj0QTtrARw4rroxIIepf2kipn1nw%2FformResponse%3Fusp%3Dpp_url%26entry.1313582257%3D0098409943%20%2F%20252610304%26entry.1578404635%3DHadir | R25: 136MyB6rX3s1kqMNIIeqtTu6JwDGBkWlO | S25: https://drive.google.com/file/d/136MyB6rX3s1kqMNIIeqtTu6JwDGBkWlO/view?usp=drivesdk | T25: =HYPERLINK("https://drive.google.com/file/d/136MyB6rX3s1kqMNIIeqtTu6JwDGBkWlO/view?usp=drivesdk","33 - X1 - Kariswan Wahyudi - L") -> 33 - X1 - Kariswan Wahyudi - L | U25: Document successfully created; Document successfully merged; PDF created; Manually run by skycircle.id@gmail.com; Timestamp: Nov 7 2025 2:54 AM | W25: =COUNTIFS('Form Presensi SCC'!$B:$B, IF($C25<>0, TEXT($C25, "0000000000"), $D25), 'Form Presensi SCC'!$C:$C, "Hadir") -> 0 | X25: =MAXIFS($W:$W, $H:$H, $H25) -> 0 | Y25: =(W25/X25)*100% -> #DIV/0!
A26: 25 | B26: 25 | C26: 0092985486 / 252610311 | D26: Maria Rica Stefany Demu - P | E26: P | F26: 33 | G26: X1 | J26: X1 | P26: ="https://docs.google.com/forms/d/e/1FAIpQLSeZ-R1GrWlAPkfaThGqxeTj0QTtrARw4rroxIIepf2kipn1nw/formResponse?usp=pp_url&entry.1313582257="&C26&"&entry.1578404635=Hadir" -> https://docs.google.com/forms/d/e/1FAIpQLSeZ-R1GrWlAPkfaThGqxeTj0QTtrARw4rroxIIepf2kipn1nw/formResponse?usp=pp_url&entry.1313582257=0092985486 / 252610311&entry.1578404635=Hadir | Q26: https://quickchart.io/qr?size=250&text=https%3A%2F%2Fdocs.google.com%2Fforms%2Fd%2Fe%2F1FAIpQLSeZ-R1GrWlAPkfaThGqxeTj0QTtrARw4rroxIIepf2kipn1nw%2FformResponse%3Fusp%3Dpp_url%26entry.1313582257%3D0092985486%20%2F%20252610311%26entry.1578404635%3DHadir | R26: 1SGFJCN2vvOney4NApARqhB73iCOgk7PP | S26: https://drive.google.com/file/d/1SGFJCN2vvOney4NApARqhB73iCOgk7PP/view?usp=drivesdk | T26: =HYPERLINK("https://drive.google.com/file/d/1SGFJCN2vvOney4NApARqhB73iCOgk7PP/view?usp=drivesdk","33 - X1 - Maria Rica Stefany Demu - P") -> 33 - X1 - Maria Rica Stefany Demu - P | U26: Document successfully created; Document successfully merged; PDF created; Manually run by skycircle.id@gmail.com; Timestamp: Nov 7 2025 2:54 AM | W26: =COUNTIFS('Form Presensi SCC'!$B:$B, IF($C26<>0, TEXT($C26, "0000000000"), $D26), 'Form Presensi SCC'!$C:$C, "Hadir") -> 0 | X26: =MAXIFS($W:$W, $H:$H, $H26) -> 0 | Y26: =(W26/X26)*100% -> #DIV/0!
A27: 26 | B27: 26 | C27: 0094677765 / 252610313 | D27: Melani Putri Triana - P | E27: P | F27: 33 | G27: X1 | J27: X1 | P27: ="https://docs.google.com/forms/d/e/1FAIpQLSeZ-R1GrWlAPkfaThGqxeTj0QTtrARw4rroxIIepf2kipn1nw/formResponse?usp=pp_url&entry.1313582257="&C27&"&entry.1578404635=Hadir" -> https://docs.google.com/forms/d/e/1FAIpQLSeZ-R1GrWlAPkfaThGqxeTj0QTtrARw4rroxIIepf2kipn1nw/formResponse?usp=pp_url&entry.1313582257=0094677765 / 252610313&entry.1578404635=Hadir | Q27: https://quickchart.io/qr?size=250&text=https%3A%2F%2Fdocs.google.com%2Fforms%2Fd%2Fe%2F1FAIpQLSeZ-R1GrWlAPkfaThGqxeTj0QTtrARw4rroxIIepf2kipn1nw%2FformResponse%3Fusp%3Dpp_url%26entry.1313582257%3D0094677765%20%2F%20252610313%26entry.1578404635%3DHadir | R27: 1nehMZH1FhrVr5ttGwQVfgvqeJrIzLhyT | S27: https://drive.google.com/file/d/1nehMZH1FhrVr5ttGwQVfgvqeJrIzLhyT/view?usp=drivesdk | T27: =HYPERLINK("https://drive.google.com/file/d/1nehMZH1FhrVr5ttGwQVfgvqeJrIzLhyT/view?usp=drivesdk","33 - X1 - Melani Putri Triana - P") -> 33 - X1 - Melani Putri Triana - P | U27: Document successfully created; Document successfully merged; PDF created; Manually run by skycircle.id@gmail.com; Timestamp: Nov 7 2025 2:54 AM | W27: =COUNTIFS('Form Presensi SCC'!$B:$B, IF($C27<>0, TEXT($C27, "0000000000"), $D27), 'Form Presensi SCC'!$C:$C, "Hadir") -> 1 | X27: =MAXIFS($W:$W, $H:$H, $H27) -> 0 | Y27: =(W27/X27)*100% -> #DIV/0!
A28: 27 | B28: 27 | C28: 0107959828 / 252610316 | D28: Michael Mazmur Hatorangan Hutabarat - L | E28: L | F28: 33 | G28: X1 | J28: X1 | P28: ="https://docs.google.com/forms/d/e/1FAIpQLSeZ-R1GrWlAPkfaThGqxeTj0QTtrARw4rroxIIepf2kipn1nw/formResponse?usp=pp_url&entry.1313582257="&C28&"&entry.1578404635=Hadir" -> https://docs.google.com/forms/d/e/1FAIpQLSeZ-R1GrWlAPkfaThGqxeTj0QTtrARw4rroxIIepf2kipn1nw/formResponse?usp=pp_url&entry.1313582257=0107959828 / 252610316&entry.1578404635=Hadir | Q28: https://quickchart.io/qr?size=250&text=https%3A%2F%2Fdocs.google.com%2Fforms%2Fd%2Fe%2F1FAIpQLSeZ-R1GrWlAPkfaThGqxeTj0QTtrARw4rroxIIepf2kipn1nw%2FformResponse%3Fusp%3Dpp_url%26entry.1313582257%3D0107959828%20%2F%20252610316%26entry.1578404635%3DHadir | R28: 1AxwkbKLziu4iXcBBFIxplfneQH4t6uJO | S28: https://drive.google.com/file/d/1AxwkbKLziu4iXcBBFIxplfneQH4t6uJO/view?usp=drivesdk | T28: =HYPERLINK("https://drive.google.com/file/d/1AxwkbKLziu4iXcBBFIxplfneQH4t6uJO/view?usp=drivesdk","33 - X1 - Michael Mazmur Hatorangan Hutabarat - L") -> 33 - X1 - Michael Mazmur Hatorangan Hutabarat - L | U28: Document successfully created; Document successfully merged; PDF created; Manually run by skycircle.id@gmail.com; Timestamp: Nov 7 2025 2:54 AM | W28: =COUNTIFS('Form Presensi SCC'!$B:$B, IF($C28<>0, TEXT($C28, "0000000000"), $D28), 'Form Presensi SCC'!$C:$C, "Hadir") -> 0 | X28: =MAXIFS($W:$W, $H:$H, $H28) -> 0 | Y28: =(W28/X28)*100% -> #DIV/0!
A29: 28 | B29: 28 | C29: 0092600602 / 252610330 | D29: Mochamad Nayaka Tuharea - L | E29: L | F29: 33 | G29: X1 | J29: X1 | P29: ="https://docs.google.com/forms/d/e/1FAIpQLSeZ-R1GrWlAPkfaThGqxeTj0QTtrARw4rroxIIepf2kipn1nw/formResponse?usp=pp_url&entry.1313582257="&C29&"&entry.1578404635=Hadir" -> https://docs.google.com/forms/d/e/1FAIpQLSeZ-R1GrWlAPkfaThGqxeTj0QTtrARw4rroxIIepf2kipn1nw/formResponse?usp=pp_url&entry.1313582257=0092600602 / 252610330&entry.1578404635=Hadir | Q29: https://quickchart.io/qr?size=250&text=https%3A%2F%2Fdocs.google.com%2Fforms%2Fd%2Fe%2F1FAIpQLSeZ-R1GrWlAPkfaThGqxeTj0QTtrARw4rroxIIepf2kipn1nw%2FformResponse%3Fusp%3Dpp_url%26entry.1313582257%3D0092600602%20%2F%20252610330%26entry.1578404635%3DHadir | R29: 1HdjxzTJ5BmtVS3ZKEvlKKC3LEql2q-BA | S29: https://drive.google.com/file/d/1HdjxzTJ5BmtVS3ZKEvlKKC3LEql2q-BA/view?usp=drivesdk | T29: =HYPERLINK("https://drive.google.com/file/d/1HdjxzTJ5BmtVS3ZKEvlKKC3LEql2q-BA/view?usp=drivesdk","33 - X1 - Mochamad Nayaka Tuharea - L") -> 33 - X1 - Mochamad Nayaka Tuharea - L | U29: Document successfully created; Document successfully merged; PDF created; Manually run by skycircle.id@gmail.com; Timestamp: Nov 7 2025 2:55 AM | W29: =COUNTIFS('Form Presensi SCC'!$B:$B, IF($C29<>0, TEXT($C29, "0000000000"), $D29), 'Form Presensi SCC'!$C:$C, "Hadir") -> 0 | X29: =MAXIFS($W:$W, $H:$H, $H29) -> 0 | Y29: =(W29/X29)*100% -> #DIV/0!
A30: 29 | B30: 29 | C30: 0108695912 / 252610334 | D30: Muhamad Septian Romadhon - L | E30: L | F30: 33 | G30: X1 | J30: X1 | P30: ="https://docs.google.com/forms/d/e/1FAIpQLSeZ-R1GrWlAPkfaThGqxeTj0QTtrARw4rroxIIepf2kipn1nw/formResponse?usp=pp_url&entry.1313582257="&C30&"&entry.1578404635=Hadir" -> https://docs.google.com/forms/d/e/1FAIpQLSeZ-R1GrWlAPkfaThGqxeTj0QTtrARw4rroxIIepf2kipn1nw/formResponse?usp=pp_url&entry.1313582257=0108695912 / 252610334&entry.1578404635=Hadir | Q30: https://quickchart.io/qr?size=250&text=https%3A%2F%2Fdocs.google.com%2Fforms%2Fd%2Fe%2F1FAIpQLSeZ-R1GrWlAPkfaThGqxeTj0QTtrARw4rroxIIepf2kipn1nw%2FformResponse%3Fusp%3Dpp_url%26entry.1313582257%3D0108695912%20%2F%20252610334%26entry.1578404635%3DHadir | R30: 1njzPNLi7sKr8WVYPxIbyQkQOSVUilGWD | S30: https://drive.google.com/file/d/1njzPNLi7sKr8WVYPxIbyQkQOSVUilGWD/view?usp=drivesdk | T30: =HYPERLINK("https://drive.google.com/file/d/1njzPNLi7sKr8WVYPxIbyQkQOSVUilGWD/view?usp=drivesdk","33 - X1 - Muhamad Septian Romadhon - L") -> 33 - X1 - Muhamad Septian Romadhon - L | U30: Document successfully created; Document successfully merged; PDF created; Manually run by skycircle.id@gmail.com; Timestamp: Nov 7 2025 2:55 AM | W30: =COUNTIFS('Form Presensi SCC'!$B:$B, IF($C30<>0, TEXT($C30, "0000000000"), $D30), 'Form Presensi SCC'!$C:$C, "Hadir") -> 0 | X30: =MAXIFS($W:$W, $H:$H, $H30) -> 0 | Y30: =(W30/X30)*100% -> #DIV/0!
A31: 30 | B31: 30 | C31: 0093126257 / 252610343 | D31: Muhammad Adrian Gianni Adam - L | E31: L | F31: 33 | G31: X1 | H31: 33 - XSUMEN BC | J31: X1 | P31: ="https://docs.google.com/forms/d/e/1FAIpQLSeZ-R1GrWlAPkfaThGqxeTj0QTtrARw4rroxIIepf2kipn1nw/formResponse?usp=pp_url&entry.1313582257="&C31&"&entry.1578404635=Hadir" -> https://docs.google.com/forms/d/e/1FAIpQLSeZ-R1GrWlAPkfaThGqxeTj0QTtrARw4rroxIIepf2kipn1nw/formResponse?usp=pp_url&entry.1313582257=0093126257 / 252610343&entry.1578404635=Hadir | Q31: https://quickchart.io/qr?size=250&text=https%3A%2F%2Fdocs.google.com%2Fforms%2Fd%2Fe%2F1FAIpQLSeZ-R1GrWlAPkfaThGqxeTj0QTtrARw4rroxIIepf2kipn1nw%2FformResponse%3Fusp%3Dpp_url%26entry.1313582257%3D0093126257%20%2F%20252610343%26entry.1578404635%3DHadir | R31: 1X8wfYY0OH5CW_UBHbmpxRFg3_EjS9P9F | S31: https://drive.google.com/file/d/1X8wfYY0OH5CW_UBHbmpxRFg3_EjS9P9F/view?usp=drivesdk | T31: =HYPERLINK("https://drive.google.com/file/d/1X8wfYY0OH5CW_UBHbmpxRFg3_EjS9P9F/view?usp=drivesdk","33 - X1 - Muhammad Adrian Gianni Adam - L") -> 33 - X1 - Muhammad Adrian Gianni Adam - L | U31: Document successfully created; Document successfully merged; PDF created; Manually run by skycircle.id@gmail.com; Timestamp: Nov 7 2025 2:55 AM | W31: =COUNTIFS('Form Presensi SCC'!$B:$B, IF($C31<>0, TEXT($C31, "0000000000"), $D31), 'Form Presensi SCC'!$C:$C, "Hadir") -> 0 | X31: =MAXIFS($W:$W, $H:$H, $H31) -> 3 | Y31: =(W31/X31)*100% -> 0
A32: 31 | B32: 31 | C32: 3104497802 / 252610351 | D32: Muhammad Chaerudin Ramdhani - L | E32: L | F32: 33 | G32: X1 | J32: X1 | P32: ="https://docs.google.com/forms/d/e/1FAIpQLSeZ-R1GrWlAPkfaThGqxeTj0QTtrARw4rroxIIepf2kipn1nw/formResponse?usp=pp_url&entry.1313582257="&C32&"&entry.1578404635=Hadir" -> https://docs.google.com/forms/d/e/1FAIpQLSeZ-R1GrWlAPkfaThGqxeTj0QTtrARw4rroxIIepf2kipn1nw/formResponse?usp=pp_url&entry.1313582257=3104497802 / 252610351&entry.1578404635=Hadir | Q32: https://quickchart.io/qr?size=250&text=https%3A%2F%2Fdocs.google.com%2Fforms%2Fd%2Fe%2F1FAIpQLSeZ-R1GrWlAPkfaThGqxeTj0QTtrARw4rroxIIepf2kipn1nw%2FformResponse%3Fusp%3Dpp_url%26entry.1313582257%3D3104497802%20%2F%20252610351%26entry.1578404635%3DHadir | R32: 1FK6nuT5kuh1PkAwodKSoBvRM2HMA8KS7 | S32: https://drive.google.com/file/d/1FK6nuT5kuh1PkAwodKSoBvRM2HMA8KS7/view?usp=drivesdk | T32: =HYPERLINK("https://drive.google.com/file/d/1FK6nuT5kuh1PkAwodKSoBvRM2HMA8KS7/view?usp=drivesdk","33 - X1 - Muhammad Chaerudin Ramdhani - L") -> 33 - X1 - Muhammad Chaerudin Ramdhani - L | U32: Document successfully created; Document successfully merged; PDF created; Manually run by skycircle.id@gmail.com; Timestamp: Nov 7 2025 2:55 AM | W32: =COUNTIFS('Form Presensi SCC'!$B:$B, IF($C32<>0, TEXT($C32, "0000000000"), $D32), 'Form Presensi SCC'!$C:$C, "Hadir") -> 0 | X32: =MAXIFS($W:$W, $H:$H, $H32) -> 0 | Y32: =(W32/X32)*100% -> #DIV/0!
A33: 32 | B33: 32 | C33: 0108107461 / 252610369 | D33: Muhammad Fathan Assidiq - L | E33: L | F33: 33 | G33: X1 | J33: X1 | P33: ="https://docs.google.com/forms/d/e/1FAIpQLSeZ-R1GrWlAPkfaThGqxeTj0QTtrARw4rroxIIepf2kipn1nw/formResponse?usp=pp_url&entry.1313582257="&C33&"&entry.1578404635=Hadir" -> https://docs.google.com/forms/d/e/1FAIpQLSeZ-R1GrWlAPkfaThGqxeTj0QTtrARw4rroxIIepf2kipn1nw/formResponse?usp=pp_url&entry.1313582257=0108107461 / 252610369&entry.1578404635=Hadir | Q33: https://quickchart.io/qr?size=250&text=https%3A%2F%2Fdocs.google.com%2Fforms%2Fd%2Fe%2F1FAIpQLSeZ-R1GrWlAPkfaThGqxeTj0QTtrARw4rroxIIepf2kipn1nw%2FformResponse%3Fusp%3Dpp_url%26entry.1313582257%3D0108107461%20%2F%20252610369%26entry.1578404635%3DHadir | R33: 1fHQJCzZK5CIHCmoVs_TFJCU_qKWVm8gt | S33: https://drive.google.com/file/d/1fHQJCzZK5CIHCmoVs_TFJCU_qKWVm8gt/view?usp=drivesdk | T33: =HYPERLINK("https://drive.google.com/file/d/1fHQJCzZK5CIHCmoVs_TFJCU_qKWVm8gt/view?usp=drivesdk","33 - X1 - Muhammad Fathan Assidiq - L") -> 33 - X1 - Muhammad Fathan Assidiq - L | U33: Document successfully created; Document successfully merged; PDF created; Manually run by skycircle.id@gmail.com; Timestamp: Nov 7 2025 2:55 AM | W33: =COUNTIFS('Form Presensi SCC'!$B:$B, IF($C33<>0, TEXT($C33, "0000000000"), $D33), 'Form Presensi SCC'!$C:$C, "Hadir") -> 0 | X33: =MAXIFS($W:$W, $H:$H, $H33) -> 0
A34: 33 | B34: 33 | C34: 0092807405 / 252610371 | D34: Muhammad Rodzul Amrullah - L | E34: L | F34: 33 | G34: X1 | J34: X1 | P34: ="https://docs.google.com/forms/d/e/1FAIpQLSeZ-R1GrWlAPkfaThGqxeTj0QTtrARw4rroxIIepf2kipn1nw/formResponse?usp=pp_url&entry.1313582257="&C34&"&entry.1578404635=Hadir" -> https://docs.google.com/forms/d/e/1FAIpQLSeZ-R1GrWlAPkfaThGqxeTj0QTtrARw4rroxIIepf2kipn1nw/formResponse?usp=pp_url&entry.1313582257=0092807405 / 252610371&entry.1578404635=Hadir | Q34: https://quickchart.io/qr?size=250&text=https%3A%2F%2Fdocs.google.com%2Fforms%2Fd%2Fe%2F1FAIpQLSeZ-R1GrWlAPkfaThGqxeTj0QTtrARw4rroxIIepf2kipn1nw%2FformResponse%3Fusp%3Dpp_url%26entry.1313582257%3D0092807405%20%2F%20252610371%26entry.1578404635%3DHadir | R34: 1B4JozJy9yq_amhwZfnrDmsiUaUaw9pS2 | S34: https://drive.google.com/file/d/1B4JozJy9yq_amhwZfnrDmsiUaUaw9pS2/view?usp=drivesdk | T34: =HYPERLINK("https://drive.google.com/file/d/1B4JozJy9yq_amhwZfnrDmsiUaUaw9pS2/view?usp=drivesdk","33 - X1 - Muhammad Rodzul Amrullah - L") -> 33 - X1 - Muhammad Rodzul Amrullah - L | U34: Document successfully created; Document successfully merged; PDF created; Manually run by skycircle.id@gmail.com; Timestamp: Nov 7 2025 2:56 AM | W34: =COUNTIFS('Form Presensi SCC'!$B:$B, IF($C34<>0, TEXT($C34, "0000000000"), $D34), 'Form Presensi SCC'!$C:$C, "Hadir") -> 0 | X34: =MAXIFS($W:$W, $H:$H, $H34) -> 0
A35: 34 | B35: 34 | C35: 0102300207 / 252610390 | D35: Nadya Salwa Altiara - P | E35: P | F35: 33 | G35: X1 | J35: X1 | P35: ="https://docs.google.com/forms/d/e/1FAIpQLSeZ-R1GrWlAPkfaThGqxeTj0QTtrARw4rroxIIepf2kipn1nw/formResponse?usp=pp_url&entry.1313582257="&C35&"&entry.1578404635=Hadir" -> https://docs.google.com/forms/d/e/1FAIpQLSeZ-R1GrWlAPkfaThGqxeTj0QTtrARw4rroxIIepf2kipn1nw/formResponse?usp=pp_url&entry.1313582257=0102300207 / 252610390&entry.1578404635=Hadir | Q35: https://quickchart.io/qr?size=250&text=https%3A%2F%2Fdocs.google.com%2Fforms%2Fd%2Fe%2F1FAIpQLSeZ-R1GrWlAPkfaThGqxeTj0QTtrARw4rroxIIepf2kipn1nw%2FformResponse%3Fusp%3Dpp_url%26entry.1313582257%3D0102300207%20%2F%20252610390%26entry.1578404635%3DHadir | R35: 1Fa_RZpZUSOiZLYYLI4c1YBUgjAxlPtVL | S35: https://drive.google.com/file/d/1Fa_RZpZUSOiZLYYLI4c1YBUgjAxlPtVL/view?usp=drivesdk | T35: =HYPERLINK("https://drive.google.com/file/d/1Fa_RZpZUSOiZLYYLI4c1YBUgjAxlPtVL/view?usp=drivesdk","33 - X1 - Nadya Salwa Altiara - P") -> 33 - X1 - Nadya Salwa Altiara - P | U35: Document successfully created; Document successfully merged; PDF created; Manually run by skycircle.id@gmail.com; Timestamp: Nov 7 2025 2:56 AM | W35: =COUNTIFS('Form Presensi SCC'!$B:$B, IF($C35<>0, TEXT($C35, "0000000000"), $D35), 'Form Presensi SCC'!$C:$C, "Hadir") -> 0
A36: 35 | B36: 35 | C36: 0097892166 / 252610393 | D36: Nailah Khoirunisa Arsanti - P | E36: P | F36: 33 | G36: X1 | J36: X1 | P36: ="https://docs.google.com/forms/d/e/1FAIpQLSeZ-R1GrWlAPkfaThGqxeTj0QTtrARw4rroxIIepf2kipn1nw/formResponse?usp=pp_url&entry.1313582257="&C36&"&entry.1578404635=Hadir" -> https://docs.google.com/forms/d/e/1FAIpQLSeZ-R1GrWlAPkfaThGqxeTj0QTtrARw4rroxIIepf2kipn1nw/formResponse?usp=pp_url&entry.1313582257=0097892166 / 252610393&entry.1578404635=Hadir | Q36: https://quickchart.io/qr?size=250&text=https%3A%2F%2Fdocs.google.com%2Fforms%2Fd%2Fe%2F1FAIpQLSeZ-R1GrWlAPkfaThGqxeTj0QTtrARw4rroxIIepf2kipn1nw%2FformResponse%3Fusp%3Dpp_url%26entry.1313582257%3D0097892166%20%2F%20252610393%26entry.1578404635%3DHadir | R36: 1BAAuTlBsqQ-JFYTZzc_oBG3dSG-nl41G | S36: https://drive.google.com/file/d/1BAAuTlBsqQ-JFYTZzc_oBG3dSG-nl41G/view?usp=drivesdk | T36: =HYPERLINK("https://drive.google.com/file/d/1BAAuTlBsqQ-JFYTZzc_oBG3dSG-nl41G/view?usp=drivesdk","33 - X1 - Nailah Khoirunisa Arsanti - P") -> 33 - X1 - Nailah Khoirunisa Arsanti - P | U36: Document successfully created; Document successfully merged; PDF created; Manually run by skycircle.id@gmail.com; Timestamp: Nov 7 2025 2:56 AM | W36: =COUNTIFS('Form Presensi SCC'!$B:$B, IF($C36<>0, TEXT($C36, "0000000000"), $D36), 'Form Presensi SCC'!$C:$C, "Hadir") -> 0
A37: 36 | B37: 36 | C37: 0097858274 / 252610423 | D37: Novyola Safitri - P | E37: P | F37: 33 | G37: X1 | J37: X1 | P37: ="https://docs.google.com/forms/d/e/1FAIpQLSeZ-R1GrWlAPkfaThGqxeTj0QTtrARw4rroxIIepf2kipn1nw/formResponse?usp=pp_url&entry.1313582257="&C37&"&entry.1578404635=Hadir" -> https://docs.google.com/forms/d/e/1FAIpQLSeZ-R1GrWlAPkfaThGqxeTj0QTtrARw4rroxIIepf2kipn1nw/formResponse?usp=pp_url&entry.1313582257=0097858274 / 252610423&entry.1578404635=Hadir | Q37: https://quickchart.io/qr?size=250&text=https%3A%2F%2Fdocs.google.com%2Fforms%2Fd%2Fe%2F1FAIpQLSeZ-R1GrWlAPkfaThGqxeTj0QTtrARw4rroxIIepf2kipn1nw%2FformResponse%3Fusp%3Dpp_url%26entry.1313582257%3D0097858274%20%2F%20252610423%26entry.1578404635%3DHadir | R37: 122ujRpdl36x6kaMiqL-5rkF40v2zMA3b | S37: https://drive.google.com/file/d/122ujRpdl36x6kaMiqL-5rkF40v2zMA3b/view?usp=drivesdk | T37: =HYPERLINK("https://drive.google.com/file/d/122ujRpdl36x6kaMiqL-5rkF40v2zMA3b/view?usp=drivesdk","33 - X1 - Novyola Safitri - P") -> 33 - X1 - Novyola Safitri - P | U37: Document successfully created; Document successfully merged; PDF created; Manually run by skycircle.id@gmail.com; Timestamp: Nov 7 2025 2:56 AM | W37: =COUNTIFS('Form Presensi SCC'!$B:$B, IF($C37<>0, TEXT($C37, "0000000000"), $D37), 'Form Presensi SCC'!$C:$C, "Hadir") -> 0
A38: 37 | B38: 37 | C38: 0093105045 / 252610424 | D38: Nur Alifah Silvia - P | E38: P | F38: 33 | G38: X1 | J38: X1 | P38: ="https://docs.google.com/forms/d/e/1FAIpQLSeZ-R1GrWlAPkfaThGqxeTj0QTtrARw4rroxIIepf2kipn1nw/formResponse?usp=pp_url&entry.1313582257="&C38&"&entry.1578404635=Hadir" -> https://docs.google.com/forms/d/e/1FAIpQLSeZ-R1GrWlAPkfaThGqxeTj0QTtrARw4rroxIIepf2kipn1nw/formResponse?usp=pp_url&entry.1313582257=0093105045 / 252610424&entry.1578404635=Hadir | Q38: https://quickchart.io/qr?size=250&text=https%3A%2F%2Fdocs.google.com%2Fforms%2Fd%2Fe%2F1FAIpQLSeZ-R1GrWlAPkfaThGqxeTj0QTtrARw4rroxIIepf2kipn1nw%2FformResponse%3Fusp%3Dpp_url%26entry.1313582257%3D0093105045%20%2F%20252610424%26entry.1578404635%3DHadir | R38: 1NkYk1mzO36BrpmFMNmWG0E23Kt180dcP | S38: https://drive.google.com/file/d/1NkYk1mzO36BrpmFMNmWG0E23Kt180dcP/view?usp=drivesdk | T38: =HYPERLINK("https://drive.google.com/file/d/1NkYk1mzO36BrpmFMNmWG0E23Kt180dcP/view?usp=drivesdk","33 - X1 - Nur Alifah Silvia - P") -> 33 - X1 - Nur Alifah Silvia - P | U38: Document successfully created; Document successfully merged; PDF created; Manually run by skycircle.id@gmail.com; Timestamp: Nov 7 2025 2:56 AM | W38: =COUNTIFS('Form Presensi SCC'!$B:$B, IF($C38<>0, TEXT($C38, "0000000000"), $D38), 'Form Presensi SCC'!$C:$C, "Hadir") -> 2
A39: 38 | B39: 38 | C39: 0095438030 / 252610436 | D39: Pungki Yustisia Pertiwi - L | E39: L | F39: 33 | G39: X1 | J39: X1 | P39: ="https://docs.google.com/forms/d/e/1FAIpQLSeZ-R1GrWlAPkfaThGqxeTj0QTtrARw4rroxIIepf2kipn1nw/formResponse?usp=pp_url&entry.1313582257="&C39&"&entry.1578404635=Hadir" -> https://docs.google.com/forms/d/e/1FAIpQLSeZ-R1GrWlAPkfaThGqxeTj0QTtrARw4rroxIIepf2kipn1nw/formResponse?usp=pp_url&entry.1313582257=0095438030 / 252610436&entry.1578404635=Hadir | Q39: https://quickchart.io/qr?size=250&text=https%3A%2F%2Fdocs.google.com%2Fforms%2Fd%2Fe%2F1FAIpQLSeZ-R1GrWlAPkfaThGqxeTj0QTtrARw4rroxIIepf2kipn1nw%2FformResponse%3Fusp%3Dpp_url%26entry.1313582257%3D0095438030%20%2F%20252610436%26entry.1578404635%3DHadir | R39: 1n8G_y0n2UNS1r9qU99EPhaluwpebdXU2 | S39: https://drive.google.com/file/d/1n8G_y0n2UNS1r9qU99EPhaluwpebdXU2/view?usp=drivesdk | T39: =HYPERLINK("https://drive.google.com/file/d/1n8G_y0n2UNS1r9qU99EPhaluwpebdXU2/view?usp=drivesdk","33 - X1 - Pungki Yustisia Pertiwi - L") -> 33 - X1 - Pungki Yustisia Pertiwi - L | U39: Document successfully created; Document successfully merged; PDF created; Manually run by skycircle.id@gmail.com; Timestamp: Nov 7 2025 2:56 AM | W39: =COUNTIFS('Form Presensi SCC'!$B:$B, IF($C39<>0, TEXT($C39, "0000000000"), $D39), 'Form Presensi SCC'!$C:$C, "Hadir") -> 1
A40: 39 | B40: 39 | C40: 0107914534 / 252610452 | D40: Raden Gathan Azaki Soesilo - L | E40: L | F40: 33 | G40: X1 | J40: X1 | P40: ="https://docs.google.com/forms/d/e/1FAIpQLSeZ-R1GrWlAPkfaThGqxeTj0QTtrARw4rroxIIepf2kipn1nw/formResponse?usp=pp_url&entry.1313582257="&C40&"&entry.1578404635=Hadir" -> https://docs.google.com/forms/d/e/1FAIpQLSeZ-R1GrWlAPkfaThGqxeTj0QTtrARw4rroxIIepf2kipn1nw/formResponse?usp=pp_url&entry.1313582257=0107914534 / 252610452&entry.1578404635=Hadir | Q40: https://quickchart.io/qr?size=250&text=https%3A%2F%2Fdocs.google.com%2Fforms%2Fd%2Fe%2F1FAIpQLSeZ-R1GrWlAPkfaThGqxeTj0QTtrARw4rroxIIepf2kipn1nw%2FformResponse%3Fusp%3Dpp_url%26entry.1313582257%3D0107914534%20%2F%20252610452%26entry.1578404635%3DHadir | R40: 1vyybGg2I_y0EeSocpKMdZZvnZmLckHie | S40: https://drive.google.com/file/d/1vyybGg2I_y0EeSocpKMdZZvnZmLckHie/view?usp=drivesdk | T40: =HYPERLINK("https://drive.google.com/file/d/1vyybGg2I_y0EeSocpKMdZZvnZmLckHie/view?usp=drivesdk","33 - X1 - Raden Gathan Azaki Soesilo - L") -> 33 - X1 - Raden Gathan Azaki Soesilo - L | U40: Document successfully created; Document successfully merged; PDF created; Manually run by skycircle.id@gmail.com; Timestamp: Nov 7 2025 2:56 AM | W40: =COUNTIFS('Form Presensi SCC'!$B:$B, IF($C40<>0, TEXT($C40, "0000000000"), $D40), 'Form Presensi SCC'!$C:$C, "Hadir") -> 0
...

Sheet NVScriptsProperties
A1: autocratn | B1: autocratp
A2: updateTime | B2: "1.770120073809E12"
A3: dataSheetId | B3: "1.3051252E9"
A4: dataSheetName | B4: "Database Presensi SCC"
A5: v | B5: "5.1"

Sheet Database Presensi SCC_Lama
A1: Column 10 | B1: NO ABSEN | C1: NISN | D1: NIS | E1: NAMA | F1: L/P | G1: Angkatan | H1: Kelas TA | I1: Grup TA | J1: Mentor TA | K1: Kelas X | L1: Kelas XI | M1: Kelas XII | N1: Grup X | O1: Grup XI | P1: Grup XII | Q1: Link Presensi | R1: QR Code | S1: Merged Doc ID - Kartu QR Code | T1: Merged Doc URL - Kartu QR Code | U1: Link to merged Doc - Kartu QR Code | V1: Document Merge Status - Kartu QR Code
A2: 3 | B2: 1 | C2: 0 | D2: 252610008 | E2: Adhie Bramantyo Faqih | F2: L | G2: 33 | H2: =K2 -> X-1 | I2: =N2 -> 33 - BC X-1 | J2: =VLOOKUP(I2,'Database Grup SCC'!$B$2:$C1382,2,false) -> Rony | K2: X-1 | N2: 33 - BC X-1 | Q2: ="https://docs.google.com/forms/d/e/1FAIpQLSeZ-R1GrWlAPkfaThGqxeTj0QTtrARw4rroxIIepf2kipn1nw/formResponse?usp=pp_url&entry.1313582257="&C2&"&entry.1578404635=Hadir" -> https://docs.google.com/forms/d/e/1FAIpQLSeZ-R1GrWlAPkfaThGqxeTj0QTtrARw4rroxIIepf2kipn1nw/formResponse?usp=pp_url&entry.1313582257=0&entry.1578404635=Hadir | R2: {=IF(Q2:Q1382="","", "https://quickchart.io/qr?size=250&text=" & ENCODEURL(Q2:Q1382))} -> https://quickchart.io/qr?size=250&text=https%3A%2F%2Fdocs.google.com%2Fforms%2Fd%2Fe%2F1FAIpQLSeZ-R1GrWlAPkfaThGqxeTj0QTtrARw4rroxIIepf2kipn1nw%2FformResponse%3Fusp%3Dpp_url%26entry.1313582257%3D0%26entry.1578404635%3DHadir
