Workbook

Sheet Sheet7
B2: Mentor 2025-2026
B4: Angkatan 33 (Kelas X) | Q4: mentor
B5: Ikhwan | C5: Jumlah Menti | D5: Mentor | F5: Akhwat | G5: Jumlah Menti | H5: Mentor Grup 1 | I5: Jumlah Menti | J5: Mentor Grup 2 | Q5: sehat | R5: sakit | S5: tak tertolong | T5: Cuti
B6: X-1 | C6: 17 | D6: Rony | F6: X-1 | G6: 11 | H6: Syifa | I6: 11 | J6: Oshe (XI) | K6: Iga | Q6: Iga | R6: Iqlima | S6: Lisana | T6: Syifa Aulia
B7: X-2 | C7: 15 | D7: Joko | E7: belum ada ganti | F7: X-2 | G7: 12 | H7: Rania (XII) | I7: 11 | J7: Nadine (XI) | Q7: Hamzah | R7: Yunan | S7: Joko | T7: Najla
B8: X-3 | C8: 13 | D8: Angga | F8: X-3 | G8: 13 | H8: Hanin | I8: 13 | J8: Zhafira (XI) | Q8: Muhamad Khadafi | R8: Zalika Shafa Azizah | S8: Abim Ibrahim | T8: Hana
B9: X-4 | C9: 16 | D9: Rizky Putra | F9: X-4 | G9: 12 | H9: Najla | I9: 12 | J9: Faliqa (XI) | Q9: Kiaa | R9: Sakina
B10: X-5 | C10: 14 | D10: Topik & Adrian | F10: X-5 | G10: 12 | H10: Hana | I10: 12 | J10: Sabika (XI) | Q10: Hanin | R10: Devi
B11: X-6 | C11: 7 | D11: Arumbinang | F11: X-6 | G11: 12 | H11: Khairunnisa (XII) | I11: 11 | J11: Bumi (XI) | Q11: Nadira Adzra As Shofa | R11: Amel (XII)
B12: X-7 | C12: 16 | D12: Rizza Al-Farisi | F12: X-7 | G12: 14 | H12: Shafa | I12: 14 | J12: Desya (XI) | Q12: Muhammad Rizza Al-farisi | R12: Najmi
B13: X-8 | C13: 14 | D13: Teguh | F13: X-8 | G13: 14 | H13: Sakina | I13: 14 | J13: Arsyila (XI) | Q13: Arsyila | R13: Kia
B14: X-9 | C14: 17 | D14: Veril (XII) | F14: X-9 | G14: 13 | H14: Tiara (XII) | I14: 12 | J14: Almira (XI) | Q14: Muhammad Irghi | R14: Farisa
B15: X-10 | C15: 14 | D15: Irghi (XII) | F15: X-10 | G15: 12 | H15: Citra | I15: 11 | J15: Lexa (XI) | Q15: Lexa El Sohbia
B16: X-11 | C16: 17 | D16: Khadafi (XII) | F16: X-11 | G16: 12 | H16: Kusniawati | I16: 11 | J16: Annisa Alya (XII) | Q16: Taufiq
B17: X-12 | C17: 16 | D17: Almeer (XII) | F17: X-12 | G17: 12 | H17: Ninda (XII) | I17: 12 | J17: Fiona (XI) | Q17: Khairunnisa Nur Ibtihal
B18: Xsumen | C18: 18 | D18: Rekhsa | F18: Xsumen1 | G18: 13 | H18: Ayun | J18: - | Q18: Raihana Citra
F19: Xsumen2 | G19: 14 | H19: Iqlima | J19: -
Q20: Nur Najmi Nuha
B21: Angkatan 32 (Kelas XI) | Q21: Pebryan
B22: Ikhwan | C22: Jumlah Menti | D22: Mentor | F22: Akhwat | G22: Jumlah Menti | H22: Mentor | Q22: Syafiq
B23: X-1 | C23: 6-7/14 | D23: Arya | F23: X-1 | G23: 14/19 | H23: Nia | Q23: Aryatama Wicaksana
B24: X-2 | C24: 45761 | D24: Rafli (XII) | F24: X-2 | G24: 15-16/21 | H24: Iga | I24: Nadira | Q24: Rizki Putra
B25: X-3 | C25: 8-10/12 | D25: Taufik | F25: X-3 | G25: 10-15/15 | H25: Devi | Q25: Mohammad Taufik
B26: X-4 | C26: 45816 | D26: Arya | F26: X-4 | G26: 45917 | H26: Nadira | Q26: rony
B27: X-5 | C27: 45883 | D27: Taufik | F27: X-5 | G27: 45846 | H27: Amel | Q27: Dimas Wahyu Ekawananto
B28: X-6 | C28: 45881 | D28: Febryan (XII) | F28: X-6 | G28: 13/20 | H28: Zalika
B29: X-7 | C29: 45850 | D29: Fadhlan (XII) | F29: X-7 | G29: 45856 | H29: Najmi (XII) | Q29: Ayun
B30: X-8 | C30: 45728 | D30: Rafli (XII) | F30: X-8 | G30: 12 | H30: Amel (XII) | Q30: Ulfiana
B31: X-9 | C31: Belum terdata | D31: Abim Ibrahim | F31: X-9 | G31: 45766 | H31: Athaya | Q31: Angga
B32: X-10 | C32: 45790 | D32: Dimas | F32: X-10 | G32: 5-11/21 | H32: Athaya | Q32: kusniawati
B33: X-11 | C33: 3-4/9 | D33: Dimas | F33: X-11 | G33: 45982 | H33: Kia (XII) | Q33: Shafa Ananda
B34: X-12 | C34: 45849 | D34: Syafiq | F34: X-12 | G34: 45885 | H34: Farisa (XII) | Q34: Amelia Nitami
Q35: Agus Budiyanto
Q36: Athaya Isnanuzul Fiany
B37: Angkatan 31 (Kelas XII) | Q37: Rania Adila
B38: Ikhwan | C38: Jml Mentee | D38: Mentor | E38: Pengganti | G38: Akhwat | H38: Jml Mentee | I38: Mentor | J38: Pengganti | L38: Supermentoring 32 | M38: Mentor | N38: Jml Mentee | Q38: Tiara Azizah Wibowo
B39: X-1 | D39: Rekhsa | E39: Master Class | G39: X-1 | I39: Lisana | J39: Master Class | L39: Ikhwan | M39: Randy | N39: 11 | Q39: Teguh
B40: X-2 | D40: Joko | G40: X-2 | I40: Hanin | L40: Akhwat-1 | M40: Ukhti | N40: 11 | Q40: Kak Ulfiana
B41: X-3 | D41: Rekhsa | G41: X-3 | I41: Nadia | L41: Akhwat-2 | M41: Eka | N41: 11
B42: X-4 | D42: Joko | G42: X-4 | I42: Lisana | Q42: Mia Yuliana
...

Sheet TImeline Sem 2
A1: TIMELINE SEMESTER 2 2025/2026
A2: Tanggal | B2: Kegiatan | C2: PIC
A3: 46053 | B3: Mentoring X dan XI | C3: Seluruh mentor
A4: 46060 | B4: Masterclass kelas 12: Bekal Kehidupan Perkuliahan | C4: Rizza Al-Farisi (Pemateri)
A5: 46067 | B5: Libur | C5: -
A6: 46081 | B6: Mentoring X dan XI: Amalan Ramadhan | C6: Seluruh mentor
A7: 46088 | B7: Bukber dengan masing-masing circle | C7: Seluruh mentor
A8: 46123 | B8: Mentoring X dan XI | C8: Seluruh mentor
A9: 46130 | B9: Mentoring X dan XI | C9: Seluruh mentor
A10: 46137 | B10: Mentoring X dan XI | C10: Seluruh mentor
A11: 9 Mei | B11: Mentoring X dan XI | C11: Seluruh mentor
A12: 23 Mei | B12: Mentoring X dan XI | C12: Seluruh mentor
A13: 46179
A14: 46193
A16: Kelas 12 | B16: sebelum ramadhan sudah selesai

Sheet Dahboard 20252026
B1: Mentor SMAVO 2025-2026 | P1: Mentee
B3: Angkatan 33 (Kelas X) | Q3: Total Siswa | R3: Boys | S3: Girls
B4: Ikhwan | C4: Jml Mentee | D4: Mentor | F4: Akhwat | G4: Jml Mentee | H4: Mentor Grup 1 | I4: Mentor Grup 2 | P4: Angkatan 31 | Q4: =COUNTA('Angkatan 33'!$B$3:$B$517) -> 515 | R4: =COUNTIF('Angkatan 33'!$F$3:$F$517,"L") -> 195 | S4: =COUNTIF('Angkatan 33'!$F$3:$F$517,"P") -> 320
B5: X-1 | C5: 17 | D5: Rony | F5: X-1 | G5: 22 | H5: Syifa | I5: Oshe (XI) | P5: Angkatan 32
B6: X-2 | C6: 15 | D6: Joko | F6: X-2 | G6: 23 | H6: Rania (XII) | I6: Nadine (XI) | P6: Angkatan 33
B7: X-3 | C7: 13 | D7: Angga | F7: X-3 | G7: 26 | H7: Hanin | I7: Zhafira (XI) | P7: Grant Total
B8: X-4 | C8: 16 | D8: Arumbinang | F8: X-4 | G8: 24 | H8: Najla | I8: Faliqa (XI)
B9: X-5 | C9: 14 | D9: Topik & Adrian | F9: X-5 | G9: 24 | H9: Hana | I9: Sabika (XI)
B10: X-6 | C10: 7 | D10: Rizki Putra | F10: X-6 | G10: 23 | H10: Khairunnisa (XII) | I10: Bumi (XI)
B11: X-7 | C11: 16 | D11: Rizza Al-Farisi | F11: X-7 | G11: 28 | H11: Shafa | I11: Desya (XI)
B12: X-8 | C12: 14 | D12: Teguh | F12: X-8 | G12: 28 | H12: Sakina | I12: Arsyila (XI)
B13: X-9 | C13: 16 | D13: Veril (XII) | F13: X-9 | G13: 25 | H13: Tiara (XII) | I13: Almira (XI)
B14: X-10 | C14: 14 | D14: Irghi (XII) | F14: X-10 | G14: 23 | H14: Citra (XII) | I14: Lexa (XI)
B15: X-11 | C15: 16 | D15: Khadafi (XII) | F15: X-11 | G15: 23 | H15: Kusniawati | I15: Annisa Alya (XII)
B16: X-12 | C16: 15 | D16: Almeer (XII) | F16: X-12 | G16: 24 | H16: Ninda (XII) | I16: Fiona (XI)
B17: Xsumen1 | C17: 10 | D17: Pak Muhammad | F17: Xsumen1 | G17: 13 | H17: Ayun | I17: -
B18: Xsumen2 | C18: 11 | D18: Rekhsa | F18: Xsumen2 | G18: 14 | H18: Iqlima | I18: -
B19: Jumlah | C19: =sum(C5:C18) -> 194 | D19: 14 | F19: Jumlah | G19: =sum(G6:G18) -> 298 | H19: 14 | I19: 12
B21: Angkatan 32 (Kelas XI)
B22: Ikhwan | C22: Jml Mentee | D22: Mentor | F22: Akhwat | G22: Jml Mentee | H22: Mentor | K22: Supermentoring 32 | L22: Mentor | M22: Jml Mentee
B23: X-1 | C23: 6-7/14 | D23: Arya | F23: X-1 | G23: 14/19 | H23: Nia | K23: Ikhwan | L23: Randy | M23: 11
B24: X-2 | C24: 45761 | D24: Rafli (XII) | F24: X-2 | G24: 15-16/21 | H24: Iga | K24: Akhwat-1 | L24: Ukhti | M24: 11
B25: X-3 | C25: 8-10/12 | D25: Taufik | F25: X-3 | G25: 10-15/15 | H25: Devi | K25: Akhwat-2 | L25: Eka | M25: 11
B26: X-4 | C26: 45816 | D26: Arya | F26: X-4 | G26: 45917 | H26: Nadira (XII)
B27: X-5 | C27: 45883 | D27: Ibrahim | F27: X-5 | G27: 45846 | H27: Amel | K27: Supermentoring 31 | L27: Mentor | M27: Jml Mentee
B28: X-6 | C28: 45881 | D28: Febryan (XII) | F28: X-6 | G28: 13/20 | H28: Zalika | K28: Ikhwan-1 | L28: Hamzah | M28: 9
B29: X-7 | C29: 45850 | D29: Fadhlan (XII) | F29: X-7 | G29: 45856 | H29: Najmi (XII) | K29: Akhwat-1 | L29: Fahriya | M29: 15
B30: X-8 | C30: 45728 | D30: Rafli (XII) | F30: X-8 | G30: 12 | H30: Amel (XII) | K30: Ikhwan-2 | L30: Budi | M30: 8
B31: X-9 | C31: Belum terdata | D31: Abim Ibrahim | F31: X-9 | G31: 45766 | H31: Athaya | K31: Akhwat-2 | L31: Ulfi | M31: 11
B32: X-10 | C32: 45790 | D32: Dimas | F32: X-10 | G32: 5-11/21 | H32: Athaya
B33: X-11 | C33: 3-4/9 | D33: Dimas | F33: X-11 | G33: 45982 | H33: Kia (XII)
B34: X-12 | C34: 45849 | D34: Syafiq | F34: X-12 | G34: 45885 | H34: Farisa (XII)

Sheet BOY Circle 33

Sheet GIRL Circle 33

Sheet Angkatan 33
A2: Column 10 | B2: NO | C2: NISN | D2: NIS | E2: NAMA | F2: L/P | G2: Kelas | H2: Wali Kelas | I2: Grup | J2: Mentor | K2: Column 11
A3: 3 | B3: 1 | C3: 0092626116 | D3: 252610008 | E3: Adhie Bramantyo Faqih | F3: L | G3: X-1 | H3: =VLOOKUP(G3,MetaData!$A$2:$C$13,3,false) -> Selly Amalia, S.Hum | I3: BC X-1 | J3: =VLOOKUP(I3,MetaData!$E$2:$G$40,3,false) -> Rony
A4: 4 | B4: 2 | C4: 3103201253 | D4: 252610048 | E4: Almira Dwi Safira | F4: P | G4: X-1 | H4: =VLOOKUP(G4,MetaData!$A$2:$C$13,3,false) -> Selly Amalia, S.Hum | I4: GC1 X-1 | J4: =VLOOKUP(I4,MetaData!$E$2:$G$40,3,false) -> Syifa
A5: 5 | B5: 3 | C5: 0102149444 | D5: 252610053 | E5: Alzena Juneeta Talisha Theo | F5: P | G5: X-1 | H5: =VLOOKUP(G5,MetaData!$A$2:$C$13,3,false) -> Selly Amalia, S.Hum | I5: GC1 X-1 | J5: =VLOOKUP(I5,MetaData!$E$2:$G$40,3,false) -> Syifa
A6: 6 | B6: 4 | C6: 0095992391 | D6: 252610082 | E6: Arya Aditya Gunawan | F6: L | G6: X-1 | H6: =VLOOKUP(G6,MetaData!$A$2:$C$13,3,false) -> Selly Amalia, S.Hum | I6: BC X-1 | J6: =VLOOKUP(I6,MetaData!$E$2:$G$40,3,false) -> Rony
A7: 7 | B7: 5 | C7: 0106142601 | D7: 252610083 | E7: Aryasatia Pradipta | F7: P | G7: X-1 | H7: =VLOOKUP(G7,MetaData!$A$2:$C$13,3,false) -> Selly Amalia, S.Hum | I7: GC1 X-1 | J7: =VLOOKUP(I7,MetaData!$E$2:$G$40,3,false) -> Syifa
A8: 8 | B8: 6 | C8: 0108104548 | D8: 252610087 | E8: Asyifa Diandra Bayu | F8: P | G8: X-1 | H8: =VLOOKUP(G8,MetaData!$A$2:$C$13,3,false) -> Selly Amalia, S.Hum | I8: GC1 X-1 | J8: =VLOOKUP(I8,MetaData!$E$2:$G$40,3,false) -> Syifa
A9: 9 | B9: 7 | C9: 0103045473 | D9: 252610088 | E9: Asyifa Maulidia Salsabila | F9: P | G9: X-1 | H9: =VLOOKUP(G9,MetaData!$A$2:$C$13,3,false) -> Selly Amalia, S.Hum | I9: GC1 X-1 | J9: =VLOOKUP(I9,MetaData!$E$2:$G$40,3,false) -> Syifa
A10: 10 | B10: 8 | C10: 0109105725 | D10: 252610100 | E10: Aurelia Langit Callysta | F10: P | G10: X-1 | H10: =VLOOKUP(G10,MetaData!$A$2:$C$13,3,false) -> Selly Amalia, S.Hum | I10: GC1 X-1 | J10: =VLOOKUP(I10,MetaData!$E$2:$G$40,3,false) -> Syifa
A11: 11 | B11: 9 | C11: 0096394871 | D11: 252610101 | E11: Aurelia Septiani Putri | F11: P | G11: X-1 | H11: =VLOOKUP(G11,MetaData!$A$2:$C$13,3,false) -> Selly Amalia, S.Hum | I11: GC1 X-1 | J11: =VLOOKUP(I11,MetaData!$E$2:$G$40,3,false) -> Syifa
A12: 12 | B12: 10 | C12: 0096477713 | D12: 252610122 | E12: Bilqis Anwar Thebe | F12: P | G12: X-1 | H12: =VLOOKUP(G12,MetaData!$A$2:$C$13,3,false) -> Selly Amalia, S.Hum | I12: XSUMEN1 GC | J12: =VLOOKUP(I12,MetaData!$E$2:$G$40,3,false) -> Ayun
A13: 13 | B13: 11 | C13: 0106995291 | D13: 252610126 | E13: Bimo Armani Aulia Putra | F13: L | G13: X-1 | H13: =VLOOKUP(G13,MetaData!$A$2:$C$13,3,false) -> Selly Amalia, S.Hum | I13: BC X-1 | J13: =VLOOKUP(I13,MetaData!$E$2:$G$40,3,false) -> Rony
A14: 14 | B14: 12 | C14: 0094126705 | D14: 252610130 | E14: Callysta Tuchi Solin | F14: P | G14: X-1 | H14: =VLOOKUP(G14,MetaData!$A$2:$C$13,3,false) -> Selly Amalia, S.Hum | I14: GC1 X-1 | J14: =VLOOKUP(I14,MetaData!$E$2:$G$40,3,false) -> Syifa
... A517: 594 | B517: 48 | C517: 0095810986 | D517: 252610562 | E517: Zalfa Rizqia Nur Nadhifa | F517: P | G517: X-12 | H517: =VLOOKUP(G517,MetaData!$A$2:$C$13,3,false) -> Sari Rahayu, S.Pd, M.Pd | I517: GC2 X-12 | J517: =VLOOKUP(I517,MetaData!$E$2:$G$40,3,false) -> Fiona (XI)

Sheet Angkatan 32
A2: Column 10 | B2: NO | C2: NISN | D2: NIS | E2: NAMA | F2: L/P | G2: Kelas | H2: Wali Kelas | I2: Grup | J2: Mentor | K2: Column 11
A3: 3 | B3: 1 | C3: 0092626116 | D3: 252610008 | E3: Adhie Bramantyo Faqih | F3: L | G3: X-1 | H3: =VLOOKUP(G3,MetaData!$A$2:$C$13,3,false) -> Selly Amalia, S.Hum | I3: BC X-1 | J3: =VLOOKUP(I3,MetaData!$E$2:$G$40,3,false) -> Rony
A4: 4 | B4: 2 | C4: 3103201253 | D4: 252610048 | E4: Almira Dwi Safira | F4: P | G4: X-1 | H4: =VLOOKUP(G4,MetaData!$A$2:$C$13,3,false) -> Selly Amalia, S.Hum | I4: GC1 X-1 | J4: =VLOOKUP(I4,MetaData!$E$2:$G$40,3,false) -> Syifa
A5: 5 | B5: 3 | C5: 0102149444 | D5: 252610053 | E5: Alzena Juneeta Talisha Theo | F5: P | G5: X-1 | H5: =VLOOKUP(G5,MetaData!$A$2:$C$13,3,false) -> Selly Amalia, S.Hum | I5: GC1 X-1 | J5: =VLOOKUP(I5,MetaData!$E$2:$G$40,3,false) -> Syifa
A6: 6 | B6: 4 | C6: 0095992391 | D6: 252610082 | E6: Arya Aditya Gunawan | F6: L | G6: X-1 | H6: =VLOOKUP(G6,MetaData!$A$2:$C$13,3,false) -> Selly Amalia, S.Hum | I6: BC X-1 | J6: =VLOOKUP(I6,MetaData!$E$2:$G$40,3,false) -> Rony
A7: 7 | B7: 5 | C7: 0106142601 | D7: 252610083 | E7: Aryasatia Pradipta | F7: P | G7: X-1 | H7: =VLOOKUP(G7,MetaData!$A$2:$C$13,3,false) -> Selly Amalia, S.Hum | I7: GC1 X-1 | J7: =VLOOKUP(I7,MetaData!$E$2:$G$40,3,false) -> Syifa
A8: 8 | B8: 6 | C8: 0108104548 | D8: 252610087 | E8: Asyifa Diandra Bayu | F8: P | G8: X-1 | H8: =VLOOKUP(G8,MetaData!$A$2:$C$13,3,false) -> Selly Amalia, S.Hum | I8: GC1 X-1 | J8: =VLOOKUP(I8,MetaData!$E$2:$G$40,3,false) -> Syifa
A9: 9 | B9: 7 | C9: 0103045473 | D9: 252610088 | E9: Asyifa Maulidia Salsabila | F9: P | G9: X-1 | H9: =VLOOKUP(G9,MetaData!$A$2:$C$13,3,false) -> Selly Amalia, S.Hum | I9: GC1 X-1 | J9: =VLOOKUP(I9,MetaData!$E$2:$G$40,3,false) -> Syifa
A10: 10 | B10: 8 | C10: 0109105725 | D10: 252610100 | E10: Aurelia Langit Callysta | F10: P | G10: X-1 | H10: =VLOOKUP(G10,MetaData!$A$2:$C$13,3,false) -> Selly Amalia, S.Hum | I10: GC1 X-1 | J10: =VLOOKUP(I10,MetaData!$E$2:$G$40,3,false) -> Syifa
A11: 11 | B11: 9 | C11: 0096394871 | D11: 252610101 | E11: Aurelia Septiani Putri | F11: P | G11: X-1 | H11: =VLOOKUP(G11,MetaData!$A$2:$C$13,3,false) -> Selly Amalia, S.Hum | I11: GC1 X-1 | J11: =VLOOKUP(I11,MetaData!$E$2:$G$40,3,false) -> Syifa
A12: 12 | B12: 10 | C12: 0096477713 | D12: 252610122 | E12: Bilqis Anwar Thebe | F12: P | G12: X-1 | H12: =VLOOKUP(G12,MetaData!$A$2:$C$13,3,false) -> Selly Amalia, S.Hum | I12: XSUMEN1 GC | J12: =VLOOKUP(I12,MetaData!$E$2:$G$40,3,false) -> Ayun
A13: 13 | B13: 11 | C13: 0106995291 | D13: 252610126 | E13: Bimo Armani Aulia Putra | F13: L | G13: X-1 | H13: =VLOOKUP(G13,MetaData!$A$2:$C$13,3,false) -> Selly Amalia, S.Hum | I13: BC X-1 | J13: =VLOOKUP(I13,MetaData!$E$2:$G$40,3,false) -> Rony
A14: 14 | B14: 12 | C14: 0094126705 | D14: 252610130 | E14: Callysta Tuchi Solin | F14: P | G14: X-1 | H14: =VLOOKUP(G14,MetaData!$A$2:$C$13,3,false) -> Selly Amalia, S.Hum | I14: GC1 X-1 | J14: =VLOOKUP(I14,MetaData!$E$2:$G$40,3,false) -> Syifa
... A517: 594 | B517: 48 | C517: 0095810986 | D517: 252610562 | E517: Zalfa Rizqia Nur Nadhifa | F517: P | G517: X-12 | H517: =VLOOKUP(G517,MetaData!$A$2:$C$13,3,false) -> Sari Rahayu, S.Pd, M.Pd | I517: GC2 X-12 | J517: =VLOOKUP(I517,MetaData!$E$2:$G$40,3,false) -> Fiona (XI)

Sheet Angkatan 31
A2: Column 10 | B2: NO | C2: NISN | D2: NIS | E2: NAMA | F2: L/P | G2: Kelas | H2: Wali Kelas | I2: Grup | J2: Mentor | K2: Column 11
A3: 3 | B3: 1 | C3: 0092626116 | D3: 252610008 | E3: Adhie Bramantyo Faqih | F3: L | G3: X-1 | H3: =VLOOKUP(G3,MetaData!$A$2:$C$13,3,false) -> Selly Amalia, S.Hum | I3: BC X-1 | J3: =VLOOKUP(I3,MetaData!$E$2:$G$40,3,false) -> Rony
A4: 4 | B4: 2 | C4: 3103201253 | D4: 252610048 | E4: Almira Dwi Safira | F4: P | G4: X-1 | H4: =VLOOKUP(G4,MetaData!$A$2:$C$13,3,false) -> Selly Amalia, S.Hum | I4: GC1 X-1 | J4: =VLOOKUP(I4,MetaData!$E$2:$G$40,3,false) -> Syifa
A5: 5 | B5: 3 | C5: 0102149444 | D5: 252610053 | E5: Alzena Juneeta Talisha Theo | F5: P | G5: X-1 | H5: =VLOOKUP(G5,MetaData!$A$2:$C$13,3,false) -> Selly Amalia, S.Hum | I5: GC1 X-1 | J5: =VLOOKUP(I5,MetaData!$E$2:$G$40,3,false) -> Syifa
A6: 6 | B6: 4 | C6: 0095992391 | D6: 252610082 | E6: Arya Aditya Gunawan | F6: L | G6: X-1 | H6: =VLOOKUP(G6,MetaData!$A$2:$C$13,3,false) -> Selly Amalia, S.Hum | I6: BC X-1 | J6: =VLOOKUP(I6,MetaData!$E$2:$G$40,3,false) -> Rony
A7: 7 | B7: 5 | C7: 0106142601 | D7: 252610083 | E7: Aryasatia Pradipta | F7: P | G7: X-1 | H7: =VLOOKUP(G7,MetaData!$A$2:$C$13,3,false) -> Selly Amalia, S.Hum | I7: GC1 X-1 | J7: =VLOOKUP(I7,MetaData!$E$2:$G$40,3,false) -> Syifa
A8: 8 | B8: 6 | C8: 0108104548 | D8: 252610087 | E8: Asyifa Diandra Bayu | F8: P | G8: X-1 | H8: =VLOOKUP(G8,MetaData!$A$2:$C$13,3,false) -> Selly Amalia, S.Hum | I8: GC1 X-1 | J8: =VLOOKUP(I8,MetaData!$E$2:$G$40,3,false) -> Syifa
A9: 9 | B9: 7 | C9: 0103045473 | D9: 252610088 | E9: Asyifa Maulidia Salsabila | F9: P | G9: X-1 | H9: =VLOOKUP(G9,MetaData!$A$2:$C$13,3,false) -> Selly Amalia, S.Hum | I9: GC1 X-1 | J9: =VLOOKUP(I9,MetaData!$E$2:$G$40,3,false) -> Syifa
A10: 10 | B10: 8 | C10: 0109105725 | D10: 252610100 | E10: Aurelia Langit Callysta | F10: P | G10: X-1 | H10: =VLOOKUP(G10,MetaData!$A$2:$C$13,3,false) -> Selly Amalia, S.Hum | I10: GC1 X-1 | J10: =VLOOKUP(I10,MetaData!$E$2:$G$40,3,false) -> Syifa
A11: 11 | B11: 9 | C11: 0096394871 | D11: 252610101 | E11: Aurelia Septiani Putri | F11: P | G11: X-1 | H11: =VLOOKUP(G11,MetaData!$A$2:$C$13,3,false) -> Selly Amalia, S.Hum | I11: GC1 X-1 | J11: =VLOOKUP(I11,MetaData!$E$2:$G$40,3,false) -> Syifa
A12: 12 | B12: 10 | C12: 0096477713 | D12: 252610122 | E12: Bilqis Anwar Thebe | F12: P | G12: X-1 | H12: =VLOOKUP(G12,MetaData!$A$2:$C$13,3,false) -> Selly Amalia, S.Hum | I12: XSUMEN1 GC | J12: =VLOOKUP(I12,MetaData!$E$2:$G$40,3,false) -> Ayun
A13: 13 | B13: 11 | C13: 0106995291 | D13: 252610126 | E13: Bimo Armani Aulia Putra | F13: L | G13: X-1 | H13: =VLOOKUP(G13,MetaData!$A$2:$C$13,3,false) -> Selly Amalia, S.Hum | I13: BC X-1 | J13: =VLOOKUP(I13,MetaData!$E$2:$G$40,3,false) -> Rony
A14: 14 | B14: 12 | C14: 0094126705 | D14: 252610130 | E14: Callysta Tuchi Solin | F14: P | G14: X-1 | H14: =VLOOKUP(G14,MetaData!$A$2:$C$13,3,false) -> Selly Amalia, S.Hum | I14: GC1 X-1 | J14: =VLOOKUP(I14,MetaData!$E$2:$G$40,3,false) -> Syifa
... A517: 594 | B517: 48 | C517: 0095810986 | D517: 252610562 | E517: Zalfa Rizqia Nur Nadhifa | F517: P | G517: X-12 | H517: =VLOOKUP(G517,MetaData!$A$2:$C$13,3,false) -> Sari Rahayu, S.Pd, M.Pd | I517: GC2 X-12 | J517: =VLOOKUP(I517,MetaData!$E$2:$G$40,3,false) -> Fiona (XI)

Sheet SUMEN33 MUHAMMAD
A2: No. | B2: Kelas | C2: NISN | D2: NIS | E2: Nama | F2: P/L | G2: Asal Sekolah | H2: Tilawah & Hafalan
A3: 1 | B3: X-2 | C3: 0098345742 | D3: 252610338 | E3: Muhammad Ariza Rizkya Irvan | F3: L | G3: al matuq boarding school / 6 juz | H3: Lancar sesuai tajwid
A4: 2 | B4: X-4 | C4: 3091547533 | D4: 252610275 | E4: Keyno Nazmi Afham | F4: L | G4: SMP Al-Kahfi : 3 juz | H4: Bagus, Lancar bacaannya
A5: 3 | B5: X-4 | C5: 3105173369 | D5: 252610378 | E5: Muhammad Zaidan Aqil | F5: L | G5: SMP Qur'an Assalam : 6 juz mutqin 3 | H5: Lancar bacaannya sesuai tajwid
A6: 4 | B6: X-5 | C6: 0105902624 | D6: 252610361 | E6: Muhammad Naufal Rhesa Fernando | F6: L | G6: SMPIT Rahmaniyah : 5 juz | H6: Lancar dengan tajwid
A7: 5 | B7: X-7 | C7: 0107042804 | D7: 252610197 | E7: Farhan Abdurrahman Yusuf | F7: L | G7: dari pondok pindah ke SMP / 5 juz | H7: Lancar dengan tajwid dan tartil
A8: 6 | B8: X-8 | C8: 3108018555 | D8: 252610353 | E8: Muhammad Fawaz Ali | F8: L | G8: SMPIT darul qur'an / 3juz | H8: Lancar sesuai tajwid
A9: 7 | B9: X-8 | C9: 0099739465 | D9: 252610470 | E9: Raka Syabany Amsyah | F9: L | G9: SMP Ungulan Rarohman Sukabumi : 5 juz | H9: Lancar sesuai tajwid
A10: 8 | B10: X-9 | C10: 0106681838 | D10: 252610003 | E10: Abyan Zuka Ibrahim Nasution | F10: L | G10: SMPIT Sinergi Islamic Boarding School / 3 juz | H10: Lancar sesuai tajwid
A11: 9 | B11: X-10 | C11: 0096033014 | D11: 252610001 | E11: Abdul Ghofar | F11: L | G11: Ponpes Rahmaniya / 3 juz | H11: Lancar dengan tajwid
A12: 10 | B12: X-10 | C12: 0109589144 | D12: 252610375 | E12: Muhammad Tsafiq Ihsan | F12: L | G12: Ponpes el tahfidh / 18 juz | H12: Lancar dengan tajwid

Sheet SUMEN33 REKHSA
A2: No. | B2: Kelas | C2: NISN | D2: NIS | E2: Nama | F2: P/L | G2: Asal Sekolah | H2: Tilawah & Hafalan
A3: 1 | B3: X-1 | C3: 0108695912 | D3: 252610334 | E3: Muhammad Adrian Gianni Adam | F3: L | G3: SMP Bintang Pelajar | H3: Lancar dengan tajwid
A4: 2 | B4: X-2 | C4: 0108384400 | D4: 252610320 | E4: Mohammad Irshad Faizanshah | F4: L | G4: SMP AL Azhar Syifa Budi | H4: Lancar sesuai tajwid dan tartil
A5: 3 | B5: X-5 | C5: 0092194625 | D5: 252610004 | E5: Achmad Ardiansyah | F5: L | G5: MTS Nurul Furqon | H5: Lancar dengan tajwid suara bagus
A6: 4 | B6: X-7 | C6: 0103120702 | D6: 252610144 | E6: Daffa Khoirul Fajri | F6: L | G6: Pondok Umul Quro | H6: Lancar dengan tajwid dan tartil
A7: 5 | B7: X-8 | C7: 0099772945 | D7: 252610324 | E7: Muhamad Ilham Akbar | F7: L | G7: Ponpes Idrisiyah | H7: Lancar sesuai tajwid
A8: 6 | B8: X-9 | C8: 0108974704 | D8: 252610019 | E8: Ahmad Hafidz Anwar | F8: L | G8: SMP Al Kahfi | H8: Lancar sesuai tajwid
A9: 7 | B9: X-9 | C9: 114593936 | D9: 252610231 | E9: Hizam Kynan Putra Purwanto | F9: L | G9: SMP Darul Jannah | H9: Lancar sesuai tajwid
A10: 8 | B10: X-9 | C10: 0097946386 | D10: 252610211 | E10: Fitrah Thirafi | F10: L | G10: SMP Al-Kahfi | H10: Lancar sesuai tajwid
A11: 9 | B11: X-11 | C11: 0092179308 | D11: 252610356 | E11: Muhammad Ieddzar Haradiya | F11: L | G11: SMP Syifa Budi | H11: Lancar dengan tajwid
A12: 10 | B12: X-12 | C12: 3106961615 | D12: 252610147 | E12: Damara Dasha Bahi Utomo | F12: L | G12: SMP IT Al Yasmin 2 Bogor | H12: Lancar dengan tajwid
A13: 11 | B13: X-12 | C13: 0098429745 | D13: 252610400 | E13: Natiq Tawqir Muniruzzaman Anandamaya | F13: L | G13: ponpes umul quro | H13: Lancar dengan tajwid suara bagus

Sheet SUMEN33 AYUN
A2: No. | B2: Kelas | C2: NISN | D2: NIS | E2: Nama | F2: P/L | G2: Asal Sekolah | H2: Tilawah & Hafalan
A3: 1 | B3: X-1 | C3: 0096477713 | D3: 252610122 | E3: Bilqis Anwar Thebe | F3: P | G3: Mahad AlFaruq : 4 juz | H3: Lancar dengan tajwid
A4: 2 | B4: X-1 | C4: 0092605198 | D4: 252610477 | E4: Rayhana Rizkya Al-Multazam | F4: P | G4: SMPIT Umul Quro : 10 juz | H4: Lancar dengan tajwid
A5: 3 | B5: X-2 | C5: 0105813396 | D5: 252610052 | E5: Alyya Zahra Kusumadewi | F5: P | G5: Pondok ma'had tahfidz Al=Qur'an Al=Imam Asy syathiby / 30 juz | H5: lancar sesuai tajwid
A6: 4 | B6: X-2 | C6: 0106276801 | D6: 252610434 | E6: Priscillia Putri Viona | F6: P | G6: SMP El Makmur / 3 juz | H6: Lancar sesuai tajwid
A7: 5 | B7: X-4 | C7: 0105775007 | D7: 252610514 | E7: Shafa Talitha Budiarto | F7: P | G7: SMP BINA INSAN MULIA 2 CIREBON : 5 JUZ | H7: Lancar bacaannya sesuai tajwid
A8: 6 | B8: X-5 | C8: 0099540724 | D8: 252610022 | E8: Aira Alessia Adha | F8: P | G8: SMPIT Rahmaniyah : 7 juz | H8: Lancar dengan tajwid
A9: 7 | B9: X-6 | C9: 0092383688 | D9: 252610195 | E9: Fanisa Nurkamila Hamdani | F9: P | G9: Ponpes Darul Qur'an (10 juz) | H9: Lancar dengan tajwid tartil dan suara bagus
A10: 8 | B10: X-10 | C10: 0103526904 | D10: 252610165 | E10: Dinara Savina | F10: P | G10: SMPIT al Iman | H10: Lancar dengan tajwid tartil
A11: 9 | B11: X-10 | C11: 0102890859 | D11: 252610235 | E11: Isnaini Fauziyah Utomo | F11: P | G11: Ponpes Rahmaniya / 5 juz | H11: Lancar dengan tajwid
A12: 10 | B12: X-11 | C12: 0099678017 | D12: 252610098 | E12: Aulia Intan Rhamadhani | F12: P | G12: SMP Sains Whid Hasyim 11 juz | H12: Lancar dengan tajwid
A13: 11 | B13: X-12 | C13: 2099366441 | D13: 252610106 | E13: Ayi Artadinata | F13: P | G13: SMP Bani Abdillah 8 juz | H13: Lancar dengan tajwid suara bagus
A14: 12 | B14: X-12 | C14: 0094328074 | D14: 252610391 | E14: Naila | F14: P | G14: SMPQ As Salam : 30 juz | H14: Lancar dengan tajwid
A15: 13 | B15: X-12 | C15: 0093563834 | D15: 252610490 | E15: Rifqah Ramadhani | F15: P | G15: MTS MILBoS International 7 juz | H15: Lancar dengn tajwid

Sheet SUMEN33 IQLIMA
A2: No. | B2: Kelas | C2: NISN | D2: NIS | E2: Nama | F2: P/L | G2: Asal Sekolah | H2: Tilawah & Hafalan
A3: 1 | B3: X-2 | C3: 0107760733 | D3: 252610023 | E3: Aira Aulia Putri | F3: P | G3: SMPIT AMALIA / | H3: Lancar sesuai tajwid
A4: 2 | B4: X-4 | C4: 0107838813 | D4: 252610056 | E4: Amira Najwa Fauziyah | F4: P | G4: SMPIT AMALIA | H4: Lancar bacaannya sesuai tajwid
A5: 3 | B5: X-5 | C5: 0102993208 | D5: 252610043 | E5: Alisya Belva Dhio | F5: P | G5: Ponpes Umul Quro | H5: Lancar dengan tajwid
A6: 4 | B6: X-5 | C6: 0103139137 | D6: 252610205 | E6: Fathimah Septiani Azahra | F6: P | G6: SMP Al azhar syifa budi | H6: Lancar dengan tajwid, suara bagus
A7: 5 | B7: X-5 | C7: 0108770789 | D7: 252610412 | E7: Nayyira Ghania Mehnaz | F7: P | G7: SMP IT Al-Huda wonogiri | H7: Lancar dengan tajwid
A8: 6 | B8: X-5 | C8: 3099045754 | D8: 252610427 | E8: Nurul Aulia Ramadhani | F8: P | G8: Ponpes AlQur'an Al Furqon | H8: Lancar dengan tajwid
A9: 7 | B9: X-7 | C9: 0108129059 | D9: 252610464 | E9: Raihana Humairah Budianto | F9: P | G9: SMP Anugerah Insani | H9: Lancar dengan tajwid dan tartil
A10: 8 | B10: X-8 | C10: 0103091510 | D10: 252610160 | E10: Dian Noer Savitri | F10: P | G10: Ponpes Assalam islamic boarding school | H10: Lancar sesuai tajwid
A11: 9 | B11: X-8 | C11: 0103174946 | D11: 252610203 | E11: Fathia Adilla Ramsha | F11: P | G11: SMP islam AMALIA | H11: Lancar sesuai tajwid
A12: 10 | B12: X-9 | C12: 3096149866 | D12: 252610473 | E12: Rassya Faiq Hibatullah | F12: P | G12: SMPIT Al-Kahfi | H12: Lancar sesuai tajwid
A13: 11 | B13: X-10 | C13: 2107246447 | D13: 252610014 | E13: Affy Kaew Ni'Mitr Alhanafi | F13: P | G13: SMP AMALIA | H13: Lancar tanpa tajwid
A14: 12 | B14: X-11 | C14: 0102000943 | D14: 252610388 | E14: Nadia Delisa Saefani | F14: P | G14: PONPES Darut Taqwa | H14: L:ancara dengan tajwid
... A16: 14 | B16: X-11 | C16: 0105717177 | D16: 252610545 | E16: Tiara Zenobia Nafisa | F16: P | G16: SMP AMALIA | H16: Lancar dengan

Sheet ALL
A3: Wali Kelas : Selly Amalia, S.Hum | E3: X-1
A4: NO | B4: NISN | C4: NIS | D4: NAMA | E4: L/P
A5: 1 | B5: 0092626116 | C5: 252610008 | D5: Adhie Bramantyo Faqih | E5: L
A6: 2 | B6: 3103201253 | C6: 252610048 | D6: Almira Dwi Safira | E6: P
A7: 3 | B7: 0102149444 | C7: 252610053 | D7: Alzena Juneeta Talisha Theo | E7: P
A8: 4 | B8: 0095992391 | C8: 252610082 | D8: Arya Aditya Gunawan | E8: L
A9: 5 | B9: 0106142601 | C9: 252610083 | D9: Aryasatia Pradipta | E9: P
A10: 6 | B10: 0108104548 | C10: 252610087 | D10: Asyifa Diandra Bayu | E10: P
A11: 7 | B11: 0103045473 | C11: 252610088 | D11: Asyifa Maulidia Salsabila | E11: P
A12: 8 | B12: 0109105725 | C12: 252610100 | D12: Aurelia Langit Callysta | E12: P
A13: 9 | B13: 0096394871 | C13: 252610101 | D13: Aurelia Septiani Putri | E13: P
A14: 10 | B14: 0096477713 | C14: 252610122 | D14: Bilqis Anwar Thebe | E14: P
A15: 11 | B15: 0106995291 | C15: 252610126 | D15: Bimo Armani Aulia Putra | E15: L
A16: 12 | B16: 0094126705 | C16: 252610130 | D16: Callysta Tuchi Solin | E16: P
... A46: 42 | B46: 0108505453 | C46: 252610566 | D46: Zhafirah Dwi Fauziah | E46: P
D48: Perempuan | E48: =COUNTIF(E5:E46,"P") -> 24
D49: Laki laki | E49: =COUNTIF(E5:E46,"L") -> 18
A52: Wali Kelas : Muhammad, S.Pd | E52: X-2
A53: NO | B53: NISN | C53: NIS | D53: NAMA | E53: L/P
A54: 1 | B54: 0094216870 | C54: 252610011 | D54: Adinda Syahira Hariyadi | E54: P
A55: 2 | B55: 0107760733 | C55: 252610023 | D55: Aira Aulia Putri | E55: P
A56: 3 | B56: 0105130233 | C56: 252610026 | D56: Aisha Faiha Dzakiyah | E56: P
A57: 4 | B57: 0104550133 | C57: 252610039 | D57: Alifa Safa Salsabila | E57: P
A58: 5 | B58: 0095372504 | C58: 252610050 | D58: Alviana Dwie Putery | E58: P
A59: 6 | B59: 0105813396 | C59: 252610052 | D59: Alyya Zahra Kusumadewi | E59: P
A60: 7 | B60: 0109006152 | C60: 252610058 | D60: Ammar Raziq Mahdiya | E60: L
A61: 8 | B61: 0097211030 | C61: 252610062 | D61: Andini Qoriyati Khaerani | E61: P
A62: 9 | B62: 3108667209 | C62: 252610070 | D62: Aqeela Az Zahra | E62: P
A63: 10 | B63: 0098513542 | C63: 252610084 | D63: Ashiila Rindu Dwi Laufli | E63: P
A64: 11 | B64: 0106376916 | C64: 252610090 | D64: Atharrayhan Abimanyu Pratama | E64: P
A65: 12 | B65: 0105797314 | C65: 252610102 | D65: Aurelly Diana Zulkarnaen | E65: P
... A96: 43 | B96: 0096087965 | C96: 252610563 | D96: Zalikhah Rasikhah Putri | E96: P
D98: Perempuan | E98: =COUNTIF(E54:E96,"P") -> 26
D99: Laki laki | E99: =COUNTIF(E54:E96,"L") -> 17
A102: Wali Kelas : Syamsi Jawawi, S.Pd | E102: X-3
A103: NO | B103: NISN | C103: NIS | D103: NAMA | E103: L/P
A104: 1 | B104: 0094703204 | C104: 252610002 | D104: Abhinaya Zaidan Akbar | E104: L
A105: 2 | B105: 0106941990 | C105: 252610063 | D105: Andra Rakadityono | E105: L
A106: 3 | B106: 0109964803 | C106: 252610065 | D106: Anjani Safira Salma | E106: P
A107: 4 | B107: 0104084075 | C107: 252610076 | D107: Ario Bimo Wicaksono | E107: L
...

Sheet MetaData
A1: Kelas | C1: Wali Kelas | E1: Grup | G1: Mentor | I1: Partner
A2: X-1 | C2: Selly Amalia, S.Hum | E2: BC X-1 | G2: Rony
A3: X-2 | C3: Muhammad, S.Pd | E3: BC X-2 | G3: Joko
A4: X-3 | C4: Syamsi Jawawi, S.Pd | E4: BC X-3 | G4: Angga
A5: X-4 | C5: Dwi Lestari, S.Pd | E5: BC X-4 | G5: Rizky Putra
A6: X-5 | C6: Deden Nur hasanah, S.E | E6: BC X-5 | G6: Topik & Adrian
A7: X-6 | C7: Raden Rara Tatra Sudhawati, S.Pd, M.Pd | E7: BC X-6 | G7: Arumbinang
A8: X-7 | C8: Dian Hairunnisa, S.Pd | E8: BC X-7 | G8: Rizza Al-Farisi
A9: X-8 | C9: Fatmawati, S.Pd | E9: BC X-8 | G9: Teguh
A10: X-9 | C10: Dra. Nani Suryani, M.Pd | E10: BC X-9 | G10: Veril (XII)
A11: X-10 | C11: Eva Fauziah, S.Pd | E11: BC X-10 | G11: Irghi (XII)
A12: X-11 | C12: Rahmalia Dewi, S.Si | E12: BC X-11 | G12: Khadafi (XII)
A13: X-12 | C13: Sari Rahayu, S.Pd, M.Pd | E13: BC X-12 | G13: Almeer (XII)
E14: XSUMEN BC | G14: Rekhsa
E15: GC1 X-1 | G15: Syifa
E16: GC1 X-2 | G16: Rania (XII)
E17: GC1 X-3 | G17: Hanin
E18: GC1 X-4 | G18: Najla
E19: GC1 X-5 | G19: Hana
E20: GC1 X-6 | G20: Khairunnisa (XII)
E21: GC1 X-7 | G21: Shafa
E22: GC1 X-8 | G22: Sakina
E23: GC1 X-9 | G23: Tiara (XII)
E24: GC1 X-10 | G24: Citra
E25: GC1 X-11 | G25: Kusniawati
... E40: GC2 X-12 | G40: Fiona (XI)

Sheet Mentee
A3: Wali Kelas : Selly Amalia, S.Hum | E3: X-1 | I3: Mentor: | J3: Syifa | O3: Mentor: | P3: Oshe (XII)
A4: NO | B4: NISN | C4: NIS | D4: NAMA | E4: L/P | G4: NO | H4: NISN | I4: NIS | J4: NAMA | K4: L/P | M4: NO | N4: NISN | O4: NIS | P4: NAMA | Q4: L/P
A5: 1 | B5: 0092626116 | C5: 252610008 | D5: Adhie Bramantyo Faqih | E5: L | G5: 1 | H5: 3103201253 | I5: 252610048 | J5: Almira Dwi Safira | K5: P | M5: 1 | N5: 0102149444 | O5: 252610053 | P5: Alzena Juneeta Talisha Theo | Q5: P
A6: 2 | B6: 0095992391 | C6: 252610082 | D6: Arya Aditya Gunawan | E6: L | G6: 2 | H6: 0106142601 | I6: 252610083 | J6: Aryasatia Pradipta | K6: P | M6: 2 | N6: 0108104548 | O6: 252610087 | P6: Asyifa Diandra Bayu | Q6: P
A7: 3 | B7: 0106995291 | C7: 252610126 | D7: Bimo Armani Aulia Putra | E7: L | G7: 3 | H7: 0103045473 | I7: 252610088 | J7: Asyifa Maulidia Salsabila | K7: P | M7: 3 | N7: 0109105725 | O7: 252610100 | P7: Aurelia Langit Callysta | Q7: P
A8: 4 | B8: 0105914504 | C8: 252610171 | D8: Diwangkara Rizki Rabbani | E8: L | G8: 4 | H8: 0096394871 | I8: 252610101 | J8: Aurelia Septiani Putri | K8: P | M8: 4 | N8: 0094126705 | O8: 252610130 | P8: Callysta Tuchi Solin | Q8: P
A9: 5 | B9: 0102644442 | C9: 252610193 | D9: Fakhri Haikal Alvito Rachmat | E9: L | G9: 5 | H9: 0092097491 | I9: 252610175 | J9: Dzahra Miftahuljanah | K9: P | M9: 5 | N9: 0095023834 | O9: 252610206 | P9: Fatimah Aszahra | Q9: P
A10: 6 | B10: 0107657965 | C10: 252610202 | D10: Fathi Azzam Hawwari | E10: L | G10: 6 | H10: 0094631117 | I10: 252610224 | J10: Gwenna Irene Winata | K10: P | M10: 6 | N10: 0092679798 | O10: 252610239 | P10: Jasmine Zahira Ramadhani | Q10: P
A11: 7 | B11: 0107959828 | C11: 252610316 | D11: Mochamad Nayaka Tuharea | E11: L | G11: 7 | H11: 0103648473 | I11: 252610246 | J11: Jihan Al Hasya | K11: P | M11: 7 | N11: 0092985486 | O11: 252610311 | P11: Melani Putri Triana | Q11: P
A12: 8 | B12: 0092600602 | C12: 252610330 | D12: Muhamad Septian Romadhon | E12: L | G12: 8 | H12: 0102300207 | I12: 252610390 | J12: Nadya Salwa Altiara | K12: P | M12: 8 | N12: 0097892166 | O12: 252610393 | P12: Nailah Khoirunisa Arsanti | Q12: P
A13: 9 | B13: 0093126257 | C13: 252610343 | D13: Muhammad Chaerudin Ramdhani | E13: L | G13: 9 | H13: 0097858274 | I13: 252610423 | J13: Novyola Safitri | K13: P | M13: 9 | N13: 0093105045 | O13: 252610424 | P13: Nur Alifah Silvia | Q13: P
A14: 10 | B14: 3104497802 | C14: 252610351 | D14: Muhammad Fathan Assidiq | E14: L | G14: 10 | H14: 0103151970 | I14: 252610489 | J14: Riffa Nugraha | K14: P | M14: 10 | N14: 0097644165 | O14: 252610508 | P14: Salsabila Zahwa Mulana | Q14: P
A15: 11 | B15: 0108107461 | C15: 252610369 | D15: Muhammad Rizky Aditya Putra Sukmawijayaguna | E15: L | G15: 11 | H15: 0102657659 | I15: 252610513 | J15: Shabira Ayatul Husna | K15: P | M15: 11 | N15: 0108505453 | O15: 252610566 | P15: Zhafirah Dwi Fauziah | Q15: P
A16: 12 | B16: 0092807405 | C16: 252610371 | D16: Muhammad Rodzul Amrullah | E16: L
A17: 13 | B17: 0095438030 | C17: 252610436 | D17: Pungki Yustisia Pertiwi | E17: L
A18: 14 | B18: 0107914534 | C18: 252610452 | D18: Raden Gathan Azaki Soesilo | E18: L
A19: 15 | B19: 0097963483 | C19: 252610454 | D19: Raden Muhammad Rafi Wiranata | E19: L
A20: 16 | B20: 0092135851 | C20: 252610476 | D20: Rayhan Ashabi | E20: L
A21: 17 | B21: 0111428850 | C21: 252610564 | D21: Zavier Lamya Arkanominatha | E21: L
D23: Perempuan | E23: =COUNTIF(K5:Q15,"P") -> 22
D24: Laki laki | E24: =COUNTIF(E5:E21,"L") -> 17
A27: Wali Kelas : Muhammad, S.Pd | E27: X-2 | I27: Mentor: | J27: Rania (XII) | O27: Mentor: | P27: Nadine (XI)
A28: NO | B28: NISN | C28: NIS | D28: NAMA | E28: L/P | G28: NO | H28: NISN | I28: NIS | J28: NAMA | K28: L/P | M28: NO | N28: NISN | O28: NIS | P28: NAMA | Q28: L/P
A29: 1 | B29: 0109006152 | C29: 252610058 | D29: Ammar Raziq Mahdiya | E29: L | G29: 1 | H29: 0094216870 | I29: 252610011 | J29: Adinda Syahira Hariyadi | K29: P | M29: 1 | N29: 0097593921 | O29: 252610181 | P29: Enisye Putri Zeliawati Limpong | Q29: P
A30: 2 | B30: 0102731314 | C30: 252610124 | D30: Bima Adyatma Ilmiawan | E30: L | G30: 2 | H30: 0105130233 | I30: 252610026 | J30: Aisha Faiha Dzakiyah | K30: P | M30: 2 | N30: 0105606050 | O30: 252610238 | P30: Jasmine Makayla Putri Arvani | Q30: P
A31: 3 | B31: 0106384221 | C31: 252610145 | D31: Dafsyah Arifa Putra | E31: L | G31: 3 | H31: 0104550133 | I31: 252610039 | J31: Alifa Safa Salsabila | K31: P | M31: 3 | N31: 0103261879 | O31: 252610280 | P31: Khansa Aulia Damtsa Hylmi | Q31: P
A32: 4 | B32: 0099675945 | C32: 252610164 | D32: Dimas Putra Pribadi | E32: L | G32: 4 | H32: 0095372504 | I32: 252610050 | J32: Alviana Dwie Putery | K32: P | M32: 4 | N32: 0093768427 | O32: 252610416 | P32: Neng Rahmi Novianti | Q32: P
A33: 5 | B33: 0104532267 | C33: 252610180 | D33: Elvio Dyahyu Yusanto | E33: L | G33: 5 | H33: 0097211030 | I33: 252610062 | J33: Andini Qoriyati Khaerani | K33: P | M33: 5 | N33: 0103404970 | O33: 252610419 | P33: Niesha Anindya Firstsaly | Q33: P
A34: 6 | B34: 0106157075 | C34: 252610185 | D34: Fabian Ahza Hidayat | E34: L | G34: 6 | H34: 3108667209 | I34: 252610070 | J34: Aqeela Az Zahra | K34: P | M34: 6 | N34: 0098833541 | O34: 252610440 | P34: Qaniah Mardiyah Salsabila | Q34: P
A35: 7 | B35: 0104141415 | C35: 252610186 | D35: Fadhilah Raisa Kamilati | E35: L | G35: 7 | H35: 0098513542 | I35: 252610084 | J35: Ashiila Rindu Dwi Laufli | K35: P | M35: 7 | N35: 0095492963 | O35: 252610467 | P35: Raisha Puri Lianti | Q35: P
A36: 8 | B36: 0094564578 | C36: 252610277 | D36: Khalid Ahmad Ghazali | E36: L | G36: 8 | H36: 0106376916 | I36: 252610090 | J36: Atharrayhan Abimanyu Pratama | K36: P | M36: 8 | N36: 0091964566 | O36: 252610474 | P36: Rasya Arkananta Mulya | Q36: P
A37: 9 | B37: 0092576905 | C37: 252610302 | D37: Mardiansyah Isman | E37: L | G37: 9 | H37: 0105797314 | I37: 252610102 | J37: Aurelly Diana Zulkarnaen | K37: P | M37: 9 | N37: 0092731928 | O37: 252610497 | P37: Rusvi Putri Ingguan | Q37: P
A38: 10 | B38: 0099605205 | C38: 252610319 | D38: Mohammad Haikal | E38: L | G38: 10 | H38: 0092794157 | I38: 252610139 | J38: Cinta Cludia Putri | K38: P | M38: 10 | N38: 0102751293 | O38: 252610546 | P38: Titania Dwizita Shahla | Q38: P
A39: 11 | B39: 0098087445 | C39: 252610332 | D39: Muhamad Thoriq Al Rasyad | E39: L | G39: 11 | H39: 3104617391 | I39: 252610153 | J39: Denisa Azka Putri | K39: P | M39: 11 | N39: 0096087965 | O39: 252610563 | P39: Zalikhah Rasikhah Putri | Q39: P
A40: 12 | B40: 0108518402 | C40: 252610336 | D40: Muhammad Akmaluddin | E40: L | G40: 12 | H40: 0098157268 | I40: 252610154 | J40: Devani Keyla Noris | K40: P
A41: 13 | B41: 0104535464 | C41: 252610362 | D41: Muhammad Nazam Rizal | E41: L
A42: 14 | B42: 3107410887 | C42: 252610365 | D42: Muhammad Rasyad Mahdawi | E42: L
A43: 15 | B43: 0104292767 | C43: 252610560 | D43: Zaidan Riziq Sakha | E43: L
D45: Perempuan | E45: =COUNTIF(K29:Q40,"P") -> 23
D46: Laki laki | E46: =COUNTIF(E29:E43,"L") -> 15
...
