Workbook

Sheet X 2
A1: PEMERINTAH DAERAH PROVINSI JAWA BARAT DINAS PENDIDIKAN SMA NEGERI 2 CIBINONG Jln. Karadenan No. 5 Cibinong Telp/Fax. ( 0251 ) 8654347 Bogor 16913 http://www.sman2cibinong.sch.id email: info@sman2cibinong.sch.id
A3: DAFTAR CAPAIAN PEMBELAJARAN SEMESTER 1
A4: TAHUN PELAJARAN 2025 - 2026
A6: Mata Pelajaran | C6: :
A7: Kelas | C7: : X-2
A8: Pengajar | C8: :
A10: NO | B10: NISN / NIS | C10: NAMA PESERTA DIDIK | D10: ASESMEN / PENILAIAN
S11: Rata - Rata | V11: PAS | W11: RT | X11: NR | Y11: Skp | Z11: Hdr | AA11: Rapor
D12: 1 | E12: 2 | F12: 3 | G12: 4 | H12: 5 | I12: 1 | J12: 2 | K12: 3 | L12: 4 | M12: 5 | N12: 1 | O12: 2 | P12: 3 | Q12: 4 | R12: 5 | S12: CP1 | T12: CP2 | U12: CP3
A13: 1 | B13: 0094216870 / 252610011 | C13: Adinda Syahira Hariyadi | S13: =AVERAGE(D13:H13) -> #DIV/0! | T13: =AVERAGE(I13:M13) -> #DIV/0! | U13: =AVERAGE(N13:R13) -> #DIV/0! | W13: =AVERAGE(S13:U13) -> #DIV/0! | X13: =ROUND(AVERAGE(V13:W13),0) -> #DIV/0! | Z13: 1 | AA13: =ROUND(IF((X13*(IF(Y13="A",105%,IF(Y13="B",102%,IF(Y13="C",75%,50%))))*Z13)>100,100,(X13*(IF(Y13="A",105%,IF(Y13="B",102%,IF(Y13="C",75%,50%))))*Z13)),0) -> #DIV/0!
A14: 2 | B14: 0107760733 / 252610023 | C14: Aira Aulia Putri | S14: =AVERAGE(D14:H14) -> #DIV/0! | T14: =AVERAGE(I14:M14) -> #DIV/0! | U14: =AVERAGE(N14:R14) -> #DIV/0! | W14: =AVERAGE(S14:U14) -> #DIV/0! | X14: =ROUND(AVERAGE(V14:W14),0) -> #DIV/0! | Z14: 1 | AA14: =ROUND(IF((X14*(IF(Y14="A",105%,IF(Y14="B",102%,IF(Y14="C",75%,50%))))*Z14)>100,100,(X14*(IF(Y14="A",105%,IF(Y14="B",102%,IF(Y14="C",75%,50%))))*Z14)),0) -> #DIV/0!
A15: 3 | B15: 0105130233 / 252610026 | C15: Aisha Faiha Dzakiyah | S15: =AVERAGE(D15:H15) -> #DIV/0! | T15: =AVERAGE(I15:M15) -> #DIV/0! | U15: =AVERAGE(N15:R15) -> #DIV/0! | W15: =AVERAGE(S15:U15) -> #DIV/0! | X15: =ROUND(AVERAGE(V15:W15),0) -> #DIV/0! | Z15: 1 | AA15: =ROUND(IF((X15*(IF(Y15="A",105%,IF(Y15="B",102%,IF(Y15="C",75%,50%))))*Z15)>100,100,(X15*(IF(Y15="A",105%,IF(Y15="B",102%,IF(Y15="C",75%,50%))))*Z15)),0) -> #DIV/0!
A16: 4 | B16: 0104550133 / 252610039 | C16: Alifa Safa Salsabila | S16: =AVERAGE(D16:H16) -> #DIV/0! | T16: =AVERAGE(I16:M16) -> #DIV/0! | U16: =AVERAGE(N16:R16) -> #DIV/0! | W16: =AVERAGE(S16:U16) -> #DIV/0! | X16: =ROUND(AVERAGE(V16:W16),0) -> #DIV/0! | Z16: 1 | AA16: =ROUND(IF((X16*(IF(Y16="A",105%,IF(Y16="B",102%,IF(Y16="C",75%,50%))))*Z16)>100,100,(X16*(IF(Y16="A",105%,IF(Y16="B",102%,IF(Y16="C",75%,50%))))*Z16)),0) -> #DIV/0!
A17: 5 | B17: 0095372504 / 252610050 | C17: Alviana Dwie Putery | S17: =AVERAGE(D17:H17) -> #DIV/0! | T17: =AVERAGE(I17:M17) -> #DIV/0! | U17: =AVERAGE(N17:R17) -> #DIV/0! | W17: =AVERAGE(S17:U17) -> #DIV/0! | X17: =ROUND(AVERAGE(V17:W17),0) -> #DIV/0! | Z17: 1 | AA17: =ROUND(IF((X17*(IF(Y17="A",105%,IF(Y17="B",102%,IF(Y17="C",75%,50%))))*Z17)>100,100,(X17*(IF(Y17="A",105%,IF(Y17="B",102%,IF(Y17="C",75%,50%))))*Z17)),0) -> #DIV/0!
A18: 6 | B18: 0105813396 / 252610052 | C18: Alyya Zahra Kusumadewi | S18: =AVERAGE(D18:H18) -> #DIV/0! | T18: =AVERAGE(I18:M18) -> #DIV/0! | U18: =AVERAGE(N18:R18) -> #DIV/0! | W18: =AVERAGE(S18:U18) -> #DIV/0! | X18: =ROUND(AVERAGE(V18:W18),0) -> #DIV/0! | Z18: 1 | AA18: =ROUND(IF((X18*(IF(Y18="A",105%,IF(Y18="B",102%,IF(Y18="C",75%,50%))))*Z18)>100,100,(X18*(IF(Y18="A",105%,IF(Y18="B",102%,IF(Y18="C",75%,50%))))*Z18)),0) -> #DIV/0!
A19: 7 | B19: 0109006152 / 252610058 | C19: Ammar Raziq Mahdiya | S19: =AVERAGE(D19:H19) -> #DIV/0! | T19: =AVERAGE(I19:M19) -> #DIV/0! | U19: =AVERAGE(N19:R19) -> #DIV/0! | W19: =AVERAGE(S19:U19) -> #DIV/0! | X19: =ROUND(AVERAGE(V19:W19),0) -> #DIV/0! | Z19: 1 | AA19: =ROUND(IF((X19*(IF(Y19="A",105%,IF(Y19="B",102%,IF(Y19="C",75%,50%))))*Z19)>100,100,(X19*(IF(Y19="A",105%,IF(Y19="B",102%,IF(Y19="C",75%,50%))))*Z19)),0) -> #DIV/0!
A20: 8 | B20: 0097211030 / 252610062 | C20: Andini Qoriyati Khaerani | S20: =AVERAGE(D20:H20) -> #DIV/0! | T20: =AVERAGE(I20:M20) -> #DIV/0! | U20: =AVERAGE(N20:R20) -> #DIV/0! | W20: =AVERAGE(S20:U20) -> #DIV/0! | X20: =ROUND(AVERAGE(V20:W20),0) -> #DIV/0! | Z20: 1 | AA20: =ROUND(IF((X20*(IF(Y20="A",105%,IF(Y20="B",102%,IF(Y20="C",75%,50%))))*Z20)>100,100,(X20*(IF(Y20="A",105%,IF(Y20="B",102%,IF(Y20="C",75%,50%))))*Z20)),0) -> #DIV/0!
A21: 9 | B21: 3108667209 / 252610070 | C21: Aqeela Az Zahra | S21: =AVERAGE(D21:H21) -> #DIV/0! | T21: =AVERAGE(I21:M21) -> #DIV/0! | U21: =AVERAGE(N21:R21) -> #DIV/0! | W21: =AVERAGE(S21:U21) -> #DIV/0! | X21: =ROUND(AVERAGE(V21:W21),0) -> #DIV/0! | Z21: 1 | AA21: =ROUND(IF((X21*(IF(Y21="A",105%,IF(Y21="B",102%,IF(Y21="C",75%,50%))))*Z21)>100,100,(X21*(IF(Y21="A",105%,IF(Y21="B",102%,IF(Y21="C",75%,50%))))*Z21)),0) -> #DIV/0!
A22: 10 | B22: 0109904498 / 252610075 | C22: Arfan Kristian Perlindungan Harefa | S22: =AVERAGE(D22:H22) -> #DIV/0! | T22: =AVERAGE(I22:M22) -> #DIV/0! | U22: =AVERAGE(N22:R22) -> #DIV/0! | W22: =AVERAGE(S22:U22) -> #DIV/0! | X22: =ROUND(AVERAGE(V22:W22),0) -> #DIV/0! | Z22: 1 | AA22: =ROUND(IF((X22*(IF(Y22="A",105%,IF(Y22="B",102%,IF(Y22="C",75%,50%))))*Z22)>100,100,(X22*(IF(Y22="A",105%,IF(Y22="B",102%,IF(Y22="C",75%,50%))))*Z22)),0) -> #DIV/0!
A23: 11 | B23: 0098513542 / 252610084 | C23: Ashiila Rindu Dwi Laufli | S23: =AVERAGE(D23:H23) -> #DIV/0! | T23: =AVERAGE(I23:M23) -> #DIV/0! | U23: =AVERAGE(N23:R23) -> #DIV/0! | W23: =AVERAGE(S23:U23) -> #DIV/0! | X23: =ROUND(AVERAGE(V23:W23),0) -> #DIV/0! | Z23: 1 | AA23: =ROUND(IF((X23*(IF(Y23="A",105%,IF(Y23="B",102%,IF(Y23="C",75%,50%))))*Z23)>100,100,(X23*(IF(Y23="A",105%,IF(Y23="B",102%,IF(Y23="C",75%,50%))))*Z23)),0) -> #DIV/0!
A24: 12 | B24: 0106376916 / 252610090 | C24: Atharrayhan Abimanyu Pratama | S24: =AVERAGE(D24:H24) -> #DIV/0! | T24: =AVERAGE(I24:M24) -> #DIV/0! | U24: =AVERAGE(N24:R24) -> #DIV/0! | W24: =AVERAGE(S24:U24) -> #DIV/0! | X24: =ROUND(AVERAGE(V24:W24),0) -> #DIV/0! | Z24: 1 | AA24: =ROUND(IF((X24*(IF(Y24="A",105%,IF(Y24="B",102%,IF(Y24="C",75%,50%))))*Z24)>100,100,(X24*(IF(Y24="A",105%,IF(Y24="B",102%,IF(Y24="C",75%,50%))))*Z24)),0) -> #DIV/0!
... A48: 36 | B48: 0093768427 / 252610416 | C48: Neng Rahmi Novianti | S48: =AVERAGE(D48:H48) -> #DIV/0! | T48: =AVERAGE(I48:M48) -> #DIV/0! | U48: =AVERAGE(N48:R48) -> #DIV/0! | W48: =AVERAGE(S48:U48) -> #DIV/0! | X48: =ROUND(AVERAGE(V48:W48),0) -> #DIV/0! | Z48: 1 | AA48: =ROUND(IF((X48*(IF(Y48="A",105%,IF(Y48="B",102%,IF(Y48="C",75%,50%))))*Z48)>100,100,(X48*(IF(Y48="A",105%,IF(Y48="B",102%,IF(Y48="C",75%,50%))))*Z48)),0) -> #DIV/0!
A49: 37 | B49: 0103404970 / 252610419 | C49: Niesha Anindya Firstsaly | S49: =AVERAGE(D49:H49) -> #DIV/0! | T49: =AVERAGE(I49:M49) -> #DIV/0! | U49: =AVERAGE(N49:R49) -> #DIV/0! | W49: =AVERAGE(S49:U49) -> #DIV/0! | X49: =ROUND(AVERAGE(V49:W49),0) -> #DIV/0! | AA49: =ROUND(IF((X49*(IF(Y49="A",105%,IF(Y49="B",102%,IF(Y49="C",75%,50%))))*Z49)>100,100,(X49*(IF(Y49="A",105%,IF(Y49="B",102%,IF(Y49="C",75%,50%))))*Z49)),0) -> #DIV/0!
A50: 38 | B50: 0102495325 / 252610431 | C50: Oryza Angelina Sitohang | S50: =AVERAGE(D50:H50) -> #DIV/0! | T50: =AVERAGE(I50:M50) -> #DIV/0! | U50: =AVERAGE(N50:R50) -> #DIV/0! | W50: =AVERAGE(S50:U50) -> #DIV/0! | X50: =ROUND(AVERAGE(V50:W50),0) -> #DIV/0! | AA50: =ROUND(IF((X50*(IF(Y50="A",105%,IF(Y50="B",102%,IF(Y50="C",75%,50%))))*Z50)>100,100,(X50*(IF(Y50="A",105%,IF(Y50="B",102%,IF(Y50="C",75%,50%))))*Z50)),0) -> #DIV/0!
A51: 39 | B51: 0106276801 / 252610434 | C51: Priscillia Putri Viona | S51: =AVERAGE(D51:H51) -> #DIV/0! | T51: =AVERAGE(I51:M51) -> #DIV/0! | U51: =AVERAGE(N51:R51) -> #DIV/0! | W51: =AVERAGE(S51:U51) -> #DIV/0! | X51: =ROUND(AVERAGE(V51:W51),0) -> #DIV/0! | AA51: =ROUND(IF((X51*(IF(Y51="A",105%,IF(Y51="B",102%,IF(Y51="C",75%,50%))))*Z51)>100,100,(X51*(IF(Y51="A",105%,IF(Y51="B",102%,IF(Y51="C",75%,50%))))*Z51)),0) -> #DIV/0!
A52: 40 | B52: 0098833541 / 252610440 | C52: Qaniah Mardiyah Salsabila | S52: =AVERAGE(D52:H52) -> #DIV/0! | T52: =AVERAGE(I52:M52) -> #DIV/0! | U52: =AVERAGE(N52:R52) -> #DIV/0! | W52: =AVERAGE(S52:U52) -> #DIV/0! | X52: =ROUND(AVERAGE(V52:W52),0) -> #DIV/0! | AA52: =ROUND(IF((X52*(IF(Y52="A",105%,IF(Y52="B",102%,IF(Y52="C",75%,50%))))*Z52)>100,100,(X52*(IF(Y52="A",105%,IF(Y52="B",102%,IF(Y52="C",75%,50%))))*Z52)),0) -> #DIV/0!
A53: 41 | B53: 0095492963 / 252610467 | C53: Raisha Puri Lianti | S53: =AVERAGE(D53:H53) -> #DIV/0! | T53: =AVERAGE(I53:M53) -> #DIV/0! | U53: =AVERAGE(N53:R53) -> #DIV/0! | W53: =AVERAGE(S53:U53) -> #DIV/0! | X53: =ROUND(AVERAGE(V53:W53),0) -> #DIV/0! | AA53: =ROUND(IF((X53*(IF(Y53="A",105%,IF(Y53="B",102%,IF(Y53="C",75%,50%))))*Z53)>100,100,(X53*(IF(Y53="A",105%,IF(Y53="B",102%,IF(Y53="C",75%,50%))))*Z53)),0) -> #DIV/0!
A54: 42 | B54: 0091964566 / 252610474 | C54: Rasya Arkananta Mulya | S54: =AVERAGE(D54:H54) -> #DIV/0! | T54: =AVERAGE(I54:M54) -> #DIV/0! | U54: =AVERAGE(N54:R54) -> #DIV/0! | W54: =AVERAGE(S54:U54) -> #DIV/0! | X54: =ROUND(AVERAGE(V54:W54),0) -> #DIV/0! | AA54: =ROUND(IF((X54*(IF(Y54="A",105%,IF(Y54="B",102%,IF(Y54="C",75%,50%))))*Z54)>100,100,(X54*(IF(Y54="A",105%,IF(Y54="B",102%,IF(Y54="C",75%,50%))))*Z54)),0) -> #DIV/0!
A55: 43 | B55: 0092731928 / 252610497 | C55: Rusvi Putri Ingguan | S55: =AVERAGE(D55:H55) -> #DIV/0! | T55: =AVERAGE(I55:M55) -> #DIV/0! | U55: =AVERAGE(N55:R55) -> #DIV/0! | W55: =AVERAGE(S55:U55) -> #DIV/0! | X55: =ROUND(AVERAGE(V55:W55),0) -> #DIV/0! | AA55: =ROUND(IF((X55*(IF(Y55="A",105%,IF(Y55="B",102%,IF(Y55="C",75%,50%))))*Z55)>100,100,(X55*(IF(Y55="A",105%,IF(Y55="B",102%,IF(Y55="C",75%,50%))))*Z55)),0) -> #DIV/0!
A56: 44 | B56: 0105816582 / 252610498 | C56: Ruth Rafanela Syeby Siregar | S56: =AVERAGE(D56:H56) -> #DIV/0! | T56: =AVERAGE(I56:M56) -> #DIV/0! | U56: =AVERAGE(N56:R56) -> #DIV/0! | W56: =AVERAGE(S56:U56) -> #DIV/0! | X56: =ROUND(AVERAGE(V56:W56),0) -> #DIV/0! | AA56: =ROUND(IF((X56*(IF(Y56="A",105%,IF(Y56="B",102%,IF(Y56="C",75%,50%))))*Z56)>100,100,(X56*(IF(Y56="A",105%,IF(Y56="B",102%,IF(Y56="C",75%,50%))))*Z56)),0) -> #DIV/0!
A57: 45 | B57: 0102751293 / 252610546 | C57: Titania Dwizita Shahla | S57: =AVERAGE(D57:H57) -> #DIV/0! | T57: =AVERAGE(I57:M57) -> #DIV/0! | U57: =AVERAGE(N57:R57) -> #DIV/0! | W57: =AVERAGE(S57:U57) -> #DIV/0! | X57: =ROUND(AVERAGE(V57:W57),0) -> #DIV/0! | AA57: =ROUND(IF((X57*(IF(Y57="A",105%,IF(Y57="B",102%,IF(Y57="C",75%,50%))))*Z57)>100,100,(X57*(IF(Y57="A",105%,IF(Y57="B",102%,IF(Y57="C",75%,50%))))*Z57)),0) -> #DIV/0!
A58: 46 | B58: 0104292767 / 252610560 | C58: Zaidan Riziq Sakha | S58: =AVERAGE(D58:H58) -> #DIV/0! | T58: =AVERAGE(I58:M58) -> #DIV/0! | U58: =AVERAGE(N58:R58) -> #DIV/0! | W58: =AVERAGE(S58:U58) -> #DIV/0! | X58: =ROUND(AVERAGE(V58:W58),0) -> #DIV/0! | AA58: =ROUND(IF((X58*(IF(Y58="A",105%,IF(Y58="B",102%,IF(Y58="C",75%,50%))))*Z58)>100,100,(X58*(IF(Y58="A",105%,IF(Y58="B",102%,IF(Y58="C",75%,50%))))*Z58)),0) -> #DIV/0!
A59: 47 | B59: 0096087965 / 252610563 | C59: Zalikhah Rasikhah Putri | S59: =AVERAGE(D59:H59) -> #DIV/0! | T59: =AVERAGE(I59:M59) -> #DIV/0! | U59: =AVERAGE(N59:R59) -> #DIV/0! | W59: =AVERAGE(S59:U59) -> #DIV/0! | X59: =ROUND(AVERAGE(V59:W59),0) -> #DIV/0! | AA59: =ROUND(IF((X59*(IF(Y59="A",105%,IF(Y59="B",102%,IF(Y59="C",75%,50%))))*Z59)>100,100,(X59*(IF(Y59="A",105%,IF(Y59="B",102%,IF(Y59="C",75%,50%))))*Z59)),0) -> #DIV/0!
Y61: max
Y62: min
Y63: avg

Sheet X 1
A1: PEMERINTAH DAERAH PROVINSI JAWA BARAT DINAS PENDIDIKAN SMA NEGERI 2 CIBINONG Jln. Karadenan No. 5 Cibinong Telp/Fax. ( 0251 ) 8654347 Bogor 16913 http://www.sman2cibinong.sch.id email: info@sman2cibinong.sch.id
A3: DAFTAR CAPAIAN PEMBELAJARAN SEMESTER 1
A4: TAHUN PELAJARAN 2025 - 2026
A6: Mata Pelajaran | C6: :
A7: Kelas | C7: : X-1
A8: Pengajar | C8: :
A10: NO | B10: NISN / NIS | C10: NAMA PESERTA DIDIK
D11: Total Hdr | E11: Hdr | F11: Rapor
A13: 1 | B13: 0092626116 / 252610008 | C13: Adhie Bramantyo Faqih | D13: 3 | E13: =D13/5 -> 0.6 | F13: =if(E13>=50%,"A","B") -> A
A14: 2 | B14: 3103201253 / 252610048 | C14: Almira Dwi Safira | D14: 2 | E14: =D14/5 -> 0.4 | F14: =if(E14>=50%,"A","B") -> B
A15: 3 | B15: 0102149444 / 252610053 | C15: Alzena Juneeta Talisha Theo | D15: 1 | E15: =D15/5 -> 0.2 | F15: =if(E15>=50%,"A","B") -> B
A16: 4 | B16: 0095992391 / 252610082 | C16: Arya Aditya Gunawan | D16: 3 | E16: =D16/5 -> 0.6 | F16: =if(E16>=50%,"A","B") -> A
A17: 5 | B17: 0106142601 / 252610083 | C17: Aryasatia Pradipta | D17: 1 | E17: =D17/5 -> 0.2 | F17: =if(E17>=50%,"A","B") -> B
A18: 6 | B18: 0108104548 / 252610087 | C18: Asyifa Diandra Bayu | D18: 2 | E18: =D18/5 -> 0.4 | F18: =if(E18>=50%,"A","B") -> B
A19: 7 | B19: 0103045473 / 252610088 | C19: Asyifa Maulidia Salsabila | D19: 1 | E19: =D19/5 -> 0.2 | F19: =if(E19>=50%,"A","B") -> B
A20: 8 | B20: 0109105725 / 252610100 | C20: Aurelia Langit Callysta | D20: 2 | E20: =D20/5 -> 0.4 | F20: =if(E20>=50%,"A","B") -> B
A21: 9 | B21: 0096394871 / 252610101 | C21: Aurelia Septiani Putri | D21: 2 | E21: =D21/5 -> 0.4 | F21: =if(E21>=50%,"A","B") -> B
A22: 10 | B22: 0099038184 / 252610109 | C22: Azalia Maheswari Christabel | D22: 0 | E22: =D22/5 -> 0 | F22: =if(E22>=50%,"A","B") -> B
A23: 11 | B23: 0096477713 / 252610122 | C23: Bilqis Anwar Thebe | D23: 2 | E23: =D23/5 -> 0.4 | F23: =if(E23>=50%,"A","B") -> B
A24: 12 | B24: 0106995291 / 252610126 | C24: Bimo Armani Aulia Putra | D24: 3 | E24: =D24/5 -> 0.6 | F24: =if(E24>=50%,"A","B") -> A
... A59: 47 | B59: 0108505453 / 252610566 | C59: Zhafirah Dwi Fauziah | D59: 0 | E59: =D59/5 -> 0 | F59: =if(E59>=50%,"A","B") -> B
D61: max
D62: min
D63: avg

Sheet X 3
A1: PEMERINTAH DAERAH PROVINSI JAWA BARAT DINAS PENDIDIKAN SMA NEGERI 2 CIBINONG Jln. Karadenan No. 5 Cibinong Telp/Fax. ( 0251 ) 8654347 Bogor 16913 http://www.sman2cibinong.sch.id email: info@sman2cibinong.sch.id
A3: DAFTAR CAPAIAN PEMBELAJARAN SEMESTER 1
A4: TAHUN PELAJARAN 2025 - 2026
A6: Mata Pelajaran | C6: :
A7: Kelas | C7: : X-3
A8: Pengajar | C8: :
A10: NO | B10: NISN / NIS | C10: NAMA PESERTA DIDIK | D10: ASESMEN / PENILAIAN
S11: Rata - Rata | V11: PAS | W11: RT | X11: NR | Y11: Skp | Z11: Hdr | AA11: Rapor
D12: 1 | E12: 2 | F12: 3 | G12: 4 | H12: 5 | I12: 1 | J12: 2 | K12: 3 | L12: 4 | M12: 5 | N12: 1 | O12: 2 | P12: 3 | Q12: 4 | R12: 5 | S12: CP1 | T12: CP2 | U12: CP3
A13: 1 | B13: 0094703204 / 252610002 | C13: Abhinaya Zaidan Akbar | S13: =AVERAGE(D13:H13) -> #DIV/0! | T13: =AVERAGE(I13:M13) -> #DIV/0! | U13: =AVERAGE(N13:R13) -> #DIV/0! | W13: =AVERAGE(S13:U13) -> #DIV/0! | X13: =ROUND(AVERAGE(V13:W13),0) -> #DIV/0! | Z13: 1 | AA13: =ROUND(IF((X13*(IF(Y13="A",105%,IF(Y13="B",102%,IF(Y13="C",75%,50%))))*Z13)>100,100,(X13*(IF(Y13="A",105%,IF(Y13="B",102%,IF(Y13="C",75%,50%))))*Z13)),0) -> #DIV/0!
A14: 2 | B14: 0106941990 / 252610063 | C14: Andra Rakadityono | S14: =AVERAGE(D14:H14) -> #DIV/0! | T14: =AVERAGE(I14:M14) -> #DIV/0! | U14: =AVERAGE(N14:R14) -> #DIV/0! | W14: =AVERAGE(S14:U14) -> #DIV/0! | X14: =ROUND(AVERAGE(V14:W14),0) -> #DIV/0! | Z14: 1 | AA14: =ROUND(IF((X14*(IF(Y14="A",105%,IF(Y14="B",102%,IF(Y14="C",75%,50%))))*Z14)>100,100,(X14*(IF(Y14="A",105%,IF(Y14="B",102%,IF(Y14="C",75%,50%))))*Z14)),0) -> #DIV/0!
A15: 3 | B15: 0109964803 / 252610065 | C15: Anjani Safira Salma | S15: =AVERAGE(D15:H15) -> #DIV/0! | T15: =AVERAGE(I15:M15) -> #DIV/0! | U15: =AVERAGE(N15:R15) -> #DIV/0! | W15: =AVERAGE(S15:U15) -> #DIV/0! | X15: =ROUND(AVERAGE(V15:W15),0) -> #DIV/0! | Z15: 1 | AA15: =ROUND(IF((X15*(IF(Y15="A",105%,IF(Y15="B",102%,IF(Y15="C",75%,50%))))*Z15)>100,100,(X15*(IF(Y15="A",105%,IF(Y15="B",102%,IF(Y15="C",75%,50%))))*Z15)),0) -> #DIV/0!
A16: 4 | B16: 0104084075 / 252610076 | C16: Ario Bimo Wicaksono | S16: =AVERAGE(D16:H16) -> #DIV/0! | T16: =AVERAGE(I16:M16) -> #DIV/0! | U16: =AVERAGE(N16:R16) -> #DIV/0! | W16: =AVERAGE(S16:U16) -> #DIV/0! | X16: =ROUND(AVERAGE(V16:W16),0) -> #DIV/0! | Z16: 1 | AA16: =ROUND(IF((X16*(IF(Y16="A",105%,IF(Y16="B",102%,IF(Y16="C",75%,50%))))*Z16)>100,100,(X16*(IF(Y16="A",105%,IF(Y16="B",102%,IF(Y16="C",75%,50%))))*Z16)),0) -> #DIV/0!
A17: 5 | B17: 0098221239 / 252610079 | C17: Arman Firmansyah | S17: =AVERAGE(D17:H17) -> #DIV/0! | T17: =AVERAGE(I17:M17) -> #DIV/0! | U17: =AVERAGE(N17:R17) -> #DIV/0! | W17: =AVERAGE(S17:U17) -> #DIV/0! | X17: =ROUND(AVERAGE(V17:W17),0) -> #DIV/0! | Z17: 1 | AA17: =ROUND(IF((X17*(IF(Y17="A",105%,IF(Y17="B",102%,IF(Y17="C",75%,50%))))*Z17)>100,100,(X17*(IF(Y17="A",105%,IF(Y17="B",102%,IF(Y17="C",75%,50%))))*Z17)),0) -> #DIV/0!
A18: 6 | B18: 0104751597 / 252610093 | C18: Attaya Putri Faslahi | S18: =AVERAGE(D18:H18) -> #DIV/0! | T18: =AVERAGE(I18:M18) -> #DIV/0! | U18: =AVERAGE(N18:R18) -> #DIV/0! | W18: =AVERAGE(S18:U18) -> #DIV/0! | X18: =ROUND(AVERAGE(V18:W18),0) -> #DIV/0! | Z18: 1 | AA18: =ROUND(IF((X18*(IF(Y18="A",105%,IF(Y18="B",102%,IF(Y18="C",75%,50%))))*Z18)>100,100,(X18*(IF(Y18="A",105%,IF(Y18="B",102%,IF(Y18="C",75%,50%))))*Z18)),0) -> #DIV/0!
A19: 7 | B19: 0104406841 / 252610094 | C19: Attiyah Naila Adza Alifah | S19: =AVERAGE(D19:H19) -> #DIV/0! | T19: =AVERAGE(I19:M19) -> #DIV/0! | U19: =AVERAGE(N19:R19) -> #DIV/0! | W19: =AVERAGE(S19:U19) -> #DIV/0! | X19: =ROUND(AVERAGE(V19:W19),0) -> #DIV/0! | Z19: 1 | AA19: =ROUND(IF((X19*(IF(Y19="A",105%,IF(Y19="B",102%,IF(Y19="C",75%,50%))))*Z19)>100,100,(X19*(IF(Y19="A",105%,IF(Y19="B",102%,IF(Y19="C",75%,50%))))*Z19)),0) -> #DIV/0!
A20: 8 | B20: 0102122161 / 252610096 | C20: Aulia Azahra | S20: =AVERAGE(D20:H20) -> #DIV/0! | T20: =AVERAGE(I20:M20) -> #DIV/0! | U20: =AVERAGE(N20:R20) -> #DIV/0! | W20: =AVERAGE(S20:U20) -> #DIV/0! | X20: =ROUND(AVERAGE(V20:W20),0) -> #DIV/0! | Z20: 1 | AA20: =ROUND(IF((X20*(IF(Y20="A",105%,IF(Y20="B",102%,IF(Y20="C",75%,50%))))*Z20)>100,100,(X20*(IF(Y20="A",105%,IF(Y20="B",102%,IF(Y20="C",75%,50%))))*Z20)),0) -> #DIV/0!
A21: 9 | B21: 0108329102 / 252610121 | C21: Bianca Aurelia Putri Asari | S21: =AVERAGE(D21:H21) -> #DIV/0! | T21: =AVERAGE(I21:M21) -> #DIV/0! | U21: =AVERAGE(N21:R21) -> #DIV/0! | W21: =AVERAGE(S21:U21) -> #DIV/0! | X21: =ROUND(AVERAGE(V21:W21),0) -> #DIV/0! | Z21: 1 | AA21: =ROUND(IF((X21*(IF(Y21="A",105%,IF(Y21="B",102%,IF(Y21="C",75%,50%))))*Z21)>100,100,(X21*(IF(Y21="A",105%,IF(Y21="B",102%,IF(Y21="C",75%,50%))))*Z21)),0) -> #DIV/0!
A22: 10 | B22: 0103047499 / 252610129 | C22: Bumi Byakta Alfian | S22: =AVERAGE(D22:H22) -> #DIV/0! | T22: =AVERAGE(I22:M22) -> #DIV/0! | U22: =AVERAGE(N22:R22) -> #DIV/0! | W22: =AVERAGE(S22:U22) -> #DIV/0! | X22: =ROUND(AVERAGE(V22:W22),0) -> #DIV/0! | Z22: 1 | AA22: =ROUND(IF((X22*(IF(Y22="A",105%,IF(Y22="B",102%,IF(Y22="C",75%,50%))))*Z22)>100,100,(X22*(IF(Y22="A",105%,IF(Y22="B",102%,IF(Y22="C",75%,50%))))*Z22)),0) -> #DIV/0!
A23: 11 | B23: 0102794623 / 252610136 | C23: Cheryl Faiha Al-Tair | S23: =AVERAGE(D23:H23) -> #DIV/0! | T23: =AVERAGE(I23:M23) -> #DIV/0! | U23: =AVERAGE(N23:R23) -> #DIV/0! | W23: =AVERAGE(S23:U23) -> #DIV/0! | X23: =ROUND(AVERAGE(V23:W23),0) -> #DIV/0! | Z23: 1 | AA23: =ROUND(IF((X23*(IF(Y23="A",105%,IF(Y23="B",102%,IF(Y23="C",75%,50%))))*Z23)>100,100,(X23*(IF(Y23="A",105%,IF(Y23="B",102%,IF(Y23="C",75%,50%))))*Z23)),0) -> #DIV/0!
A24: 12 | B24: 0096103714 / 252610138 | C24: Cindy Ramadhani Sinulingga | S24: =AVERAGE(D24:H24) -> #DIV/0! | T24: =AVERAGE(I24:M24) -> #DIV/0! | U24: =AVERAGE(N24:R24) -> #DIV/0! | W24: =AVERAGE(S24:U24) -> #DIV/0! | X24: =ROUND(AVERAGE(V24:W24),0) -> #DIV/0! | Z24: 1 | AA24: =ROUND(IF((X24*(IF(Y24="A",105%,IF(Y24="B",102%,IF(Y24="C",75%,50%))))*Z24)>100,100,(X24*(IF(Y24="A",105%,IF(Y24="B",102%,IF(Y24="C",75%,50%))))*Z24)),0) -> #DIV/0!
... A48: 36 | B48: 0102114748 / 252610426 | C48: Nursifa Maulidah | S48: =AVERAGE(D48:H48) -> #DIV/0! | T48: =AVERAGE(I48:M48) -> #DIV/0! | U48: =AVERAGE(N48:R48) -> #DIV/0! | W48: =AVERAGE(S48:U48) -> #DIV/0! | X48: =ROUND(AVERAGE(V48:W48),0) -> #DIV/0! | Z48: 1 | AA48: =ROUND(IF((X48*(IF(Y48="A",105%,IF(Y48="B",102%,IF(Y48="C",75%,50%))))*Z48)>100,100,(X48*(IF(Y48="A",105%,IF(Y48="B",102%,IF(Y48="C",75%,50%))))*Z48)),0) -> #DIV/0!
A49: 37 | B49: 0097603092 / 252610432 | C49: Pramudhio Sawerigading Ihsan | S49: =AVERAGE(D49:H49) -> #DIV/0! | T49: =AVERAGE(I49:M49) -> #DIV/0! | U49: =AVERAGE(N49:R49) -> #DIV/0! | W49: =AVERAGE(S49:U49) -> #DIV/0! | X49: =ROUND(AVERAGE(V49:W49),0) -> #DIV/0! | AA49: =ROUND(IF((X49*(IF(Y49="A",105%,IF(Y49="B",102%,IF(Y49="C",75%,50%))))*Z49)>100,100,(X49*(IF(Y49="A",105%,IF(Y49="B",102%,IF(Y49="C",75%,50%))))*Z49)),0) -> #DIV/0!
A50: 38 | B50: 0106292164 / 252610438 | C50: Putri Eisya | S50: =AVERAGE(D50:H50) -> #DIV/0! | T50: =AVERAGE(I50:M50) -> #DIV/0! | U50: =AVERAGE(N50:R50) -> #DIV/0! | W50: =AVERAGE(S50:U50) -> #DIV/0! | X50: =ROUND(AVERAGE(V50:W50),0) -> #DIV/0! | AA50: =ROUND(IF((X50*(IF(Y50="A",105%,IF(Y50="B",102%,IF(Y50="C",75%,50%))))*Z50)>100,100,(X50*(IF(Y50="A",105%,IF(Y50="B",102%,IF(Y50="C",75%,50%))))*Z50)),0) -> #DIV/0!
A51: 39 | B51: 3104085681 / 252610439 | C51: Putri Zaqiyah | S51: =AVERAGE(D51:H51) -> #DIV/0! | T51: =AVERAGE(I51:M51) -> #DIV/0! | U51: =AVERAGE(N51:R51) -> #DIV/0! | W51: =AVERAGE(S51:U51) -> #DIV/0! | X51: =ROUND(AVERAGE(V51:W51),0) -> #DIV/0! | AA51: =ROUND(IF((X51*(IF(Y51="A",105%,IF(Y51="B",102%,IF(Y51="C",75%,50%))))*Z51)>100,100,(X51*(IF(Y51="A",105%,IF(Y51="B",102%,IF(Y51="C",75%,50%))))*Z51)),0) -> #DIV/0!
A52: 40 | B52: 0105055522 / 252610461 | C52: Rahma Marissa | S52: =AVERAGE(D52:H52) -> #DIV/0! | T52: =AVERAGE(I52:M52) -> #DIV/0! | U52: =AVERAGE(N52:R52) -> #DIV/0! | W52: =AVERAGE(S52:U52) -> #DIV/0! | X52: =ROUND(AVERAGE(V52:W52),0) -> #DIV/0! | AA52: =ROUND(IF((X52*(IF(Y52="A",105%,IF(Y52="B",102%,IF(Y52="C",75%,50%))))*Z52)>100,100,(X52*(IF(Y52="A",105%,IF(Y52="B",102%,IF(Y52="C",75%,50%))))*Z52)),0) -> #DIV/0!
A53: 41 | B53: 0092263541 / 252610485 | C53: Revan | S53: =AVERAGE(D53:H53) -> #DIV/0! | T53: =AVERAGE(I53:M53) -> #DIV/0! | U53: =AVERAGE(N53:R53) -> #DIV/0! | W53: =AVERAGE(S53:U53) -> #DIV/0! | X53: =ROUND(AVERAGE(V53:W53),0) -> #DIV/0! | AA53: =ROUND(IF((X53*(IF(Y53="A",105%,IF(Y53="B",102%,IF(Y53="C",75%,50%))))*Z53)>100,100,(X53*(IF(Y53="A",105%,IF(Y53="B",102%,IF(Y53="C",75%,50%))))*Z53)),0) -> #DIV/0!
A54: 42 | B54: 0091178036 / 252610501 | C54: Safa Naya Adristi | S54: =AVERAGE(D54:H54) -> #DIV/0! | T54: =AVERAGE(I54:M54) -> #DIV/0! | U54: =AVERAGE(N54:R54) -> #DIV/0! | W54: =AVERAGE(S54:U54) -> #DIV/0! | X54: =ROUND(AVERAGE(V54:W54),0) -> #DIV/0! | AA54: =ROUND(IF((X54*(IF(Y54="A",105%,IF(Y54="B",102%,IF(Y54="C",75%,50%))))*Z54)>100,100,(X54*(IF(Y54="A",105%,IF(Y54="B",102%,IF(Y54="C",75%,50%))))*Z54)),0) -> #DIV/0!
A55: 43 | B55: 0106930882 / 252610520 | C55: Shirane Ghaniyya Ramadhani | S55: =AVERAGE(D55:H55) -> #DIV/0! | T55: =AVERAGE(I55:M55) -> #DIV/0! | U55: =AVERAGE(N55:R55) -> #DIV/0! | W55: =AVERAGE(S55:U55) -> #DIV/0! | X55: =ROUND(AVERAGE(V55:W55),0) -> #DIV/0! | AA55: =ROUND(IF((X55*(IF(Y55="A",105%,IF(Y55="B",102%,IF(Y55="C",75%,50%))))*Z55)>100,100,(X55*(IF(Y55="A",105%,IF(Y55="B",102%,IF(Y55="C",75%,50%))))*Z55)),0) -> #DIV/0!
A56: 44 | B56: 0109721617 / 252610555 | C56: Yasmin Kirani Affifah | S56: =AVERAGE(D56:H56) -> #DIV/0! | T56: =AVERAGE(I56:M56) -> #DIV/0! | U56: =AVERAGE(N56:R56) -> #DIV/0! | W56: =AVERAGE(S56:U56) -> #DIV/0! | X56: =ROUND(AVERAGE(V56:W56),0) -> #DIV/0! | AA56: =ROUND(IF((X56*(IF(Y56="A",105%,IF(Y56="B",102%,IF(Y56="C",75%,50%))))*Z56)>100,100,(X56*(IF(Y56="A",105%,IF(Y56="B",102%,IF(Y56="C",75%,50%))))*Z56)),0) -> #DIV/0!
A57: 45 | B57: 0101188685 / 252610556 | C57: Yasmine Almira Queen | S57: =AVERAGE(D57:H57) -> #DIV/0! | T57: =AVERAGE(I57:M57) -> #DIV/0! | U57: =AVERAGE(N57:R57) -> #DIV/0! | W57: =AVERAGE(S57:U57) -> #DIV/0! | X57: =ROUND(AVERAGE(V57:W57),0) -> #DIV/0! | AA57: =ROUND(IF((X57*(IF(Y57="A",105%,IF(Y57="B",102%,IF(Y57="C",75%,50%))))*Z57)>100,100,(X57*(IF(Y57="A",105%,IF(Y57="B",102%,IF(Y57="C",75%,50%))))*Z57)),0) -> #DIV/0!
Y59: max
Y60: min
Y61: avg

Sheet X 4
A1: PEMERINTAH DAERAH PROVINSI JAWA BARAT DINAS PENDIDIKAN SMA NEGERI 2 CIBINONG Jln. Karadenan No. 5 Cibinong Telp/Fax. ( 0251 ) 8654347 Bogor 16913 http://www.sman2cibinong.sch.id email: info@sman2cibinong.sch.id
A3: DAFTAR CAPAIAN PEMBELAJARAN SEMESTER 1
A4: TAHUN PELAJARAN 2025 - 2026
A6: Mata Pelajaran | C6: :
A7: Kelas | C7: : X-4
A8: Pengajar | C8: :
A10: NO | B10: NISN / NIS | C10: NAMA PESERTA DIDIK | D10: ASESMEN / PENILAIAN
S11: Rata - Rata | V11: PAS | W11: RT | X11: NR | Y11: Skp | Z11: Hdr | AA11: Rapor
D12: 1 | E12: 2 | F12: 3 | G12: 4 | H12: 5 | I12: 1 | J12: 2 | K12: 3 | L12: 4 | M12: 5 | N12: 1 | O12: 2 | P12: 3 | Q12: 4 | R12: 5 | S12: CP1 | T12: CP2 | U12: CP3
A13: 1 | B13: 0106136353 / 252610016 | C13: Ahmad Azmi Mutaarrofi | S13: =AVERAGE(D13:H13) -> #DIV/0! | T13: =AVERAGE(I13:M13) -> #DIV/0! | U13: =AVERAGE(N13:R13) -> #DIV/0! | W13: =AVERAGE(S13:U13) -> #DIV/0! | X13: =ROUND(AVERAGE(V13:W13),0) -> #DIV/0! | Z13: 1 | AA13: =ROUND(IF((X13*(IF(Y13="A",105%,IF(Y13="B",102%,IF(Y13="C",75%,50%))))*Z13)>100,100,(X13*(IF(Y13="A",105%,IF(Y13="B",102%,IF(Y13="C",75%,50%))))*Z13)),0) -> #DIV/0!
A14: 2 | B14: 0095491750 / 252610018 | C14: Ahmad Farely Azriel | S14: =AVERAGE(D14:H14) -> #DIV/0! | T14: =AVERAGE(I14:M14) -> #DIV/0! | U14: =AVERAGE(N14:R14) -> #DIV/0! | W14: =AVERAGE(S14:U14) -> #DIV/0! | X14: =ROUND(AVERAGE(V14:W14),0) -> #DIV/0! | Z14: 1 | AA14: =ROUND(IF((X14*(IF(Y14="A",105%,IF(Y14="B",102%,IF(Y14="C",75%,50%))))*Z14)>100,100,(X14*(IF(Y14="A",105%,IF(Y14="B",102%,IF(Y14="C",75%,50%))))*Z14)),0) -> #DIV/0!
A15: 3 | B15: 0087811342 / 252610038 | C15: Alfian Chaniago | S15: =AVERAGE(D15:H15) -> #DIV/0! | T15: =AVERAGE(I15:M15) -> #DIV/0! | U15: =AVERAGE(N15:R15) -> #DIV/0! | W15: =AVERAGE(S15:U15) -> #DIV/0! | X15: =ROUND(AVERAGE(V15:W15),0) -> #DIV/0! | Z15: 1 | AA15: =ROUND(IF((X15*(IF(Y15="A",105%,IF(Y15="B",102%,IF(Y15="C",75%,50%))))*Z15)>100,100,(X15*(IF(Y15="A",105%,IF(Y15="B",102%,IF(Y15="C",75%,50%))))*Z15)),0) -> #DIV/0!
A16: 4 | B16: 0094160993 / 252610045 | C16: Alleandra Kaif Finandita | S16: =AVERAGE(D16:H16) -> #DIV/0! | T16: =AVERAGE(I16:M16) -> #DIV/0! | U16: =AVERAGE(N16:R16) -> #DIV/0! | W16: =AVERAGE(S16:U16) -> #DIV/0! | X16: =ROUND(AVERAGE(V16:W16),0) -> #DIV/0! | Z16: 1 | AA16: =ROUND(IF((X16*(IF(Y16="A",105%,IF(Y16="B",102%,IF(Y16="C",75%,50%))))*Z16)>100,100,(X16*(IF(Y16="A",105%,IF(Y16="B",102%,IF(Y16="C",75%,50%))))*Z16)),0) -> #DIV/0!
A17: 5 | B17: 0103659705 / 252610049 | C17: Altaira Aqila Myesha Ario | S17: =AVERAGE(D17:H17) -> #DIV/0! | T17: =AVERAGE(I17:M17) -> #DIV/0! | U17: =AVERAGE(N17:R17) -> #DIV/0! | W17: =AVERAGE(S17:U17) -> #DIV/0! | X17: =ROUND(AVERAGE(V17:W17),0) -> #DIV/0! | Z17: 1 | AA17: =ROUND(IF((X17*(IF(Y17="A",105%,IF(Y17="B",102%,IF(Y17="C",75%,50%))))*Z17)>100,100,(X17*(IF(Y17="A",105%,IF(Y17="B",102%,IF(Y17="C",75%,50%))))*Z17)),0) -> #DIV/0!
A18: 6 | B18: 0107838813 / 252610056 | C18: Amira Najwa Fauziyah | S18: =AVERAGE(D18:H18) -> #DIV/0! | T18: =AVERAGE(I18:M18) -> #DIV/0! | U18: =AVERAGE(N18:R18) -> #DIV/0! | W18: =AVERAGE(S18:U18) -> #DIV/0! | X18: =ROUND(AVERAGE(V18:W18),0) -> #DIV/0! | Z18: 1 | AA18: =ROUND(IF((X18*(IF(Y18="A",105%,IF(Y18="B",102%,IF(Y18="C",75%,50%))))*Z18)>100,100,(X18*(IF(Y18="A",105%,IF(Y18="B",102%,IF(Y18="C",75%,50%))))*Z18)),0) -> #DIV/0!
A19: 7 | B19: 0108144208 / 252610069 | C19: Aphrodyta Aurelia Avrilla | S19: =AVERAGE(D19:H19) -> #DIV/0! | T19: =AVERAGE(I19:M19) -> #DIV/0! | U19: =AVERAGE(N19:R19) -> #DIV/0! | W19: =AVERAGE(S19:U19) -> #DIV/0! | X19: =ROUND(AVERAGE(V19:W19),0) -> #DIV/0! | Z19: 1 | AA19: =ROUND(IF((X19*(IF(Y19="A",105%,IF(Y19="B",102%,IF(Y19="C",75%,50%))))*Z19)>100,100,(X19*(IF(Y19="A",105%,IF(Y19="B",102%,IF(Y19="C",75%,50%))))*Z19)),0) -> #DIV/0!
A20: 8 | B20: 0096853688 / 252610074 | C20: Aqueena Putri Salimah | S20: =AVERAGE(D20:H20) -> #DIV/0! | T20: =AVERAGE(I20:M20) -> #DIV/0! | U20: =AVERAGE(N20:R20) -> #DIV/0! | W20: =AVERAGE(S20:U20) -> #DIV/0! | X20: =ROUND(AVERAGE(V20:W20),0) -> #DIV/0! | Z20: 1 | AA20: =ROUND(IF((X20*(IF(Y20="A",105%,IF(Y20="B",102%,IF(Y20="C",75%,50%))))*Z20)>100,100,(X20*(IF(Y20="A",105%,IF(Y20="B",102%,IF(Y20="C",75%,50%))))*Z20)),0) -> #DIV/0!
A21: 9 | B21: 0092637367 / 252610132 | C21: Chairani Kanza Wulandaputri | S21: =AVERAGE(D21:H21) -> #DIV/0! | T21: =AVERAGE(I21:M21) -> #DIV/0! | U21: =AVERAGE(N21:R21) -> #DIV/0! | W21: =AVERAGE(S21:U21) -> #DIV/0! | X21: =ROUND(AVERAGE(V21:W21),0) -> #DIV/0! | Z21: 1 | AA21: =ROUND(IF((X21*(IF(Y21="A",105%,IF(Y21="B",102%,IF(Y21="C",75%,50%))))*Z21)>100,100,(X21*(IF(Y21="A",105%,IF(Y21="B",102%,IF(Y21="C",75%,50%))))*Z21)),0) -> #DIV/0!
A22: 10 | B22: 0095522157 / 252610155 | C22: Dhefa Raditya Putra | S22: =AVERAGE(D22:H22) -> #DIV/0! | T22: =AVERAGE(I22:M22) -> #DIV/0! | U22: =AVERAGE(N22:R22) -> #DIV/0! | W22: =AVERAGE(S22:U22) -> #DIV/0! | X22: =ROUND(AVERAGE(V22:W22),0) -> #DIV/0! | Z22: 1 | AA22: =ROUND(IF((X22*(IF(Y22="A",105%,IF(Y22="B",102%,IF(Y22="C",75%,50%))))*Z22)>100,100,(X22*(IF(Y22="A",105%,IF(Y22="B",102%,IF(Y22="C",75%,50%))))*Z22)),0) -> #DIV/0!
A23: 11 | B23: 0098223677 / 252610162 | C23: Diaz Syeza Zivanna | S23: =AVERAGE(D23:H23) -> #DIV/0! | T23: =AVERAGE(I23:M23) -> #DIV/0! | U23: =AVERAGE(N23:R23) -> #DIV/0! | W23: =AVERAGE(S23:U23) -> #DIV/0! | X23: =ROUND(AVERAGE(V23:W23),0) -> #DIV/0! | Z23: 1 | AA23: =ROUND(IF((X23*(IF(Y23="A",105%,IF(Y23="B",102%,IF(Y23="C",75%,50%))))*Z23)>100,100,(X23*(IF(Y23="A",105%,IF(Y23="B",102%,IF(Y23="C",75%,50%))))*Z23)),0) -> #DIV/0!
A24: 12 | B24: 0106545857 / 252610173 | C24: Dwi Nailah Azhara | S24: =AVERAGE(D24:H24) -> #DIV/0! | T24: =AVERAGE(I24:M24) -> #DIV/0! | U24: =AVERAGE(N24:R24) -> #DIV/0! | W24: =AVERAGE(S24:U24) -> #DIV/0! | X24: =ROUND(AVERAGE(V24:W24),0) -> #DIV/0! | Z24: 1 | AA24: =ROUND(IF((X24*(IF(Y24="A",105%,IF(Y24="B",102%,IF(Y24="C",75%,50%))))*Z24)>100,100,(X24*(IF(Y24="A",105%,IF(Y24="B",102%,IF(Y24="C",75%,50%))))*Z24)),0) -> #DIV/0!
... A48: 36 | B48: 0107960365 / 252610475 | C48: Ravino Abbas Subaga | S48: =AVERAGE(D48:H48) -> #DIV/0! | T48: =AVERAGE(I48:M48) -> #DIV/0! | U48: =AVERAGE(N48:R48) -> #DIV/0! | W48: =AVERAGE(S48:U48) -> #DIV/0! | X48: =ROUND(AVERAGE(V48:W48),0) -> #DIV/0! | Z48: 1 | AA48: =ROUND(IF((X48*(IF(Y48="A",105%,IF(Y48="B",102%,IF(Y48="C",75%,50%))))*Z48)>100,100,(X48*(IF(Y48="A",105%,IF(Y48="B",102%,IF(Y48="C",75%,50%))))*Z48)),0) -> #DIV/0!
A49: 37 | B49: 0104838010 / 252610480 | C49: Rei Dillan Hartedi | S49: =AVERAGE(D49:H49) -> #DIV/0! | T49: =AVERAGE(I49:M49) -> #DIV/0! | U49: =AVERAGE(N49:R49) -> #DIV/0! | W49: =AVERAGE(S49:U49) -> #DIV/0! | X49: =ROUND(AVERAGE(V49:W49),0) -> #DIV/0! | AA49: =ROUND(IF((X49*(IF(Y49="A",105%,IF(Y49="B",102%,IF(Y49="C",75%,50%))))*Z49)>100,100,(X49*(IF(Y49="A",105%,IF(Y49="B",102%,IF(Y49="C",75%,50%))))*Z49)),0) -> #DIV/0!
A50: 38 | B50: 0108451246 / 252610483 | C50: Reni Apriliani | S50: =AVERAGE(D50:H50) -> #DIV/0! | T50: =AVERAGE(I50:M50) -> #DIV/0! | U50: =AVERAGE(N50:R50) -> #DIV/0! | W50: =AVERAGE(S50:U50) -> #DIV/0! | X50: =ROUND(AVERAGE(V50:W50),0) -> #DIV/0! | AA50: =ROUND(IF((X50*(IF(Y50="A",105%,IF(Y50="B",102%,IF(Y50="C",75%,50%))))*Z50)>100,100,(X50*(IF(Y50="A",105%,IF(Y50="B",102%,IF(Y50="C",75%,50%))))*Z50)),0) -> #DIV/0!
A51: 39 | B51: 3104089400 / 252610492 | C51: Rizky Putra Kunta Ajie | S51: =AVERAGE(D51:H51) -> #DIV/0! | T51: =AVERAGE(I51:M51) -> #DIV/0! | U51: =AVERAGE(N51:R51) -> #DIV/0! | W51: =AVERAGE(S51:U51) -> #DIV/0! | X51: =ROUND(AVERAGE(V51:W51),0) -> #DIV/0! | AA51: =ROUND(IF((X51*(IF(Y51="A",105%,IF(Y51="B",102%,IF(Y51="C",75%,50%))))*Z51)>100,100,(X51*(IF(Y51="A",105%,IF(Y51="B",102%,IF(Y51="C",75%,50%))))*Z51)),0) -> #DIV/0!
A52: 40 | B52: 0107731505 / 252610512 | C52: Shabira Andiani | S52: =AVERAGE(D52:H52) -> #DIV/0! | T52: =AVERAGE(I52:M52) -> #DIV/0! | U52: =AVERAGE(N52:R52) -> #DIV/0! | W52: =AVERAGE(S52:U52) -> #DIV/0! | X52: =ROUND(AVERAGE(V52:W52),0) -> #DIV/0! | AA52: =ROUND(IF((X52*(IF(Y52="A",105%,IF(Y52="B",102%,IF(Y52="C",75%,50%))))*Z52)>100,100,(X52*(IF(Y52="A",105%,IF(Y52="B",102%,IF(Y52="C",75%,50%))))*Z52)),0) -> #DIV/0!
A53: 41 | B53: 0105775007 / 252610514 | C53: Shafa Talitha Budiarto | S53: =AVERAGE(D53:H53) -> #DIV/0! | T53: =AVERAGE(I53:M53) -> #DIV/0! | U53: =AVERAGE(N53:R53) -> #DIV/0! | W53: =AVERAGE(S53:U53) -> #DIV/0! | X53: =ROUND(AVERAGE(V53:W53),0) -> #DIV/0! | AA53: =ROUND(IF((X53*(IF(Y53="A",105%,IF(Y53="B",102%,IF(Y53="C",75%,50%))))*Z53)>100,100,(X53*(IF(Y53="A",105%,IF(Y53="B",102%,IF(Y53="C",75%,50%))))*Z53)),0) -> #DIV/0!
A54: 42 | B54: 0106588309 / 252610515 | C54: Shahira Hafiza Putri | S54: =AVERAGE(D54:H54) -> #DIV/0! | T54: =AVERAGE(I54:M54) -> #DIV/0! | U54: =AVERAGE(N54:R54) -> #DIV/0! | W54: =AVERAGE(S54:U54) -> #DIV/0! | X54: =ROUND(AVERAGE(V54:W54),0) -> #DIV/0! | AA54: =ROUND(IF((X54*(IF(Y54="A",105%,IF(Y54="B",102%,IF(Y54="C",75%,50%))))*Z54)>100,100,(X54*(IF(Y54="A",105%,IF(Y54="B",102%,IF(Y54="C",75%,50%))))*Z54)),0) -> #DIV/0!
A55: 43 | B55: 0106219079 / 252610519 | C55: Sheika Rizki Ramadanti Aurelia | S55: =AVERAGE(D55:H55) -> #DIV/0! | T55: =AVERAGE(I55:M55) -> #DIV/0! | U55: =AVERAGE(N55:R55) -> #DIV/0! | W55: =AVERAGE(S55:U55) -> #DIV/0! | X55: =ROUND(AVERAGE(V55:W55),0) -> #DIV/0! | AA55: =ROUND(IF((X55*(IF(Y55="A",105%,IF(Y55="B",102%,IF(Y55="C",75%,50%))))*Z55)>100,100,(X55*(IF(Y55="A",105%,IF(Y55="B",102%,IF(Y55="C",75%,50%))))*Z55)),0) -> #DIV/0!
A56: 44 | B56: 0094714082 / 252610533 | C56: Syahwa Fatmah | S56: =AVERAGE(D56:H56) -> #DIV/0! | T56: =AVERAGE(I56:M56) -> #DIV/0! | U56: =AVERAGE(N56:R56) -> #DIV/0! | W56: =AVERAGE(S56:U56) -> #DIV/0! | X56: =ROUND(AVERAGE(V56:W56),0) -> #DIV/0! | AA56: =ROUND(IF((X56*(IF(Y56="A",105%,IF(Y56="B",102%,IF(Y56="C",75%,50%))))*Z56)>100,100,(X56*(IF(Y56="A",105%,IF(Y56="B",102%,IF(Y56="C",75%,50%))))*Z56)),0) -> #DIV/0!
A57: 45 | B57: 0102630183 / 252610534 | C57: Syakira Alma Annisa | S57: =AVERAGE(D57:H57) -> #DIV/0! | T57: =AVERAGE(I57:M57) -> #DIV/0! | U57: =AVERAGE(N57:R57) -> #DIV/0! | W57: =AVERAGE(S57:U57) -> #DIV/0! | X57: =ROUND(AVERAGE(V57:W57),0) -> #DIV/0! | AA57: =ROUND(IF((X57*(IF(Y57="A",105%,IF(Y57="B",102%,IF(Y57="C",75%,50%))))*Z57)>100,100,(X57*(IF(Y57="A",105%,IF(Y57="B",102%,IF(Y57="C",75%,50%))))*Z57)),0) -> #DIV/0!
A58: 46 | B58: 0106490661 / 252610544 | C58: Tiara Winni Melia | S58: =AVERAGE(D58:H58) -> #DIV/0! | T58: =AVERAGE(I58:M58) -> #DIV/0! | U58: =AVERAGE(N58:R58) -> #DIV/0! | W58: =AVERAGE(S58:U58) -> #DIV/0! | X58: =ROUND(AVERAGE(V58:W58),0) -> #DIV/0! | AA58: =ROUND(IF((X58*(IF(Y58="A",105%,IF(Y58="B",102%,IF(Y58="C",75%,50%))))*Z58)>100,100,(X58*(IF(Y58="A",105%,IF(Y58="B",102%,IF(Y58="C",75%,50%))))*Z58)),0) -> #DIV/0!
Y60: max
Y61: min
Y62: avg

Sheet X 5
A1: PEMERINTAH DAERAH PROVINSI JAWA BARAT DINAS PENDIDIKAN SMA NEGERI 2 CIBINONG Jln. Karadenan No. 5 Cibinong Telp/Fax. ( 0251 ) 8654347 Bogor 16913 http://www.sman2cibinong.sch.id email: info@sman2cibinong.sch.id
A3: DAFTAR CAPAIAN PEMBELAJARAN SEMESTER 1
A4: TAHUN PELAJARAN 2025 - 2026
A6: Mata Pelajaran | C6: :
A7: Kelas | C7: : X-5
A8: Pengajar | C8: :
A10: NO | B10: NISN / NIS | C10: NAMA PESERTA DIDIK | D10: ASESMEN / PENILAIAN
S11: Rata - Rata | V11: PAS | W11: RT | X11: NR | Y11: Skp | Z11: Hdr | AA11: Rapor
D12: 1 | E12: 2 | F12: 3 | G12: 4 | H12: 5 | I12: 1 | J12: 2 | K12: 3 | L12: 4 | M12: 5 | N12: 1 | O12: 2 | P12: 3 | Q12: 4 | R12: 5 | S12: CP1 | T12: CP2 | U12: CP3
A13: 1 | B13: 0092194625 / 252610004 | C13: Achmad Ardiansyah | S13: =AVERAGE(D13:H13) -> #DIV/0! | T13: =AVERAGE(I13:M13) -> #DIV/0! | U13: =AVERAGE(N13:R13) -> #DIV/0! | W13: =AVERAGE(S13:U13) -> #DIV/0! | X13: =ROUND(AVERAGE(V13:W13),0) -> #DIV/0! | Z13: 1 | AA13: =ROUND(IF((X13*(IF(Y13="A",105%,IF(Y13="B",102%,IF(Y13="C",75%,50%))))*Z13)>100,100,(X13*(IF(Y13="A",105%,IF(Y13="B",102%,IF(Y13="C",75%,50%))))*Z13)),0) -> #DIV/0!
A14: 2 | B14: 3108509756 / 252610013 | C14: Adrian Muhammad Fadillah | S14: =AVERAGE(D14:H14) -> #DIV/0! | T14: =AVERAGE(I14:M14) -> #DIV/0! | U14: =AVERAGE(N14:R14) -> #DIV/0! | W14: =AVERAGE(S14:U14) -> #DIV/0! | X14: =ROUND(AVERAGE(V14:W14),0) -> #DIV/0! | Z14: 1 | AA14: =ROUND(IF((X14*(IF(Y14="A",105%,IF(Y14="B",102%,IF(Y14="C",75%,50%))))*Z14)>100,100,(X14*(IF(Y14="A",105%,IF(Y14="B",102%,IF(Y14="C",75%,50%))))*Z14)),0) -> #DIV/0!
A15: 3 | B15: 0099540724 / 252610022 | C15: Aira Alessia Adha | S15: =AVERAGE(D15:H15) -> #DIV/0! | T15: =AVERAGE(I15:M15) -> #DIV/0! | U15: =AVERAGE(N15:R15) -> #DIV/0! | W15: =AVERAGE(S15:U15) -> #DIV/0! | X15: =ROUND(AVERAGE(V15:W15),0) -> #DIV/0! | Z15: 1 | AA15: =ROUND(IF((X15*(IF(Y15="A",105%,IF(Y15="B",102%,IF(Y15="C",75%,50%))))*Z15)>100,100,(X15*(IF(Y15="A",105%,IF(Y15="B",102%,IF(Y15="C",75%,50%))))*Z15)),0) -> #DIV/0!
A16: 4 | B16: 0107934430 / 252610024 | C16: Aira Febria Sari | S16: =AVERAGE(D16:H16) -> #DIV/0! | T16: =AVERAGE(I16:M16) -> #DIV/0! | U16: =AVERAGE(N16:R16) -> #DIV/0! | W16: =AVERAGE(S16:U16) -> #DIV/0! | X16: =ROUND(AVERAGE(V16:W16),0) -> #DIV/0! | Z16: 1 | AA16: =ROUND(IF((X16*(IF(Y16="A",105%,IF(Y16="B",102%,IF(Y16="C",75%,50%))))*Z16)>100,100,(X16*(IF(Y16="A",105%,IF(Y16="B",102%,IF(Y16="C",75%,50%))))*Z16)),0) -> #DIV/0!
A17: 5 | B17: 0099668827 / 252610034 | C17: Al Jadid Syafruddin Lubis | S17: =AVERAGE(D17:H17) -> #DIV/0! | T17: =AVERAGE(I17:M17) -> #DIV/0! | U17: =AVERAGE(N17:R17) -> #DIV/0! | W17: =AVERAGE(S17:U17) -> #DIV/0! | X17: =ROUND(AVERAGE(V17:W17),0) -> #DIV/0! | Z17: 1 | AA17: =ROUND(IF((X17*(IF(Y17="A",105%,IF(Y17="B",102%,IF(Y17="C",75%,50%))))*Z17)>100,100,(X17*(IF(Y17="A",105%,IF(Y17="B",102%,IF(Y17="C",75%,50%))))*Z17)),0) -> #DIV/0!
A18: 6 | B18: 0102993208 / 252610043 | C18: Alisya Belva Dhio | S18: =AVERAGE(D18:H18) -> #DIV/0! | T18: =AVERAGE(I18:M18) -> #DIV/0! | U18: =AVERAGE(N18:R18) -> #DIV/0! | W18: =AVERAGE(S18:U18) -> #DIV/0! | X18: =ROUND(AVERAGE(V18:W18),0) -> #DIV/0! | Z18: 1 | AA18: =ROUND(IF((X18*(IF(Y18="A",105%,IF(Y18="B",102%,IF(Y18="C",75%,50%))))*Z18)>100,100,(X18*(IF(Y18="A",105%,IF(Y18="B",102%,IF(Y18="C",75%,50%))))*Z18)),0) -> #DIV/0!
A19: 7 | B19: 0104459637 / 252610055 | C19: Amira Agni Kayla Raisya | S19: =AVERAGE(D19:H19) -> #DIV/0! | T19: =AVERAGE(I19:M19) -> #DIV/0! | U19: =AVERAGE(N19:R19) -> #DIV/0! | W19: =AVERAGE(S19:U19) -> #DIV/0! | X19: =ROUND(AVERAGE(V19:W19),0) -> #DIV/0! | Z19: 1 | AA19: =ROUND(IF((X19*(IF(Y19="A",105%,IF(Y19="B",102%,IF(Y19="C",75%,50%))))*Z19)>100,100,(X19*(IF(Y19="A",105%,IF(Y19="B",102%,IF(Y19="C",75%,50%))))*Z19)),0) -> #DIV/0!
A20: 8 | B20: 0104825356 / 252610057 | C20: Amirah Khalishah Somoal | S20: =AVERAGE(D20:H20) -> #DIV/0! | T20: =AVERAGE(I20:M20) -> #DIV/0! | U20: =AVERAGE(N20:R20) -> #DIV/0! | W20: =AVERAGE(S20:U20) -> #DIV/0! | X20: =ROUND(AVERAGE(V20:W20),0) -> #DIV/0! | Z20: 1 | AA20: =ROUND(IF((X20*(IF(Y20="A",105%,IF(Y20="B",102%,IF(Y20="C",75%,50%))))*Z20)>100,100,(X20*(IF(Y20="A",105%,IF(Y20="B",102%,IF(Y20="C",75%,50%))))*Z20)),0) -> #DIV/0!
A21: 9 | B21: 0099339799 / 252610060 | C21: Anas Legawa Riyadi | S21: =AVERAGE(D21:H21) -> #DIV/0! | T21: =AVERAGE(I21:M21) -> #DIV/0! | U21: =AVERAGE(N21:R21) -> #DIV/0! | W21: =AVERAGE(S21:U21) -> #DIV/0! | X21: =ROUND(AVERAGE(V21:W21),0) -> #DIV/0! | Z21: 1 | AA21: =ROUND(IF((X21*(IF(Y21="A",105%,IF(Y21="B",102%,IF(Y21="C",75%,50%))))*Z21)>100,100,(X21*(IF(Y21="A",105%,IF(Y21="B",102%,IF(Y21="C",75%,50%))))*Z21)),0) -> #DIV/0!
A22: 10 | B22: 0098197227 / 252610067 | C22: Annisa Fitriyani | S22: =AVERAGE(D22:H22) -> #DIV/0! | T22: =AVERAGE(I22:M22) -> #DIV/0! | U22: =AVERAGE(N22:R22) -> #DIV/0! | W22: =AVERAGE(S22:U22) -> #DIV/0! | X22: =ROUND(AVERAGE(V22:W22),0) -> #DIV/0! | Z22: 1 | AA22: =ROUND(IF((X22*(IF(Y22="A",105%,IF(Y22="B",102%,IF(Y22="C",75%,50%))))*Z22)>100,100,(X22*(IF(Y22="A",105%,IF(Y22="B",102%,IF(Y22="C",75%,50%))))*Z22)),0) -> #DIV/0!
A23: 11 | B23: 0093274791 / 252610115 | C23: Bagaskara Bisma Anoka | S23: =AVERAGE(D23:H23) -> #DIV/0! | T23: =AVERAGE(I23:M23) -> #DIV/0! | U23: =AVERAGE(N23:R23) -> #DIV/0! | W23: =AVERAGE(S23:U23) -> #DIV/0! | X23: =ROUND(AVERAGE(V23:W23),0) -> #DIV/0! | Z23: 1 | AA23: =ROUND(IF((X23*(IF(Y23="A",105%,IF(Y23="B",102%,IF(Y23="C",75%,50%))))*Z23)>100,100,(X23*(IF(Y23="A",105%,IF(Y23="B",102%,IF(Y23="C",75%,50%))))*Z23)),0) -> #DIV/0!
A24: 12 | B24: 0099900563 / 252610123 | C24: Bilqis Nikita Aylani | S24: =AVERAGE(D24:H24) -> #DIV/0! | T24: =AVERAGE(I24:M24) -> #DIV/0! | U24: =AVERAGE(N24:R24) -> #DIV/0! | W24: =AVERAGE(S24:U24) -> #DIV/0! | X24: =ROUND(AVERAGE(V24:W24),0) -> #DIV/0! | Z24: 1 | AA24: =ROUND(IF((X24*(IF(Y24="A",105%,IF(Y24="B",102%,IF(Y24="C",75%,50%))))*Z24)>100,100,(X24*(IF(Y24="A",105%,IF(Y24="B",102%,IF(Y24="C",75%,50%))))*Z24)),0) -> #DIV/0!
... A48: 36 | B48: 0102081772 / 252610451 | C48: Raden Ciara Za Syahluna | S48: =AVERAGE(D48:H48) -> #DIV/0! | T48: =AVERAGE(I48:M48) -> #DIV/0! | U48: =AVERAGE(N48:R48) -> #DIV/0! | W48: =AVERAGE(S48:U48) -> #DIV/0! | X48: =ROUND(AVERAGE(V48:W48),0) -> #DIV/0! | Z48: 1 | AA48: =ROUND(IF((X48*(IF(Y48="A",105%,IF(Y48="B",102%,IF(Y48="C",75%,50%))))*Z48)>100,100,(X48*(IF(Y48="A",105%,IF(Y48="B",102%,IF(Y48="C",75%,50%))))*Z48)),0) -> #DIV/0!
A49: 37 | B49: 0097864614 / 252610471 | C49: Rama Andhika | S49: =AVERAGE(D49:H49) -> #DIV/0! | T49: =AVERAGE(I49:M49) -> #DIV/0! | U49: =AVERAGE(N49:R49) -> #DIV/0! | W49: =AVERAGE(S49:U49) -> #DIV/0! | X49: =ROUND(AVERAGE(V49:W49),0) -> #DIV/0! | AA49: =ROUND(IF((X49*(IF(Y49="A",105%,IF(Y49="B",102%,IF(Y49="C",75%,50%))))*Z49)>100,100,(X49*(IF(Y49="A",105%,IF(Y49="B",102%,IF(Y49="C",75%,50%))))*Z49)),0) -> #DIV/0!
A50: 38 | B50: 0093090773 / 252610481 | C50: Reisha Azzahra Pramesti | S50: =AVERAGE(D50:H50) -> #DIV/0! | T50: =AVERAGE(I50:M50) -> #DIV/0! | U50: =AVERAGE(N50:R50) -> #DIV/0! | W50: =AVERAGE(S50:U50) -> #DIV/0! | X50: =ROUND(AVERAGE(V50:W50),0) -> #DIV/0! | AA50: =ROUND(IF((X50*(IF(Y50="A",105%,IF(Y50="B",102%,IF(Y50="C",75%,50%))))*Z50)>100,100,(X50*(IF(Y50="A",105%,IF(Y50="B",102%,IF(Y50="C",75%,50%))))*Z50)),0) -> #DIV/0!
A51: 39 | B51: 0095160472 / 252610488 | C51: Rheiska Amelia | S51: =AVERAGE(D51:H51) -> #DIV/0! | T51: =AVERAGE(I51:M51) -> #DIV/0! | U51: =AVERAGE(N51:R51) -> #DIV/0! | W51: =AVERAGE(S51:U51) -> #DIV/0! | X51: =ROUND(AVERAGE(V51:W51),0) -> #DIV/0! | AA51: =ROUND(IF((X51*(IF(Y51="A",105%,IF(Y51="B",102%,IF(Y51="C",75%,50%))))*Z51)>100,100,(X51*(IF(Y51="A",105%,IF(Y51="B",102%,IF(Y51="C",75%,50%))))*Z51)),0) -> #DIV/0!
A52: 40 | B52: 0092402487 / 252610507 | C52: Salsabila Kinaya | S52: =AVERAGE(D52:H52) -> #DIV/0! | T52: =AVERAGE(I52:M52) -> #DIV/0! | U52: =AVERAGE(N52:R52) -> #DIV/0! | W52: =AVERAGE(S52:U52) -> #DIV/0! | X52: =ROUND(AVERAGE(V52:W52),0) -> #DIV/0! | AA52: =ROUND(IF((X52*(IF(Y52="A",105%,IF(Y52="B",102%,IF(Y52="C",75%,50%))))*Z52)>100,100,(X52*(IF(Y52="A",105%,IF(Y52="B",102%,IF(Y52="C",75%,50%))))*Z52)),0) -> #DIV/0!
A53: 41 | B53: 0092706472 / 252610535 | C53: Syarafina Nur Alifatuzahro | S53: =AVERAGE(D53:H53) -> #DIV/0! | T53: =AVERAGE(I53:M53) -> #DIV/0! | U53: =AVERAGE(N53:R53) -> #DIV/0! | W53: =AVERAGE(S53:U53) -> #DIV/0! | X53: =ROUND(AVERAGE(V53:W53),0) -> #DIV/0! | AA53: =ROUND(IF((X53*(IF(Y53="A",105%,IF(Y53="B",102%,IF(Y53="C",75%,50%))))*Z53)>100,100,(X53*(IF(Y53="A",105%,IF(Y53="B",102%,IF(Y53="C",75%,50%))))*Z53)),0) -> #DIV/0!
A54: 42 | B54: 0105183684 / 252610540 | C54: Tanty Amelia Al Rasyid | S54: =AVERAGE(D54:H54) -> #DIV/0! | T54: =AVERAGE(I54:M54) -> #DIV/0! | U54: =AVERAGE(N54:R54) -> #DIV/0! | W54: =AVERAGE(S54:U54) -> #DIV/0! | X54: =ROUND(AVERAGE(V54:W54),0) -> #DIV/0! | AA54: =ROUND(IF((X54*(IF(Y54="A",105%,IF(Y54="B",102%,IF(Y54="C",75%,50%))))*Z54)>100,100,(X54*(IF(Y54="A",105%,IF(Y54="B",102%,IF(Y54="C",75%,50%))))*Z54)),0) -> #DIV/0!
A55: 43 | B55: 0098052333 / 252610543 | C55: Teduh Mutiara Hapsari | S55: =AVERAGE(D55:H55) -> #DIV/0! | T55: =AVERAGE(I55:M55) -> #DIV/0! | U55: =AVERAGE(N55:R55) -> #DIV/0! | W55: =AVERAGE(S55:U55) -> #DIV/0! | X55: =ROUND(AVERAGE(V55:W55),0) -> #DIV/0! | AA55: =ROUND(IF((X55*(IF(Y55="A",105%,IF(Y55="B",102%,IF(Y55="C",75%,50%))))*Z55)>100,100,(X55*(IF(Y55="A",105%,IF(Y55="B",102%,IF(Y55="C",75%,50%))))*Z55)),0) -> #DIV/0!
A56: 44 | B56: 3094664028 / 252610549 | C56: Tubagus Mochamad Rizki Fauzan Al Faris | S56: =AVERAGE(D56:H56) -> #DIV/0! | T56: =AVERAGE(I56:M56) -> #DIV/0! | U56: =AVERAGE(N56:R56) -> #DIV/0! | W56: =AVERAGE(S56:U56) -> #DIV/0! | X56: =ROUND(AVERAGE(V56:W56),0) -> #DIV/0! | AA56: =ROUND(IF((X56*(IF(Y56="A",105%,IF(Y56="B",102%,IF(Y56="C",75%,50%))))*Z56)>100,100,(X56*(IF(Y56="A",105%,IF(Y56="B",102%,IF(Y56="C",75%,50%))))*Z56)),0) -> #DIV/0!
A57: 45 | B57: 0099429653 / 252610554 | C57: Yanza Rizkia Salsabillah | S57: =AVERAGE(D57:H57) -> #DIV/0! | T57: =AVERAGE(I57:M57) -> #DIV/0! | U57: =AVERAGE(N57:R57) -> #DIV/0! | W57: =AVERAGE(S57:U57) -> #DIV/0! | X57: =ROUND(AVERAGE(V57:W57),0) -> #DIV/0! | AA57: =ROUND(IF((X57*(IF(Y57="A",105%,IF(Y57="B",102%,IF(Y57="C",75%,50%))))*Z57)>100,100,(X57*(IF(Y57="A",105%,IF(Y57="B",102%,IF(Y57="C",75%,50%))))*Z57)),0) -> #DIV/0!
Y59: max
Y60: min
Y61: avg

Sheet X 6
A1: PEMERINTAH DAERAH PROVINSI JAWA BARAT DINAS PENDIDIKAN SMA NEGERI 2 CIBINONG Jln. Karadenan No. 5 Cibinong Telp/Fax. ( 0251 ) 8654347 Bogor 16913 http://www.sman2cibinong.sch.id email: info@sman2cibinong.sch.id
A3: DAFTAR CAPAIAN PEMBELAJARAN SEMESTER 1
A4: TAHUN PELAJARAN 2025 - 2026
A6: Mata Pelajaran | C6: :
A7: Kelas | C7: : X-6
A8: Pengajar | C8: :
A10: NO | B10: NISN / NIS | C10: NAMA PESERTA DIDIK | D10: ASESMEN / PENILAIAN
S11: Rata - Rata | V11: PAS | W11: RT | X11: NR | Y11: Skp | Z11: Hdr | AA11: Rapor
D12: 1 | E12: 2 | F12: 3 | G12: 4 | H12: 5 | I12: 1 | J12: 2 | K12: 3 | L12: 4 | M12: 5 | N12: 1 | O12: 2 | P12: 3 | Q12: 4 | R12: 5 | S12: CP1 | T12: CP2 | U12: CP3
A13: 1 | B13: 0096316890 / 252610005 | C13: Achmad Firza Ghibran | S13: =AVERAGE(D13:H13) -> #DIV/0! | T13: =AVERAGE(I13:M13) -> #DIV/0! | U13: =AVERAGE(N13:R13) -> #DIV/0! | W13: =AVERAGE(S13:U13) -> #DIV/0! | X13: =ROUND(AVERAGE(V13:W13),0) -> #DIV/0! | Z13: 1 | AA13: =ROUND(IF((X13*(IF(Y13="A",105%,IF(Y13="B",102%,IF(Y13="C",75%,50%))))*Z13)>100,100,(X13*(IF(Y13="A",105%,IF(Y13="B",102%,IF(Y13="C",75%,50%))))*Z13)),0) -> #DIV/0!
A14: 2 | B14: 0091825991 / 252610009 | C14: Adi Pati Jaya Prana | S14: =AVERAGE(D14:H14) -> #DIV/0! | T14: =AVERAGE(I14:M14) -> #DIV/0! | U14: =AVERAGE(N14:R14) -> #DIV/0! | W14: =AVERAGE(S14:U14) -> #DIV/0! | X14: =ROUND(AVERAGE(V14:W14),0) -> #DIV/0! | Z14: 1 | AA14: =ROUND(IF((X14*(IF(Y14="A",105%,IF(Y14="B",102%,IF(Y14="C",75%,50%))))*Z14)>100,100,(X14*(IF(Y14="A",105%,IF(Y14="B",102%,IF(Y14="C",75%,50%))))*Z14)),0) -> #DIV/0!
A15: 3 | B15: 0094216872 / 252610036 | C15: Alfany Himma Roudina | S15: =AVERAGE(D15:H15) -> #DIV/0! | T15: =AVERAGE(I15:M15) -> #DIV/0! | U15: =AVERAGE(N15:R15) -> #DIV/0! | W15: =AVERAGE(S15:U15) -> #DIV/0! | X15: =ROUND(AVERAGE(V15:W15),0) -> #DIV/0! | Z15: 1 | AA15: =ROUND(IF((X15*(IF(Y15="A",105%,IF(Y15="B",102%,IF(Y15="C",75%,50%))))*Z15)>100,100,(X15*(IF(Y15="A",105%,IF(Y15="B",102%,IF(Y15="C",75%,50%))))*Z15)),0) -> #DIV/0!
A16: 4 | B16: 3093210071 / 252610042 | C16: Alisa Putri | S16: =AVERAGE(D16:H16) -> #DIV/0! | T16: =AVERAGE(I16:M16) -> #DIV/0! | U16: =AVERAGE(N16:R16) -> #DIV/0! | W16: =AVERAGE(S16:U16) -> #DIV/0! | X16: =ROUND(AVERAGE(V16:W16),0) -> #DIV/0! | Z16: 1 | AA16: =ROUND(IF((X16*(IF(Y16="A",105%,IF(Y16="B",102%,IF(Y16="C",75%,50%))))*Z16)>100,100,(X16*(IF(Y16="A",105%,IF(Y16="B",102%,IF(Y16="C",75%,50%))))*Z16)),0) -> #DIV/0!
A17: 5 | B17: 0099344894 / 252610072 | C17: Aqila Noya Faiza | S17: =AVERAGE(D17:H17) -> #DIV/0! | T17: =AVERAGE(I17:M17) -> #DIV/0! | U17: =AVERAGE(N17:R17) -> #DIV/0! | W17: =AVERAGE(S17:U17) -> #DIV/0! | X17: =ROUND(AVERAGE(V17:W17),0) -> #DIV/0! | Z17: 1 | AA17: =ROUND(IF((X17*(IF(Y17="A",105%,IF(Y17="B",102%,IF(Y17="C",75%,50%))))*Z17)>100,100,(X17*(IF(Y17="A",105%,IF(Y17="B",102%,IF(Y17="C",75%,50%))))*Z17)),0) -> #DIV/0!
A18: 6 | B18: 0109520546 / 252610120 | C18: Bernala Baratama Sirait | S18: =AVERAGE(D18:H18) -> #DIV/0! | T18: =AVERAGE(I18:M18) -> #DIV/0! | U18: =AVERAGE(N18:R18) -> #DIV/0! | W18: =AVERAGE(S18:U18) -> #DIV/0! | X18: =ROUND(AVERAGE(V18:W18),0) -> #DIV/0! | Z18: 1 | AA18: =ROUND(IF((X18*(IF(Y18="A",105%,IF(Y18="B",102%,IF(Y18="C",75%,50%))))*Z18)>100,100,(X18*(IF(Y18="A",105%,IF(Y18="B",102%,IF(Y18="C",75%,50%))))*Z18)),0) -> #DIV/0!
A19: 7 | B19: 0104799326 / 252610134 | C19: Chempaka Balqist Zavira Mentary Misman | S19: =AVERAGE(D19:H19) -> #DIV/0! | T19: =AVERAGE(I19:M19) -> #DIV/0! | U19: =AVERAGE(N19:R19) -> #DIV/0! | W19: =AVERAGE(S19:U19) -> #DIV/0! | X19: =ROUND(AVERAGE(V19:W19),0) -> #DIV/0! | Z19: 1 | AA19: =ROUND(IF((X19*(IF(Y19="A",105%,IF(Y19="B",102%,IF(Y19="C",75%,50%))))*Z19)>100,100,(X19*(IF(Y19="A",105%,IF(Y19="B",102%,IF(Y19="C",75%,50%))))*Z19)),0) -> #DIV/0!
A20: 8 | B20: 0081552525 / 252610150 | C20: Defrino Viernadi Laitnis Yusfa | S20: =AVERAGE(D20:H20) -> #DIV/0! | T20: =AVERAGE(I20:M20) -> #DIV/0! | U20: =AVERAGE(N20:R20) -> #DIV/0! | W20: =AVERAGE(S20:U20) -> #DIV/0! | X20: =ROUND(AVERAGE(V20:W20),0) -> #DIV/0! | Z20: 1 | AA20: =ROUND(IF((X20*(IF(Y20="A",105%,IF(Y20="B",102%,IF(Y20="C",75%,50%))))*Z20)>100,100,(X20*(IF(Y20="A",105%,IF(Y20="B",102%,IF(Y20="C",75%,50%))))*Z20)),0) -> #DIV/0!
A21: 9 | B21: 0099286083 / 252610157 | C21: Dhia Salsabila | S21: =AVERAGE(D21:H21) -> #DIV/0! | T21: =AVERAGE(I21:M21) -> #DIV/0! | U21: =AVERAGE(N21:R21) -> #DIV/0! | W21: =AVERAGE(S21:U21) -> #DIV/0! | X21: =ROUND(AVERAGE(V21:W21),0) -> #DIV/0! | Z21: 1 | AA21: =ROUND(IF((X21*(IF(Y21="A",105%,IF(Y21="B",102%,IF(Y21="C",75%,50%))))*Z21)>100,100,(X21*(IF(Y21="A",105%,IF(Y21="B",102%,IF(Y21="C",75%,50%))))*Z21)),0) -> #DIV/0!
A22: 10 | B22: 0093451857 / 252610167 | C22: Dinda Dyah Pitaloka | S22: =AVERAGE(D22:H22) -> #DIV/0! | T22: =AVERAGE(I22:M22) -> #DIV/0! | U22: =AVERAGE(N22:R22) -> #DIV/0! | W22: =AVERAGE(S22:U22) -> #DIV/0! | X22: =ROUND(AVERAGE(V22:W22),0) -> #DIV/0! | Z22: 1 | AA22: =ROUND(IF((X22*(IF(Y22="A",105%,IF(Y22="B",102%,IF(Y22="C",75%,50%))))*Z22)>100,100,(X22*(IF(Y22="A",105%,IF(Y22="B",102%,IF(Y22="C",75%,50%))))*Z22)),0) -> #DIV/0!
A23: 11 | B23: 0074430959 / 252610172 | C23: Dwi Irmawati | S23: =AVERAGE(D23:H23) -> #DIV/0! | T23: =AVERAGE(I23:M23) -> #DIV/0! | U23: =AVERAGE(N23:R23) -> #DIV/0! | W23: =AVERAGE(S23:U23) -> #DIV/0! | X23: =ROUND(AVERAGE(V23:W23),0) -> #DIV/0! | Z23: 1 | AA23: =ROUND(IF((X23*(IF(Y23="A",105%,IF(Y23="B",102%,IF(Y23="C",75%,50%))))*Z23)>100,100,(X23*(IF(Y23="A",105%,IF(Y23="B",102%,IF(Y23="C",75%,50%))))*Z23)),0) -> #DIV/0!
A24: 12 | B24: 0096744611 / 252610176 | C24: Egi Surjana | S24: =AVERAGE(D24:H24) -> #DIV/0! | T24: =AVERAGE(I24:M24) -> #DIV/0! | U24: =AVERAGE(N24:R24) -> #DIV/0! | W24: =AVERAGE(S24:U24) -> #DIV/0! | X24: =ROUND(AVERAGE(V24:W24),0) -> #DIV/0! | Z24: 1 | AA24: =ROUND(IF((X24*(IF(Y24="A",105%,IF(Y24="B",102%,IF(Y24="C",75%,50%))))*Z24)>100,100,(X24*(IF(Y24="A",105%,IF(Y24="B",102%,IF(Y24="C",75%,50%))))*Z24)),0) -> #DIV/0!
... A48: 36 | B48: 0094690365 / 252610478 | C48: Raynar Abiyu Diera | S48: =AVERAGE(D48:H48) -> #DIV/0! | T48: =AVERAGE(I48:M48) -> #DIV/0! | U48: =AVERAGE(N48:R48) -> #DIV/0! | W48: =AVERAGE(S48:U48) -> #DIV/0! | X48: =ROUND(AVERAGE(V48:W48),0) -> #DIV/0! | Z48: 1 | AA48: =ROUND(IF((X48*(IF(Y48="A",105%,IF(Y48="B",102%,IF(Y48="C",75%,50%))))*Z48)>100,100,(X48*(IF(Y48="A",105%,IF(Y48="B",102%,IF(Y48="C",75%,50%))))*Z48)),0) -> #DIV/0!
A49: 37 | B49: 0093623051 / 252610479 | C49: Rayyan Wahyu Ramadhan | S49: =AVERAGE(D49:H49) -> #DIV/0! | T49: =AVERAGE(I49:M49) -> #DIV/0! | U49: =AVERAGE(N49:R49) -> #DIV/0! | W49: =AVERAGE(S49:U49) -> #DIV/0! | X49: =ROUND(AVERAGE(V49:W49),0) -> #DIV/0! | AA49: =ROUND(IF((X49*(IF(Y49="A",105%,IF(Y49="B",102%,IF(Y49="C",75%,50%))))*Z49)>100,100,(X49*(IF(Y49="A",105%,IF(Y49="B",102%,IF(Y49="C",75%,50%))))*Z49)),0) -> #DIV/0!
A50: 38 | B50: 0108406931 / 252610484 | C50: Reva Aulia Putri | S50: =AVERAGE(D50:H50) -> #DIV/0! | T50: =AVERAGE(I50:M50) -> #DIV/0! | U50: =AVERAGE(N50:R50) -> #DIV/0! | W50: =AVERAGE(S50:U50) -> #DIV/0! | X50: =ROUND(AVERAGE(V50:W50),0) -> #DIV/0! | AA50: =ROUND(IF((X50*(IF(Y50="A",105%,IF(Y50="B",102%,IF(Y50="C",75%,50%))))*Z50)>100,100,(X50*(IF(Y50="A",105%,IF(Y50="B",102%,IF(Y50="C",75%,50%))))*Z50)),0) -> #DIV/0!
A51: 39 | B51: 0104171202 / 252610486 | C51: Revina Apriza | S51: =AVERAGE(D51:H51) -> #DIV/0! | T51: =AVERAGE(I51:M51) -> #DIV/0! | U51: =AVERAGE(N51:R51) -> #DIV/0! | W51: =AVERAGE(S51:U51) -> #DIV/0! | X51: =ROUND(AVERAGE(V51:W51),0) -> #DIV/0! | AA51: =ROUND(IF((X51*(IF(Y51="A",105%,IF(Y51="B",102%,IF(Y51="C",75%,50%))))*Z51)>100,100,(X51*(IF(Y51="A",105%,IF(Y51="B",102%,IF(Y51="C",75%,50%))))*Z51)),0) -> #DIV/0!
A52: 40 | B52: 3096816288 / 252610495 | C52: Rossy Indriyati | S52: =AVERAGE(D52:H52) -> #DIV/0! | T52: =AVERAGE(I52:M52) -> #DIV/0! | U52: =AVERAGE(N52:R52) -> #DIV/0! | W52: =AVERAGE(S52:U52) -> #DIV/0! | X52: =ROUND(AVERAGE(V52:W52),0) -> #DIV/0! | AA52: =ROUND(IF((X52*(IF(Y52="A",105%,IF(Y52="B",102%,IF(Y52="C",75%,50%))))*Z52)>100,100,(X52*(IF(Y52="A",105%,IF(Y52="B",102%,IF(Y52="C",75%,50%))))*Z52)),0) -> #DIV/0!
A53: 41 | B53: 0102698949 / 252610505 | C53: Salsa Kirana Putri | S53: =AVERAGE(D53:H53) -> #DIV/0! | T53: =AVERAGE(I53:M53) -> #DIV/0! | U53: =AVERAGE(N53:R53) -> #DIV/0! | W53: =AVERAGE(S53:U53) -> #DIV/0! | X53: =ROUND(AVERAGE(V53:W53),0) -> #DIV/0! | AA53: =ROUND(IF((X53*(IF(Y53="A",105%,IF(Y53="B",102%,IF(Y53="C",75%,50%))))*Z53)>100,100,(X53*(IF(Y53="A",105%,IF(Y53="B",102%,IF(Y53="C",75%,50%))))*Z53)),0) -> #DIV/0!
A54: 42 | B54: 3096600612 / 252610517 | C54: Shalomieta Aira Kinaya | S54: =AVERAGE(D54:H54) -> #DIV/0! | T54: =AVERAGE(I54:M54) -> #DIV/0! | U54: =AVERAGE(N54:R54) -> #DIV/0! | W54: =AVERAGE(S54:U54) -> #DIV/0! | X54: =ROUND(AVERAGE(V54:W54),0) -> #DIV/0! | AA54: =ROUND(IF((X54*(IF(Y54="A",105%,IF(Y54="B",102%,IF(Y54="C",75%,50%))))*Z54)>100,100,(X54*(IF(Y54="A",105%,IF(Y54="B",102%,IF(Y54="C",75%,50%))))*Z54)),0) -> #DIV/0!
A55: 43 | B55: 0106462308 / 252610528 | C55: Syahdan Akbar Mara Putra | S55: =AVERAGE(D55:H55) -> #DIV/0! | T55: =AVERAGE(I55:M55) -> #DIV/0! | U55: =AVERAGE(N55:R55) -> #DIV/0! | W55: =AVERAGE(S55:U55) -> #DIV/0! | X55: =ROUND(AVERAGE(V55:W55),0) -> #DIV/0! | AA55: =ROUND(IF((X55*(IF(Y55="A",105%,IF(Y55="B",102%,IF(Y55="C",75%,50%))))*Z55)>100,100,(X55*(IF(Y55="A",105%,IF(Y55="B",102%,IF(Y55="C",75%,50%))))*Z55)),0) -> #DIV/0!
A56: 44 | B56: 0101383149 / 252610529 | C56: Syahla Adzkannisa Vuzela | S56: =AVERAGE(D56:H56) -> #DIV/0! | T56: =AVERAGE(I56:M56) -> #DIV/0! | U56: =AVERAGE(N56:R56) -> #DIV/0! | W56: =AVERAGE(S56:U56) -> #DIV/0! | X56: =ROUND(AVERAGE(V56:W56),0) -> #DIV/0! | AA56: =ROUND(IF((X56*(IF(Y56="A",105%,IF(Y56="B",102%,IF(Y56="C",75%,50%))))*Z56)>100,100,(X56*(IF(Y56="A",105%,IF(Y56="B",102%,IF(Y56="C",75%,50%))))*Z56)),0) -> #DIV/0!
A57: 45 | B57: 0107096617 / 252610541 | C57: Taufik Hidayah | S57: =AVERAGE(D57:H57) -> #DIV/0! | T57: =AVERAGE(I57:M57) -> #DIV/0! | U57: =AVERAGE(N57:R57) -> #DIV/0! | W57: =AVERAGE(S57:U57) -> #DIV/0! | X57: =ROUND(AVERAGE(V57:W57),0) -> #DIV/0! | AA57: =ROUND(IF((X57*(IF(Y57="A",105%,IF(Y57="B",102%,IF(Y57="C",75%,50%))))*Z57)>100,100,(X57*(IF(Y57="A",105%,IF(Y57="B",102%,IF(Y57="C",75%,50%))))*Z57)),0) -> #DIV/0!
Y59: max
Y60: min
Y61: avg

Sheet X 7
A1: PEMERINTAH DAERAH PROVINSI JAWA BARAT DINAS PENDIDIKAN SMA NEGERI 2 CIBINONG Jln. Karadenan No. 5 Cibinong Telp/Fax. ( 0251 ) 8654347 Bogor 16913 http://www.sman2cibinong.sch.id email: info@sman2cibinong.sch.id
A3: DAFTAR CAPAIAN PEMBELAJARAN SEMESTER 1
A4: TAHUN PELAJARAN 2025 - 2026
A6: Mata Pelajaran | C6: :
A7: Kelas | C7: : X-7
A8: Pengajar | C8: :
A10: NO | B10: NISN / NIS | C10: NAMA PESERTA DIDIK | D10: ASESMEN / PENILAIAN
S11: Rata - Rata | V11: PAS | W11: RT | X11: NR | Y11: Skp | Z11: Hdr | AA11: Rapor
D12: 1 | E12: 2 | F12: 3 | G12: 4 | H12: 5 | I12: 1 | J12: 2 | K12: 3 | L12: 4 | M12: 5 | N12: 1 | O12: 2 | P12: 3 | Q12: 4 | R12: 5 | S12: CP1 | T12: CP2 | U12: CP3
A13: 1 | B13: 0101303057 / 252610006 | C13: Adara Luthfia Putri | S13: =AVERAGE(D13:H13) -> #DIV/0! | T13: =AVERAGE(I13:M13) -> #DIV/0! | U13: =AVERAGE(N13:R13) -> #DIV/0! | W13: =AVERAGE(S13:U13) -> #DIV/0! | X13: =ROUND(AVERAGE(V13:W13),0) -> #DIV/0! | Z13: 1 | AA13: =ROUND(IF((X13*(IF(Y13="A",105%,IF(Y13="B",102%,IF(Y13="C",75%,50%))))*Z13)>100,100,(X13*(IF(Y13="A",105%,IF(Y13="B",102%,IF(Y13="C",75%,50%))))*Z13)),0) -> #DIV/0!
A14: 2 | B14: 0109597144 / 252610017 | C14: Ahmad Fahri Hidayat | S14: =AVERAGE(D14:H14) -> #DIV/0! | T14: =AVERAGE(I14:M14) -> #DIV/0! | U14: =AVERAGE(N14:R14) -> #DIV/0! | W14: =AVERAGE(S14:U14) -> #DIV/0! | X14: =ROUND(AVERAGE(V14:W14),0) -> #DIV/0! | Z14: 1 | AA14: =ROUND(IF((X14*(IF(Y14="A",105%,IF(Y14="B",102%,IF(Y14="C",75%,50%))))*Z14)>100,100,(X14*(IF(Y14="A",105%,IF(Y14="B",102%,IF(Y14="C",75%,50%))))*Z14)),0) -> #DIV/0!
A15: 3 | B15: 3096764634 / 252610025 | C15: Aira Kirana | S15: =AVERAGE(D15:H15) -> #DIV/0! | T15: =AVERAGE(I15:M15) -> #DIV/0! | U15: =AVERAGE(N15:R15) -> #DIV/0! | W15: =AVERAGE(S15:U15) -> #DIV/0! | X15: =ROUND(AVERAGE(V15:W15),0) -> #DIV/0! | Z15: 1 | AA15: =ROUND(IF((X15*(IF(Y15="A",105%,IF(Y15="B",102%,IF(Y15="C",75%,50%))))*Z15)>100,100,(X15*(IF(Y15="A",105%,IF(Y15="B",102%,IF(Y15="C",75%,50%))))*Z15)),0) -> #DIV/0!
A16: 4 | B16: 0094347087 / 252610044 | C16: Aliya Trianzani Putri | S16: =AVERAGE(D16:H16) -> #DIV/0! | T16: =AVERAGE(I16:M16) -> #DIV/0! | U16: =AVERAGE(N16:R16) -> #DIV/0! | W16: =AVERAGE(S16:U16) -> #DIV/0! | X16: =ROUND(AVERAGE(V16:W16),0) -> #DIV/0! | Z16: 1 | AA16: =ROUND(IF((X16*(IF(Y16="A",105%,IF(Y16="B",102%,IF(Y16="C",75%,50%))))*Z16)>100,100,(X16*(IF(Y16="A",105%,IF(Y16="B",102%,IF(Y16="C",75%,50%))))*Z16)),0) -> #DIV/0!
A17: 5 | B17: 0101401010 / 252610051 | C17: Alya Silvana Sarifah | S17: =AVERAGE(D17:H17) -> #DIV/0! | T17: =AVERAGE(I17:M17) -> #DIV/0! | U17: =AVERAGE(N17:R17) -> #DIV/0! | W17: =AVERAGE(S17:U17) -> #DIV/0! | X17: =ROUND(AVERAGE(V17:W17),0) -> #DIV/0! | Z17: 1 | AA17: =ROUND(IF((X17*(IF(Y17="A",105%,IF(Y17="B",102%,IF(Y17="C",75%,50%))))*Z17)>100,100,(X17*(IF(Y17="A",105%,IF(Y17="B",102%,IF(Y17="C",75%,50%))))*Z17)),0) -> #DIV/0!
A18: 6 | B18: 0106758481 / 252610064 | C18: Anindya Estyana Damayanti | S18: =AVERAGE(D18:H18) -> #DIV/0! | T18: =AVERAGE(I18:M18) -> #DIV/0! | U18: =AVERAGE(N18:R18) -> #DIV/0! | W18: =AVERAGE(S18:U18) -> #DIV/0! | X18: =ROUND(AVERAGE(V18:W18),0) -> #DIV/0! | Z18: 1 | AA18: =ROUND(IF((X18*(IF(Y18="A",105%,IF(Y18="B",102%,IF(Y18="C",75%,50%))))*Z18)>100,100,(X18*(IF(Y18="A",105%,IF(Y18="B",102%,IF(Y18="C",75%,50%))))*Z18)),0) -> #DIV/0!
A19: 7 | B19: 0092241333 / 252610113 | C19: Azri Aditya Amada | S19: =AVERAGE(D19:H19) -> #DIV/0! | T19: =AVERAGE(I19:M19) -> #DIV/0! | U19: =AVERAGE(N19:R19) -> #DIV/0! | W19: =AVERAGE(S19:U19) -> #DIV/0! | X19: =ROUND(AVERAGE(V19:W19),0) -> #DIV/0! | Z19: 1 | AA19: =ROUND(IF((X19*(IF(Y19="A",105%,IF(Y19="B",102%,IF(Y19="C",75%,50%))))*Z19)>100,100,(X19*(IF(Y19="A",105%,IF(Y19="B",102%,IF(Y19="C",75%,50%))))*Z19)),0) -> #DIV/0!
A20: 8 | B20: 0102239764 / 252610140 | C20: Clara Dwi Cahya | S20: =AVERAGE(D20:H20) -> #DIV/0! | T20: =AVERAGE(I20:M20) -> #DIV/0! | U20: =AVERAGE(N20:R20) -> #DIV/0! | W20: =AVERAGE(S20:U20) -> #DIV/0! | X20: =ROUND(AVERAGE(V20:W20),0) -> #DIV/0! | Z20: 1 | AA20: =ROUND(IF((X20*(IF(Y20="A",105%,IF(Y20="B",102%,IF(Y20="C",75%,50%))))*Z20)>100,100,(X20*(IF(Y20="A",105%,IF(Y20="B",102%,IF(Y20="C",75%,50%))))*Z20)),0) -> #DIV/0!
A21: 9 | B21: 0108763766 / 252610141 | C21: Clarisa Meidiana | S21: =AVERAGE(D21:H21) -> #DIV/0! | T21: =AVERAGE(I21:M21) -> #DIV/0! | U21: =AVERAGE(N21:R21) -> #DIV/0! | W21: =AVERAGE(S21:U21) -> #DIV/0! | X21: =ROUND(AVERAGE(V21:W21),0) -> #DIV/0! | Z21: 1 | AA21: =ROUND(IF((X21*(IF(Y21="A",105%,IF(Y21="B",102%,IF(Y21="C",75%,50%))))*Z21)>100,100,(X21*(IF(Y21="A",105%,IF(Y21="B",102%,IF(Y21="C",75%,50%))))*Z21)),0) -> #DIV/0!
A22: 10 | B22: 0103120702 / 252610144 | C22: Daffa Khoirul Fajri | S22: =AVERAGE(D22:H22) -> #DIV/0! | T22: =AVERAGE(I22:M22) -> #DIV/0! | U22: =AVERAGE(N22:R22) -> #DIV/0! | W22: =AVERAGE(S22:U22) -> #DIV/0! | X22: =ROUND(AVERAGE(V22:W22),0) -> #DIV/0! | Z22: 1 | AA22: =ROUND(IF((X22*(IF(Y22="A",105%,IF(Y22="B",102%,IF(Y22="C",75%,50%))))*Z22)>100,100,(X22*(IF(Y22="A",105%,IF(Y22="B",102%,IF(Y22="C",75%,50%))))*Z22)),0) -> #DIV/0!
